Workbook

Sheet Cover
B2: Priced In: MarketAxess (MKTX)
B3: Reverse DCF, model v1.0. Inputs as of the Oct 13, 2026 close; model locked Oct 14, 2026 (commit 0735af0).
B4: Exchanges | US | reports in USD
B6: The question
B7: What revenue growth over the next five years does today's price imply, and is that more or less than the company has delivered and analysts expect?
B9: Answer
B10: Price at the lock ($) | C10: =Inputs!$C$6 -> 164.53538
B11: Implied 5-year revenue growth | C11: =Solver!$W$7 -> 0.084007684
B12: Anchor (history and analysts) | C12: =Inputs!$C$43 -> 0.057829158
B13: Gap (implied - anchor) | C13: =C11-C12 -> 0.026178525
B14: Verdict | C14: Deal price
B15: WACC | C15: =WACC!$C$37 -> 0.077507582
B16: Terminal growth | C16: =Inputs!$C$37 -> 0.0283
B17: Unlevered free-cash-flow margin | C17: =Inputs!$C$23 -> 0.22332563
B18: Your view of growth (Inputs, yellow) | C18: =Inputs!$C$45 -> 0.057829158
B19: Value per share at your view ($) | C19: =DCF!$C$41 -> 141.99835
B20: Upside or downside at your view | C20: =DCF!$C$43 -> -0.13697378
B22: Fit flag: Deal price
B23: ICE agreed on July 30, 2026 to buy MarketAxess for $167 a share in cash; the stock trades on the deal, not on growth.
B25: How to use this file
B26: 1. Change any blue cell on Inputs, History or WACC; everything recalculates, including the solver.
B27: 2. The Solver tab finds implied growth by bisection with formulas, so you never need Goal Seek. 40 steps narrow a 150-point range to well under 0.0001%.
B28: 3. Type your own growth view in the yellow cell on Inputs; DCF panel B and this page show what the stock is worth if you're right.
B29: 4. Check confirms this workbook matches the Python pipeline that runs the site.
B31: Colour key
B32: Typed input with a source | C32: 1234
B33: Formula | C33: =C32*2 -> 2468
B34: Link to another tab | C34: =Inputs!$C$12 -> 870.03
B35: Your view (edit this one) | C35: =Inputs!$C$45 -> 0.057829158
B37: Live site
B38: https://claude.ai/artifact/DS3n4CgaKxaSLzkXDsBKuK
B40: Built by Rohan Jayapalan. Not investment advice.

Sheet Inputs
B2: MarketAxess (MKTX): inputs
B3: Blue cells are typed inputs with a source. Black cells are formulas. Change a blue cell and every tab recalculates.
B5: Market and price
B6: Price per share at the lock ($) | C6: 164.53538 | E6: Market cap divided by shares from Stock Analysis at the Oct 13, 2026 close.
B7: Diluted shares outstanding (mm) | C7: 35.19 | E7: Stock Analysis statistics page, Oct 13, 2026.
B8: Market value of equity ($mm) | C8: =C6*C7 -> 5790 | E8: Price x shares.
B10: Trailing 12 months
B11: Revenue, reported ($mm) | C11: 870.03 | E11: Stock Analysis income statement, trailing 12 months.
B12: Revenue used in the model ($mm) | C12: =C11 -> 870.03 | E12: Same as reported.
B13: Free cash flow, reported (cash from operations - capex) ($mm) | C13: 194.3 | E13: Stock Analysis cash flow statement, trailing 12 months.
B14: Free cash flow before adjustments ($mm) | C14: =C13 -> 194.3 | E14: Same as reported.
B15: Less: adjustments ($mm) | C15: 0 | E15: None for this company.
B16: Free cash flow used ($mm) | C16: =C14-C15 -> 194.3
B17: Operating income ($mm) | C17: 357.17 | E17: Stock Analysis, trailing 12 months.
B18: Pretax income ($mm) | C18: 367.07 | E18: Stock Analysis, trailing 12 months.
B19: Interest proxy: operating income - pretax, floored at zero ($mm) | C19: =MAX(0,C17-C18) -> 0 | E19: Net interest and other non-operating costs. Adding it back (after tax) turns levered FCF into unlevered FCF.
B20: Tax rate | C20: 0.25 | E20: Statutory blend: 25% US (21% federal plus state), 26.5% Canada (federal plus Ontario).
B21: After-tax interest added back ($mm) | C21: =C19*(1-C20) -> 0
B22: Unlevered free cash flow ($mm) | C22: =C16+C21 -> 194.3
B23: Unlevered free-cash-flow margin | C23: =C22/C12 -> 0.22332563 | E23: Held flat for all 10 years in the model.
B24: EBITDA ($mm) | C24: 434.96 | E24: Stock Analysis, trailing 12 months.
B26: Balance sheet
B27: Total debt ($mm) | C27: 178.91 | E27: Stock Analysis balance sheet, latest quarter.
B28: Cash and equivalents ($mm) | C28: 346.31 | E28: Stock Analysis balance sheet, latest quarter.
B29: Net debt ($mm) | C29: =C27-C28 -> -167.4
B31: Rates
B32: 10-year US Treasury yield | C32: 0.0521 | E32: US Treasury daily par yield curve, Oct 13, 2026.
B33: 10-year TIPS real yield | C33: 0.0288 | E33: US Treasury daily real yield curve, Oct 13, 2026.
B34: Breakeven inflation | C34: =C32-C33 -> 0.0233 | E34: Nominal minus real: the market's inflation expectation.
B35: Risk-free rate used | C35: =C32 -> 0.0521
B36: Real growth added to inflation | C36: 0.005 | E36: Half a point of long-run real growth.
B37: Terminal growth | C37: =MIN(C34+C36,C35) -> 0.0283 | E37: Capped at the risk-free rate.
B38: Equity risk premium | C38: 0.0423 | E38: Damodaran implied equity risk premium, start of 2026.
B40: Growth anchor and verdict
B41: Past revenue growth (CAGR) | C41: =History!$C$12 -> 0.049858317 | E41: FY2021 to the 12 months ended June 2026
B42: Analysts' revenue growth forecast | C42: 0.0658 | E42: Analysts' 3-year revenue CAGR forecast (stockanalysis)
B43: Anchor (average of the two) | C43: =AVERAGE(C41:C42) -> 0.057829158 | E43: AVERAGE skips the n/a text when history isn't used.
B44: Verdict band (+/-) | C44: 0.03 | E44: Set before any backtest and never changed.
B45: Your view of 5-year revenue growth | C45: 0.057829158 | E45: Type your own view. It starts at the anchor. DCF panel B and the Cover show what the stock is worth at your view.
B46: Years at the solved growth rate | C46: 5 | E46: Model v1.0: 5 years at the growth rate, then a straight-line fade.
...

Sheet History
B2: MarketAxess (MKTX): revenue history
B3: Revenue from Stock Analysis income statements; the window is chosen so acquisitions and disposals don't count as growth.
B5: Fiscal year | C5: FY2021 | D5: FY2022 | E5: FY2023 | F5: FY2024 | G5: FY2025 | H5: TTM Jun-26
B6: Revenue ($mm) | C6: 698.95 | D6: 718.3 | E6: 752.55 | F6: 817.1 | G6: 846.27 | H6: 870.03
B7: Growth on the prior year | D7: =D6/C6-1 -> 0.027684384 | E7: =E6/D6-1 -> 0.047682027 | F7: =F6/E6-1 -> 0.085775032 | G7: =G6/F6-1 -> 0.035699425
B10: History window
B11: Start year | C11: FY2021 | E11: Years from start to TTM | G11: 4.5
B12: Revenue CAGR, start to TTM | C12: =(H6/INDEX(C6:H6,MATCH(C11,C5:H5,0)))^(1/G11)-1 -> 0.049858317 | I12: FY2021 to the 12 months ended June 2026
B15: Free-cash-flow margin history
B16: Fiscal year | C16: 2021 | D16: 2022 | E16: 2023 | F16: 2024 | G16: 2025
B17: (CFO - capex) / revenue | C17: 0.3786 | D17: 0.3844 | E17: 0.4311 | F17: 0.4593 | G17: 0.4419 | I17: SEC XBRL filings (NetCashProvidedByOperatingActivities, PaymentsToAcquirePropertyPlantAndEquipment, revenue tags).
B18: Plus today's interest add-back | C18: =C17+(Inputs!$C$23-Inputs!$C$16/Inputs!$C$12) -> 0.3786 | D18: =D17+(Inputs!$C$23-Inputs!$C$16/Inputs!$C$12) -> 0.3844 | E18: =E17+(Inputs!$C$23-Inputs!$C$16/Inputs!$C$12) -> 0.4311 | F18: =F17+(Inputs!$C$23-Inputs!$C$16/Inputs!$C$12) -> 0.4593 | G18: =G17+(Inputs!$C$23-Inputs!$C$16/Inputs!$C$12) -> 0.4419
B19: Range (the margin slider's shaded zone) | C19: =MIN(C18:G18) -> 0.3786 | D19: =MAX(C18:G18) -> 0.4593

Sheet WACC
B2: MarketAxess (MKTX): cost of capital
B3: Bottom-up beta: the median unlevered beta of the company's group, relevered for this company's debt.
B5: Peer | C5: Raw beta | D5: Debt ($mm) | E5: Equity ($mm) | F5: Tax rate | G5: Unlevered beta
B6: Intercontinental Exchange (ICE) | C6: 0.93718463 | D6: 20530 | E6: 87470 | F6: 0.25 | G6: =C6/(1+(1-F6)*D6/E6) -> 0.79690417 | H6: Raw betas: 60 monthly returns to Sep 2026 against the S&P 500 (S&P/TSX for TMX); Cboe uses Stock Analysis's 5-year beta. Debt and equity from Stock Analysis, Oct 13, 2026.
B7: CME Group (CME) | C7: 0.23986632 | D7: 3870 | E7: 99970 | F7: 0.25 | G7: =C7/(1+(1-F7)*D7/E7) -> 0.2330986
B8: Nasdaq (NDAQ) | C8: 0.99189493 | D8: 9320 | E8: 52250 | F8: 0.25 | G8: =C8/(1+(1-F8)*D8/E8) -> 0.87485669
B9: Cboe Global Markets (CBOE) | C9: 0.41 | D9: 1580 | E9: 30520 | F9: 0.25 | G9: =C9/(1+(1-F9)*D9/E9) -> 0.39467592
B10: TMX Group (X) | C10: 0.071228248 | D10: 2070 | E10: 15010 | F10: 0.265 | G10: =C10/(1+(1-F10)*D10/E10) -> 0.064672851
B11: Tradeweb (TW) | C11: 0.61179985 | D11: 150.34 | E11: 25740 | F11: 0.25 | G11: =C11/(1+(1-F11)*D11/E11) -> 0.60913153
B12: MarketAxess (MKTX) | C12: 0.79839643 | D12: 178.91 | E12: 5790 | F12: 0.25 | G12: =C12/(1+(1-F12)*D12/E12) -> 0.78031278
B14: Group median unlevered beta | C14: =MEDIAN(G6:G12) -> 0.60913153
B15: Debt ($mm) | C15: =Inputs!$C$27 -> 178.91
B16: Market value of equity ($mm) | C16: =Inputs!$C$8 -> 5790
B17: Tax rate | C17: =Inputs!$C$20 -> 0.25
B18: Relevered beta | C18: =WACC!$C$14*(1+(1-WACC!$C$17)*WACC!$C$15/WACC!$C$16) -> 0.62324807 | H18: Hamada: unlevered beta x (1 + (1 - tax) x debt / equity).
B19: Risk-free rate | C19: =Inputs!$C$35 -> 0.0521
B20: Equity risk premium | C20: =Inputs!$C$38 -> 0.0423
B21: Cost of equity | C21: =WACC!$C$19+WACC!$C$18*WACC!$C$20 -> 0.078463394 | H21: CAPM: risk-free + beta x premium.
B23: Debt-to-EBITDA spread table
B24: Debt / EBITDA below | C24: Spread
B25: 1 | C25: 0.01 | H25: Synthetic spread over the risk-free rate by leverage, a simplified version of Damodaran's ratings table; the last row covers anything at 4x or above.
B26: 2 | C26: 0.0125
B27: 3 | C27: 0.016
B28: 4 | C28: 0.02
B29: 99 | C29: 0.0275
B31: Debt / EBITDA | C31: =Inputs!$C$27/Inputs!$C$24 -> 0.41132518
B32: Credit spread | C32: =INDEX(C25:C29,COUNTIF(B25:B29,"<="&WACC!$C$31)+1) -> 0.01 | H32: First row whose limit is above this company's leverage.
B33: Pre-tax cost of debt | C33: =WACC!$C$19+WACC!$C$32 -> 0.0621
B34: After-tax cost of debt | C34: =WACC!$C$33*(1-WACC!$C$17) -> 0.046575
B35: Weight of debt | C35: =WACC!$C$15/(WACC!$C$15+WACC!$C$16) -> 0.029973647 | H35: Market-value weights.
B36: Weight of equity | C36: =1-WACC!$C$35 -> 0.97002635
B37: WACC | C37: =WACC!$C$36*WACC!$C$21+WACC!$C$35*WACC!$C$34 -> 0.077507582

Sheet Solver
A1: Solver: bisection for the growth rate that makes the model equal the price (replaces Goal Seek)
B2: Revenue | C2: =Inputs!$C$12 -> 870.03 | D2: Margin | E2: =Inputs!$C$23 -> 0.22332563 | F2: Debt | G2: =Inputs!$C$27 -> 178.91 | H2: Cash | I2: =Inputs!$C$28 -> 346.31 | J2: Shares | K2: =Inputs!$C$7 -> 35.19 | L2: Price | M2: =Inputs!$C$6 -> 164.53538 | N2: Years | O2: =Inputs!$C$46 -> 5 | P2: Fade | Q2: =Inputs!$C$47 -> 5
D3: Year | E3: 1 | F3: 2 | G3: 3 | H3: 4 | I3: 5 | J3: 6 | K3: 7 | L3: 8 | M3: 9 | N3: 10
A4: Each row tries the midpoint of the current range. If the value per share is above the price, the answer is lower, so the top of the range moves down; otherwise the bottom moves up.
A6: Base case: model WACC and terminal growth (40 steps) | E6: WACC | F6: =WACC!$C$37 -> 0.077507582 | G6: Terminal growth | I6: =Inputs!$C$37 -> 0.0283 | W6: Implied growth
A7: Step | B7: Low | C7: High | D7: Mid | E7: Rev Y1 | F7: Rev Y2 | G7: Rev Y3 | H7: Rev Y4 | I7: Rev Y5 | J7: Rev Y6 | K7: Rev Y7 | L7: Rev Y8 | M7: Rev Y9 | N7: Rev Y10 | O7: PV of FCF | P7: PV of TV | Q7: EV | R7: Equity | S7: Per share | T7: Value - price | W7: =$D$47 -> 0.084007684
A8: 1 | B8: -0.5 | C8: 1 | D8: =(B8+C8)/2 -> 0.25 | E8: =$C$2*(1+IF(E$3<=$O$2,$D8,$D8-($D8-$I$6)*MIN(E$3-$O$2,$Q$2)/$Q$2)) -> 1087.5375 | F8: =E8*(1+IF(F$3<=$O$2,$D8,$D8-($D8-$I$6)*MIN(F$3-$O$2,$Q$2)/$Q$2)) -> 1359.4219 | G8: =F8*(1+IF(G$3<=$O$2,$D8,$D8-($D8-$I$6)*MIN(G$3-$O$2,$Q$2)/$Q$2)) -> 1699.2773 | H8: =G8*(1+IF(H$3<=$O$2,$D8,$D8-($D8-$I$6)*MIN(H$3-$O$2,$Q$2)/$Q$2)) -> 2124.0967 | I8: =H8*(1+IF(I$3<=$O$2,$D8,$D8-($D8-$I$6)*MIN(I$3-$O$2,$Q$2)/$Q$2)) -> 2655.1208 | J8: =I8*(1+IF(J$3<=$O$2,$D8,$D8-($D8-$I$6)*MIN(J$3-$O$2,$Q$2)/$Q$2)) -> 3201.173 | K8: =J8*(1+IF(K$3<=$O$2,$D8,$D8-($D8-$I$6)*MIN(K$3-$O$2,$Q$2)/$Q$2)) -> 3717.5862 | L8: =K8*(1+IF(L$3<=$O$2,$D8,$D8-($D8-$I$6)*MIN(L$3-$O$2,$Q$2)/$Q$2)) -> 4152.4695 | M8: =L8*(1+IF(M$3<=$O$2,$D8,$D8-($D8-$I$6)*MIN(M$3-$O$2,$Q$2)/$Q$2)) -> 4454.1049 | N8: =M8*(1+IF(N$3<=$O$2,$D8,$D8-($D8-$I$6)*MIN(N$3-$O$2,$Q$2)/$Q$2)) -> 4580.156 | O8: =SUMPRODUCT(E8:N8,1/(1+$F$6)^$E$3:$N$3)*$E$2 -> 4002.814 | P8: =N8*$E$2*(1+$I$6)/($F$6-$I$6)/(1+$F$6)^$N$3 -> 10132.19 | Q8: =O8+P8 -> 14135.004 | R8: =Q8-$G$2+$I$2 -> 14302.404 | S8: =R8/$K$2 -> 406.43375 | T8: =S8-$M$2 -> 241.89837 | W8: =IF(OR(ABS(W7+0.5)<0.000001,ABS(W7-1)<0.000001),"Out of range","Solved") -> Solved
A9: 2 | B9: =IF(T8>0,B8,D8) -> -0.5 | C9: =IF(T8>0,D8,C8) -> 0.25 | D9: =(B9+C9)/2 -> -0.125 | E9: =$C$2*(1+IF(E$3<=$O$2,$D9,$D9-($D9-$I$6)*MIN(E$3-$O$2,$Q$2)/$Q$2)) -> 761.27625 | F9: =E9*(1+IF(F$3<=$O$2,$D9,$D9-($D9-$I$6)*MIN(F$3-$O$2,$Q$2)/$Q$2)) -> 666.11672 | G9: =F9*(1+IF(G$3<=$O$2,$D9,$D9-($D9-$I$6)*MIN(G$3-$O$2,$Q$2)/$Q$2)) -> 582.85213 | H9: =G9*(1+IF(H$3<=$O$2,$D9,$D9-($D9-$I$6)*MIN(H$3-$O$2,$Q$2)/$Q$2)) -> 509.99561 | I9: =H9*(1+IF(I$3<=$O$2,$D9,$D9-($D9-$I$6)*MIN(I$3-$O$2,$Q$2)/$Q$2)) -> 446.24616 | J9: =I9*(1+IF(J$3<=$O$2,$D9,$D9-($D9-$I$6)*MIN(J$3-$O$2,$Q$2)/$Q$2)) -> 404.1473 | K9: =J9*(1+IF(K$3<=$O$2,$D9,$D9-($D9-$I$6)*MIN(K$3-$O$2,$Q$2)/$Q$2)) -> 378.4112 | L9: =K9*(1+IF(L$3<=$O$2,$D9,$D9-($D9-$I$6)*MIN(L$3-$O$2,$Q$2)/$Q$2)) -> 365.91606 | M9: =L9*(1+IF(M$3<=$O$2,$D9,$D9-($D9-$I$6)*MIN(M$3-$O$2,$Q$2)/$Q$2)) -> 365.0525 | N9: =M9*(1+IF(N$3<=$O$2,$D9,$D9-($D9-$I$6)*MIN(N$3-$O$2,$Q$2)/$Q$2)) -> 375.38348 | O9: =SUMPRODUCT(E9:N9,1/(1+$F$6)^$E$3:$N$3)*$E$2 -> 777.20519 | P9: =N9*$E$2*(1+$I$6)/($F$6-$I$6)/(1+$F$6)^$N$3 -> 830.42076 | Q9: =O9+P9 -> 1607.6259 | R9: =Q9-$G$2+$I$2 -> 1775.0259 | S9: =R9/$K$2 -> 50.441203 | T9: =S9-$M$2 -> -114.09418
A10: 3 | B10: =IF(T9>0,B9,D9) -> -0.125 | C10: =IF(T9>0,D9,C9) -> 0.25 | D10: =(B10+C10)/2 -> 0.0625 | E10: =$C$2*(1+IF(E$3<=$O$2,$D10,$D10-($D10-$I$6)*MIN(E$3-$O$2,$Q$2)/$Q$2)) -> 924.40688 | F10: =E10*(1+IF(F$3<=$O$2,$D10,$D10-($D10-$I$6)*MIN(F$3-$O$2,$Q$2)/$Q$2)) -> 982.1823 | G10: =F10*(1+IF(G$3<=$O$2,$D10,$D10-($D10-$I$6)*MIN(G$3-$O$2,$Q$2)/$Q$2)) -> 1043.5687 | H10: =G10*(1+IF(H$3<=$O$2,$D10,$D10-($D10-$I$6)*MIN(H$3-$O$2,$Q$2)/$Q$2)) -> 1108.7917 | I10: =H10*(1+IF(I$3<=$O$2,$D10,$D10-($D10-$I$6)*MIN(I$3-$O$2,$Q$2)/$Q$2)) -> 1178.0912 | J10: =I10*(1+IF(J$3<=$O$2,$D10,$D10-($D10-$I$6)*MIN(J$3-$O$2,$Q$2)/$Q$2)) -> 1243.6638 | K10: =J10*(1+IF(K$3<=$O$2,$D10,$D10-($D10-$I$6)*MIN(K$3-$O$2,$Q$2)/$Q$2)) -> 1304.3794 | L10: =K10*(1+IF(L$3<=$O$2,$D10,$D10-($D10-$I$6)*MIN(L$3-$O$2,$Q$2)/$Q$2)) -> 1359.1373 | M10: =L10*(1+IF(M$3<=$O$2,$D10,$D10-($D10-$I$6)*MIN(M$3-$O$2,$Q$2)/$Q$2)) -> 1406.8974 | N10: =M10*(1+IF(N$3<=$O$2,$D10,$D10-($D10-$I$6)*MIN(N$3-$O$2,$Q$2)/$Q$2)) -> 1446.7126 | O10: =SUMPRODUCT(E10:N10,1/(1+$F$6)^$E$3:$N$3)*$E$2 -> 1762.5397 | P10: =N10*$E$2*(1+$I$6)/($F$6-$I$6)/(1+$F$6)^$N$3 -> 3200.4076 | Q10: =O10+P10 -> 4962.9473 | R10: =Q10-$G$2+$I$2 -> 5130.3473 | S10: =R10/$K$2 -> 145.78992 | T10: =S10-$M$2 -> -18.74546
A11: 4 | B11: =IF(T10>0,B10,D10) -> 0.0625 | C11: =IF(T10>0,D10,C10) -> 0.25 | D11: =(B11+C11)/2 -> 0.15625 | E11: =$C$2*(1+IF(E$3<=$O$2,$D11,$D11-($D11-$I$6)*MIN(E$3-$O$2,$Q$2)/$Q$2)) -> 1005.9722 | F11: =E11*(1+IF(F$3<=$O$2,$D11,$D11-($D11-$I$6)*MIN(F$3-$O$2,$Q$2)/$Q$2)) -> 1163.1553 | G11: =F11*(1+IF(G$3<=$O$2,$D11,$D11-($D11-$I$6)*MIN(G$3-$O$2,$Q$2)/$Q$2)) -> 1344.8984 | H11: =G11*(1+IF(H$3<=$O$2,$D11,$D11-($D11-$I$6)*MIN(H$3-$O$2,$Q$2)/$Q$2)) -> 1555.0387 | I11: =H11*(1+IF(I$3<=$O$2,$D11,$D11-($D11-$I$6)*MIN(I$3-$O$2,$Q$2)/$Q$2)) -> 1798.0135 | J11: =I11*(1+IF(J$3<=$O$2,$D11,$D11-($D11-$I$6)*MIN(J$3-$O$2,$Q$2)/$Q$2)) -> 2032.942 | K11: =J11*(1+IF(K$3<=$O$2,$D11,$D11-($D11-$I$6)*MIN(K$3-$O$2,$Q$2)/$Q$2)) -> 2246.5432 | L11: =K11*(1+IF(L$3<=$O$2,$D11,$D11-($D11-$I$6)*MIN(L$3-$O$2,$Q$2)/$Q$2)) -> 2425.0985 | M11: =L11*(1+IF(M$3<=$O$2,$D11,$D11-($D11-$I$6)*MIN(M$3-$O$2,$Q$2)/$Q$2)) -> 2555.787 | N11: =M11*(1+IF(N$3<=$O$2,$D11,$D11-($D11-$I$6)*MIN(N$3-$O$2,$Q$2)/$Q$2)) -> 2628.1158 | O11: =SUMPRODUCT(E11:N11,1/(1+$F$6)^$E$3:$N$3)*$E$2 -> 2661.8266 | P11: =N11*$E$2*(1+$I$6)/($F$6-$I$6)/(1+$F$6)^$N$3 -> 5813.8996 | Q11: =O11+P11 -> 8475.7262 | R11: =Q11-$G$2+$I$2 -> 8643.1262 | S11: =R11/$K$2 -> 245.61313 | T11: =S11-$M$2 -> 81.077754
A12: 5 | B12: =IF(T11>0,B11,D11) -> 0.0625 | C12: =IF(T11>0,D11,C11) -> 0.15625 | D12: =(B12+C12)/2 -> 0.109375 | E12: =$C$2*(1+IF(E$3<=$O$2,$D12,$D12-($D12-$I$6)*MIN(E$3-$O$2,$Q$2)/$Q$2)) -> 965.18953 | F12: =E12*(1+IF(F$3<=$O$2,$D12,$D12-($D12-$I$6)*MIN(F$3-$O$2,$Q$2)/$Q$2)) -> 1070.7571 | G12: =F12*(1+IF(G$3<=$O$2,$D12,$D12-($D12-$I$6)*MIN(G$3-$O$2,$Q$2)/$Q$2)) -> 1187.8712 | H12: =G12*(1+IF(H$3<=$O$2,$D12,$D12-($D12-$I$6)*MIN(H$3-$O$2,$Q$2)/$Q$2)) -> 1317.7946 | I12: =H12*(1+IF(I$3<=$O$2,$D12,$D12-($D12-$I$6)*MIN(I$3-$O$2,$Q$2)/$Q$2)) -> 1461.9284 | J12: =I12*(1+IF(J$3<=$O$2,$D12,$D12-($D12-$I$6)*MIN(J$3-$O$2,$Q$2)/$Q$2)) -> 1598.1216 | K12: =J12*(1+IF(K$3<=$O$2,$D12,$D12-($D12-$I$6)*MIN(K$3-$O$2,$Q$2)/$Q$2)) -> 1721.0891 | L12: =K12*(1+IF(L$3<=$O$2,$D12,$D12-($D12-$I$6)*MIN(L$3-$O$2,$Q$2)/$Q$2)) -> 1825.6109 | M12: =L12*(1+IF(M$3<=$O$2,$D12,$D12-($D12-$I$6)*MIN(M$3-$O$2,$Q$2)/$Q$2)) -> 1906.8779 | N12: =M12*(1+IF(N$3<=$O$2,$D12,$D12-($D12-$I$6)*MIN(N$3-$O$2,$Q$2)/$Q$2)) -> 1960.8426 | O12: =SUMPRODUCT(E12:N12,1/(1+$F$6)^$E$3:$N$3)*$E$2 -> 2166.6151 | P12: =N12*$E$2*(1+$I$6)/($F$6-$I$6)/(1+$F$6)^$N$3 -> 4337.7624 | Q12: =O12+P12 -> 6504.3775 | R12: =Q12-$G$2+$I$2 -> 6671.7775 | S12: =R12/$K$2 -> 189.59299 | T12: =S12-$M$2 -> 25.057615
A13: 6 | B13: =IF(T12>0,B12,D12) -> 0.0625 | C13: =IF(T12>0,D12,C12) -> 0.109375 | D13: =(B13+C13)/2 -> 0.0859375 | E13: =$C$2*(1+IF(E$3<=$O$2,$D13,$D13-($D13-$I$6)*MIN(E$3-$O$2,$Q$2)/$Q$2)) -> 944.7982 | F13: =E13*(1+IF(F$3<=$O$2,$D13,$D13-($D13-$I$6)*MIN(F$3-$O$2,$Q$2)/$Q$2)) -> 1025.9918 | G13: =F13*(1+IF(G$3<=$O$2,$D13,$D13-($D13-$I$6)*MIN(G$3-$O$2,$Q$2)/$Q$2)) -> 1114.163 | H13: =G13*(1+IF(H$3<=$O$2,$D13,$D13-($D13-$I$6)*MIN(H$3-$O$2,$Q$2)/$Q$2)) -> 1209.9113 | I13: =H13*(1+IF(I$3<=$O$2,$D13,$D13-($D13-$I$6)*MIN(I$3-$O$2,$Q$2)/$Q$2)) -> 1313.8881 | J13: =I13*(1+IF(J$3<=$O$2,$D13,$D13-($D13-$I$6)*MIN(J$3-$O$2,$Q$2)/$Q$2)) -> 1411.6545 | K13: =J13*(1+IF(K$3<=$O$2,$D13,$D13-($D13-$I$6)*MIN(K$3-$O$2,$Q$2)/$Q$2)) -> 1500.4229 | L13: =K13*(1+IF(L$3<=$O$2,$D13,$D13-($D13-$I$6)*MIN(L$3-$O$2,$Q$2)/$Q$2)) -> 1577.4771 | M13: =L13*(1+IF(M$3<=$O$2,$D13,$D13-($D13-$I$6)*MIN(M$3-$O$2,$Q$2)/$Q$2)) -> 1640.3041 | N13: =M13*(1+IF(N$3<=$O$2,$D13,$D13-($D13-$I$6)*MIN(N$3-$O$2,$Q$2)/$Q$2)) -> 1686.7247 | O13: =SUMPRODUCT(E13:N13,1/(1+$F$6)^$E$3:$N$3)*$E$2 -> 1954.2295 | P13: =N13*$E$2*(1+$I$6)/($F$6-$I$6)/(1+$F$6)^$N$3 -> 3731.3607 | Q13: =O13+P13 -> 5685.5902 | R13: =Q13-$G$2+$I$2 -> 5852.9902 | S13: =R13/$K$2 -> 166.32538 | T13: =S13-$M$2 -> 1.7900016
A14: 7 | B14: =IF(T13>0,B13,D13) -> 0.0625 | C14: =IF(T13>0,D13,C13) -> 0.0859375 | D14: =(B14+C14)/2 -> 0.07421875 | E14: =$C$2*(1+IF(E$3<=$O$2,$D14,$D14-($D14-$I$6)*MIN(E$3-$O$2,$Q$2)/$Q$2)) -> 934.60254 | F14: =E14*(1+IF(F$3<=$O$2,$D14,$D14-($D14-$I$6)*MIN(F$3-$O$2,$Q$2)/$Q$2)) -> 1003.9676 | G14: =F14*(1+IF(G$3<=$O$2,$D14,$D14-($D14-$I$6)*MIN(G$3-$O$2,$Q$2)/$Q$2)) -> 1078.4808 | H14: =G14*(1+IF(H$3<=$O$2,$D14,$D14-($D14-$I$6)*MIN(H$3-$O$2,$Q$2)/$Q$2)) -> 1158.5243 | I14: =H14*(1+IF(I$3<=$O$2,$D14,$D14-($D14-$I$6)*MIN(I$3-$O$2,$Q$2)/$Q$2)) -> 1244.5085 | J14: =I14*(1+IF(J$3<=$O$2,$D14,$D14-($D14-$I$6)*MIN(J$3-$O$2,$Q$2)/$Q$2)) -> 1325.4451 | K14: =J14*(1+IF(K$3<=$O$2,$D14,$D14-($D14-$I$6)*MIN(K$3-$O$2,$Q$2)/$Q$2)) -> 1399.4729 | L14: =K14*(1+IF(L$3<=$O$2,$D14,$D14-($D14-$I$6)*MIN(L$3-$O$2,$Q$2)/$Q$2)) -> 1464.7828 | M14: =L14*(1+IF(M$3<=$O$2,$D14,$D14-($D14-$I$6)*MIN(M$3-$O$2,$Q$2)/$Q$2)) -> 1519.6883 | N14: =M14*(1+IF(N$3<=$O$2,$D14,$D14-($D14-$I$6)*MIN(N$3-$O$2,$Q$2)/$Q$2)) -> 1562.6955 | O14: =SUMPRODUCT(E14:N14,1/(1+$F$6)^$E$3:$N$3)*$E$2 -> 1855.919 | P14: =N14*$E$2*(1+$I$6)/($F$6-$I$6)/(1+$F$6)^$N$3 -> 3456.9843 | Q14: =O14+P14 -> 5312.9032 | R14: =Q14-$G$2+$I$2 -> 5480.3032 | S14: =R14/$K$2 -> 155.73468 | T14: =S14-$M$2 -> -8.8007036
A15: 8 | B15: =IF(T14>0,B14,D14) -> 0.07421875 | C15: =IF(T14>0,D14,C14) -> 0.0859375 | D15: =(B15+C15)/2 -> 0.080078125 | E15: =$C$2*(1+IF(E$3<=$O$2,$D15,$D15-($D15-$I$6)*MIN(E$3-$O$2,$Q$2)/$Q$2)) -> 939.70037 | F15: =E15*(1+IF(F$3<=$O$2,$D15,$D15-($D15-$I$6)*MIN(F$3-$O$2,$Q$2)/$Q$2)) -> 1014.9498 | G15: =F15*(1+IF(G$3<=$O$2,$D15,$D15-($D15-$I$6)*MIN(G$3-$O$2,$Q$2)/$Q$2)) -> 1096.2251 | H15: =G15*(1+IF(H$3<=$O$2,$D15,$D15-($D15-$I$6)*MIN(H$3-$O$2,$Q$2)/$Q$2)) -> 1184.0087 | I15: =H15*(1+IF(I$3<=$O$2,$D15,$D15-($D15-$I$6)*MIN(I$3-$O$2,$Q$2)/$Q$2)) -> 1278.8219 | J15: =I15*(1+IF(J$3<=$O$2,$D15,$D15-($D15-$I$6)*MIN(J$3-$O$2,$Q$2)/$Q$2)) -> 1367.9846 | K15: =J15*(1+IF(K$3<=$O$2,$D15,$D15-($D15-$I$6)*MIN(K$3-$O$2,$Q$2)/$Q$2)) -> 1449.1976 | L15: =K15*(1+IF(L$3<=$O$2,$D15,$D15-($D15-$I$6)*MIN(L$3-$O$2,$Q$2)/$Q$2)) -> 1520.2246 | M15: =L15*(1+IF(M$3<=$O$2,$D15,$D15-($D15-$I$6)*MIN(M$3-$O$2,$Q$2)/$Q$2)) -> 1578.9898 | N15: =M15*(1+IF(N$3<=$O$2,$D15,$D15-($D15-$I$6)*MIN(N$3-$O$2,$Q$2)/$Q$2)) -> 1623.6752 | O15: =SUMPRODUCT(E15:N15,1/(1+$F$6)^$E$3:$N$3)*$E$2 -> 1904.443 | P15: =N15*$E$2*(1+$I$6)/($F$6-$I$6)/(1+$F$6)^$N$3 -> 3591.8831 | Q15: =O15+P15 -> 5496.3261 | R15: =Q15-$G$2+$I$2 -> 5663.7261 | S15: =R15/$K$2 -> 160.94703 | T15: =S15-$M$2 -> -3.5883452
A16: 9 | B16: =IF(T15>0,B15,D15) -> 0.080078125 | C16: =IF(T15>0,D15,C15) -> 0.0859375 | D16: =(B16+C16)/2 -> 0.083007812 | E16: =$C$2*(1+IF(E$3<=$O$2,$D16,$D16-($D16-$I$6)*MIN(E$3-$O$2,$Q$2)/$Q$2)) -> 942.24929 | F16: =E16*(1+IF(F$3<=$O$2,$D16,$D16-($D16-$I$6)*MIN(F$3-$O$2,$Q$2)/$Q$2)) -> 1020.4633 | G16: =F16*(1+IF(G$3<=$O$2,$D16,$D16-($D16-$I$6)*MIN(G$3-$O$2,$Q$2)/$Q$2)) -> 1105.1698 | H16: =G16*(1+IF(H$3<=$O$2,$D16,$D16-($D16-$I$6)*MIN(H$3-$O$2,$Q$2)/$Q$2)) -> 1196.9075 | I16: =H16*(1+IF(I$3<=$O$2,$D16,$D16-($D16-$I$6)*MIN(I$3-$O$2,$Q$2)/$Q$2)) -> 1296.2602 | J16: =I16*(1+IF(J$3<=$O$2,$D16,$D16-($D16-$I$6)*MIN(J$3-$O$2,$Q$2)/$Q$2)) -> 1389.6768 | K16: =J16*(1+IF(K$3<=$O$2,$D16,$D16-($D16-$I$6)*MIN(K$3-$O$2,$Q$2)/$Q$2)) -> 1474.6203 | L16: =K16*(1+IF(L$3<=$O$2,$D16,$D16-($D16-$I$6)*MIN(L$3-$O$2,$Q$2)/$Q$2)) -> 1548.6214 | M16: =L16*(1+IF(M$3<=$O$2,$D16,$D16-($D16-$I$6)*MIN(M$3-$O$2,$Q$2)/$Q$2)) -> 1609.3917 | N16: =M16*(1+IF(N$3<=$O$2,$D16,$D16-($D16-$I$6)*MIN(N$3-$O$2,$Q$2)/$Q$2)) -> 1654.9375 | O16: =SUMPRODUCT(E16:N16,1/(1+$F$6)^$E$3:$N$3)*$E$2 -> 1929.1766 | P16: =N16*$E$2*(1+$I$6)/($F$6-$I$6)/(1+$F$6)^$N$3 -> 3661.0413 | Q16: =O16+P16 -> 5590.2179 | R16: =Q16-$G$2+$I$2 -> 5757.6179 | S16: =R16/$K$2 -> 163.61517 | T16: =S16-$M$2 -> -0.92020749
A17: 10 | B17: =IF(T16>0,B16,D16) -> 0.083007812 | C17: =IF(T16>0,D16,C16) -> 0.0859375 | D17: =(B17+C17)/2 -> 0.084472656 | E17: =$C$2*(1+IF(E$3<=$O$2,$D17,$D17-($D17-$I$6)*MIN(E$3-$O$2,$Q$2)/$Q$2)) -> 943.52375 | F17: =E17*(1+IF(F$3<=$O$2,$D17,$D17-($D17-$I$6)*MIN(F$3-$O$2,$Q$2)/$Q$2)) -> 1023.2257 | G17: =F17*(1+IF(G$3<=$O$2,$D17,$D17-($D17-$I$6)*MIN(G$3-$O$2,$Q$2)/$Q$2)) -> 1109.6603 | H17: =G17*(1+IF(H$3<=$O$2,$D17,$D17-($D17-$I$6)*MIN(H$3-$O$2,$Q$2)/$Q$2)) -> 1203.3962 | I17: =H17*(1+IF(I$3<=$O$2,$D17,$D17-($D17-$I$6)*MIN(I$3-$O$2,$Q$2)/$Q$2)) -> 1305.0503 | J17: =I17*(1+IF(J$3<=$O$2,$D17,$D17-($D17-$I$6)*MIN(J$3-$O$2,$Q$2)/$Q$2)) -> 1400.6298 | K17: =J17*(1+IF(K$3<=$O$2,$D17,$D17-($D17-$I$6)*MIN(K$3-$O$2,$Q$2)/$Q$2)) -> 1487.4738 | L17: =K17*(1+IF(L$3<=$O$2,$D17,$D17-($D17-$I$6)*MIN(L$3-$O$2,$Q$2)/$Q$2)) -> 1562.9915 | M17: =L17*(1+IF(M$3<=$O$2,$D17,$D17-($D17-$I$6)*MIN(M$3-$O$2,$Q$2)/$Q$2)) -> 1624.7836 | N17: =M17*(1+IF(N$3<=$O$2,$D17,$D17-($D17-$I$6)*MIN(N$3-$O$2,$Q$2)/$Q$2)) -> 1670.765 | O17: =SUMPRODUCT(E17:N17,1/(1+$F$6)^$E$3:$N$3)*$E$2 -> 1941.6629 | P17: =N17*$E$2*(1+$I$6)/($F$6-$I$6)/(1+$F$6)^$N$3 -> 3696.0548 | Q17: =O17+P17 -> 5637.7177 | R17: =Q17-$G$2+$I$2 -> 5805.1177 | S17: =R17/$K$2 -> 164.96498 | T17: =S17-$M$2 -> 0.4296019
A18: 11 | B18: =IF(T17>0,B17,D17) -> 0.083007812 | C18: =IF(T17>0,D17,C17) -> 0.084472656 | D18: =(B18+C18)/2 -> 0.083740234 | E18: =$C$2*(1+IF(E$3<=$O$2,$D18,$D18-($D18-$I$6)*MIN(E$3-$O$2,$Q$2)/$Q$2)) -> 942.88652 | F18: =E18*(1+IF(F$3<=$O$2,$D18,$D18-($D18-$I$6)*MIN(F$3-$O$2,$Q$2)/$Q$2)) -> 1021.8441 | G18: =F18*(1+IF(G$3<=$O$2,$D18,$D18-($D18-$I$6)*MIN(G$3-$O$2,$Q$2)/$Q$2)) -> 1107.4135 | H18: =G18*(1+IF(H$3<=$O$2,$D18,$D18-($D18-$I$6)*MIN(H$3-$O$2,$Q$2)/$Q$2)) -> 1200.1486 | I18: =H18*(1+IF(I$3<=$O$2,$D18,$D18-($D18-$I$6)*MIN(I$3-$O$2,$Q$2)/$Q$2)) -> 1300.6493 | J18: =I18*(1+IF(J$3<=$O$2,$D18,$D18-($D18-$I$6)*MIN(J$3-$O$2,$Q$2)/$Q$2)) -> 1395.1443 | K18: =J18*(1+IF(K$3<=$O$2,$D18,$D18-($D18-$I$6)*MIN(K$3-$O$2,$Q$2)/$Q$2)) -> 1481.0352 | L18: =K18*(1+IF(L$3<=$O$2,$D18,$D18-($D18-$I$6)*MIN(L$3-$O$2,$Q$2)/$Q$2)) -> 1555.7921 | M18: =L18*(1+IF(M$3<=$O$2,$D18,$D18-($D18-$I$6)*MIN(M$3-$O$2,$Q$2)/$Q$2)) -> 1617.0717 | N18: =M18*(1+IF(N$3<=$O$2,$D18,$D18-($D18-$I$6)*MIN(N$3-$O$2,$Q$2)/$Q$2)) -> 1662.8348 | O18: =SUMPRODUCT(E18:N18,1/(1+$F$6)^$E$3:$N$3)*$E$2 -> 1935.4097 | P18: =N18*$E$2*(1+$I$6)/($F$6-$I$6)/(1+$F$6)^$N$3 -> 3678.5117 | Q18: =O18+P18 -> 5613.9214 | R18: =Q18-$G$2+$I$2 -> 5781.3214 | S18: =R18/$K$2 -> 164.28876 | T18: =S18-$M$2 -> -0.24662204
A19: 12 | B19: =IF(T18>0,B18,D18) -> 0.083740234 | C19: =IF(T18>0,D18,C18) -> 0.084472656 | D19: =(B19+C19)/2 -> 0.084106445 | E19: =$C$2*(1+IF(E$3<=$O$2,$D19,$D19-($D19-$I$6)*MIN(E$3-$O$2,$Q$2)/$Q$2)) -> 943.20513 | F19: =E19*(1+IF(F$3<=$O$2,$D19,$D19-($D19-$I$6)*MIN(F$3-$O$2,$Q$2)/$Q$2)) -> 1022.5348 | G19: =F19*(1+IF(G$3<=$O$2,$D19,$D19-($D19-$I$6)*MIN(G$3-$O$2,$Q$2)/$Q$2)) -> 1108.5365 | H19: =G19*(1+IF(H$3<=$O$2,$D19,$D19-($D19-$I$6)*MIN(H$3-$O$2,$Q$2)/$Q$2)) -> 1201.7716 | I19: =H19*(1+IF(I$3<=$O$2,$D19,$D19-($D19-$I$6)*MIN(I$3-$O$2,$Q$2)/$Q$2)) -> 1302.8483 | J19: =I19*(1+IF(J$3<=$O$2,$D19,$D19-($D19-$I$6)*MIN(J$3-$O$2,$Q$2)/$Q$2)) -> 1397.8848 | K19: =J19*(1+IF(K$3<=$O$2,$D19,$D19-($D19-$I$6)*MIN(K$3-$O$2,$Q$2)/$Q$2)) -> 1484.2515 | L19: =K19*(1+IF(L$3<=$O$2,$D19,$D19-($D19-$I$6)*MIN(L$3-$O$2,$Q$2)/$Q$2)) -> 1559.3882 | M19: =L19*(1+IF(M$3<=$O$2,$D19,$D19-($D19-$I$6)*MIN(M$3-$O$2,$Q$2)/$Q$2)) -> 1620.9236 | N19: =M19*(1+IF(N$3<=$O$2,$D19,$D19-($D19-$I$6)*MIN(N$3-$O$2,$Q$2)/$Q$2)) -> 1666.7958 | O19: =SUMPRODUCT(E19:N19,1/(1+$F$6)^$E$3:$N$3)*$E$2 -> 1938.5338 | P19: =N19*$E$2*(1+$I$6)/($F$6-$I$6)/(1+$F$6)^$N$3 -> 3687.2741 | Q19: =O19+P19 -> 5625.8079 | R19: =Q19-$G$2+$I$2 -> 5793.2079 | S19: =R19/$K$2 -> 164.62654 | T19: =S19-$M$2 -> 0.091159548
A20: 13 | B20: =IF(T19>0,B19,D19) -> 0.083740234 | C20: =IF(T19>0,D19,C19) -> 0.084106445 | D20: =(B20+C20)/2 -> 0.08392334 | E20: =$C$2*(1+IF(E$3<=$O$2,$D20,$D20-($D20-$I$6)*MIN(E$3-$O$2,$Q$2)/$Q$2)) -> 943.04582 | F20: =E20*(1+IF(F$3<=$O$2,$D20,$D20-($D20-$I$6)*MIN(F$3-$O$2,$Q$2)/$Q$2)) -> 1022.1894 | G20: =F20*(1+IF(G$3<=$O$2,$D20,$D20-($D20-$I$6)*MIN(G$3-$O$2,$Q$2)/$Q$2)) -> 1107.9749 | H20: =G20*(1+IF(H$3<=$O$2,$D20,$D20-($D20-$I$6)*MIN(H$3-$O$2,$Q$2)/$Q$2)) -> 1200.9599 | I20: =H20*(1+IF(I$3<=$O$2,$D20,$D20-($D20-$I$6)*MIN(I$3-$O$2,$Q$2)/$Q$2)) -> 1301.7484 | J20: =I20*(1+IF(J$3<=$O$2,$D20,$D20-($D20-$I$6)*MIN(J$3-$O$2,$Q$2)/$Q$2)) -> 1396.514 | K20: =J20*(1+IF(K$3<=$O$2,$D20,$D20-($D20-$I$6)*MIN(K$3-$O$2,$Q$2)/$Q$2)) -> 1482.6426 | L20: =K20*(1+IF(L$3<=$O$2,$D20,$D20-($D20-$I$6)*MIN(L$3-$O$2,$Q$2)/$Q$2)) -> 1557.5892 | M20: =L20*(1+IF(M$3<=$O$2,$D20,$D20-($D20-$I$6)*MIN(M$3-$O$2,$Q$2)/$Q$2)) -> 1618.9967 | N20: =M20*(1+IF(N$3<=$O$2,$D20,$D20-($D20-$I$6)*MIN(N$3-$O$2,$Q$2)/$Q$2)) -> 1664.8143 | O20: =SUMPRODUCT(E20:N20,1/(1+$F$6)^$E$3:$N$3)*$E$2 -> 1936.9711 | P20: =N20*$E$2*(1+$I$6)/($F$6-$I$6)/(1+$F$6)^$N$3 -> 3682.8906 | Q20: =O20+P20 -> 5619.8617 | R20: =Q20-$G$2+$I$2 -> 5787.2617 | S20: =R20/$K$2 -> 164.45757 | T20: =S20-$M$2 -> -0.077813771
... A47: 40 | B47: =IF(T46>0,B46,D46) -> 0.084007684 | C47: =IF(T46>0,D46,C46) -> 0.084007684 | D47: =(B47+C47)/2 -> 0.084007684 | E47: =$C$2*(1+IF(E$3<=$O$2,$D47,$D47-($D47-$I$6)*MIN(E$3-$O$2,$Q$2)/$Q$2)) -> 943.11921 | F47: =E47*(1+IF(F$3<=$O$2,$D47,$D47-($D47-$I$6)*MIN(F$3-$O$2,$Q$2)/$Q$2)) -> 1022.3485 | G47: =F47*(1+IF(G$3<=$O$2,$D47,$D47-($D47-$I$6)*MIN(G$3-$O$2,$Q$2)/$Q$2)) -> 1108.2336 | H47: =G47*(1+IF(H$3<=$O$2,$D47,$D47-($D47-$I$6)*MIN(H$3-$O$2,$Q$2)/$Q$2)) -> 1201.3337 | I47: =H47*(1+IF(I$3<=$O$2,$D47,$D47-($D47-$I$6)*MIN(I$3-$O$2,$Q$2)/$Q$2)) -> 1302.255 | J47: =I47*(1+IF(J$3<=$O$2,$D47,$D47-($D47-$I$6)*MIN(J$3-$O$2,$Q$2)/$Q$2)) -> 1397.1453 | K47: =J47*(1+IF(K$3<=$O$2,$D47,$D47-($D47-$I$6)*MIN(K$3-$O$2,$Q$2)/$Q$2)) -> 1483.3835 | L47: =K47*(1+IF(L$3<=$O$2,$D47,$D47-($D47-$I$6)*MIN(L$3-$O$2,$Q$2)/$Q$2)) -> 1558.4176 | M47: =L47*(1+IF(M$3<=$O$2,$D47,$D47-($D47-$I$6)*MIN(M$3-$O$2,$Q$2)/$Q$2)) -> 1619.884 | N47: =M47*(1+IF(N$3<=$O$2,$D47,$D47-($D47-$I$6)*MIN(N$3-$O$2,$Q$2)/$Q$2)) -> 1665.7267 | O47: =SUMPRODUCT(E47:N47,1/(1+$F$6)^$E$3:$N$3)*$E$2 -> 1937.6908 | P47: =N47*$E$2*(1+$I$6)/($F$6-$I$6)/(1+$F$6)^$N$3 -> 3684.9092 | Q47: =O47+P47 -> 5622.6 | R47: =Q47-$G$2+$I$2 -> 5790 | S47: =R47/$K$2 -> 164.53538 | T47: =S47-$M$2 -> -6.9223915e-10
A49: Grid block 2: row 1, column 1 of table A (24 steps) | E49: WACC | F49: =Sensitivity!$B$10 -> 0.067507582 | G49: Terminal growth | I49: =Sensitivity!$C$9 -> 0.0183
A50: Step | B50: Low | C50: High | D50: Mid | E50: Rev Y1 | F50: Rev Y2 | G50: Rev Y3 | H50: Rev Y4 | I50: Rev Y5 | J50: Rev Y6 | K50: Rev Y7 | L50: Rev Y8 | M50: Rev Y9 | N50: Rev Y10 | O50: PV of FCF | P50: PV of TV | Q50: EV | R50: Equity | S50: Per share | T50: Value - price
A51: 1 | B51: -0.5 | C51: 1 | D51: =(B51+C51)/2 -> 0.25 | E51: =$C$2*(1+IF(E$3<=$O$2,$D51,$D51-($D51-$I$49)*MIN(E$3-$O$2,$Q$2)/$Q$2)) -> 1087.5375 | F51: =E51*(1+IF(F$3<=$O$2,$D51,$D51-($D51-$I$49)*MIN(F$3-$O$2,$Q$2)/$Q$2)) -> 1359.4219 | G51: =F51*(1+IF(G$3<=$O$2,$D51,$D51-($D51-$I$49)*MIN(G$3-$O$2,$Q$2)/$Q$2)) -> 1699.2773 | H51: =G51*(1+IF(H$3<=$O$2,$D51,$D51-($D51-$I$49)*MIN(H$3-$O$2,$Q$2)/$Q$2)) -> 2124.0967 | I51: =H51*(1+IF(I$3<=$O$2,$D51,$D51-($D51-$I$49)*MIN(I$3-$O$2,$Q$2)/$Q$2)) -> 2655.1208 | J51: =I51*(1+IF(J$3<=$O$2,$D51,$D51-($D51-$I$49)*MIN(J$3-$O$2,$Q$2)/$Q$2)) -> 3195.8628 | K51: =J51*(1+IF(K$3<=$O$2,$D51,$D51-($D51-$I$49)*MIN(K$3-$O$2,$Q$2)/$Q$2)) -> 3698.6359 | L51: =K51*(1+IF(L$3<=$O$2,$D51,$D51-($D51-$I$49)*MIN(L$3-$O$2,$Q$2)/$Q$2)) -> 4109.1105 | M51: =L51*(1+IF(M$3<=$O$2,$D51,$D51-($D51-$I$49)*MIN(M$3-$O$2,$Q$2)/$Q$2)) -> 4374.7234 | N51: =M51*(1+IF(N$3<=$O$2,$D51,$D51-($D51-$I$49)*MIN(N$3-$O$2,$Q$2)/$Q$2)) -> 4454.7808 | O51: =SUMPRODUCT(E51:N51,1/(1+$F$49)^$E$3:$N$3)*$E$2 -> 4208.541 | P51: =N51*$E$2*(1+$I$49)/($F$49-$I$49)/(1+$F$49)^$N$3 -> 10712.7 | Q51: =O51+P51 -> 14921.241 | R51: =Q51-$G$2+$I$2 -> 15088.641 | S51: =R51/$K$2 -> 428.77639 | T51: =S51-$M$2 -> 264.24101
A52: 2 | B52: =IF(T51>0,B51,D51) -> -0.5 | C52: =IF(T51>0,D51,C51) -> 0.25 | D52: =(B52+C52)/2 -> -0.125 | E52: =$C$2*(1+IF(E$3<=$O$2,$D52,$D52-($D52-$I$49)*MIN(E$3-$O$2,$Q$2)/$Q$2)) -> 761.27625 | F52: =E52*(1+IF(F$3<=$O$2,$D52,$D52-($D52-$I$49)*MIN(F$3-$O$2,$Q$2)/$Q$2)) -> 666.11672 | G52: =F52*(1+IF(G$3<=$O$2,$D52,$D52-($D52-$I$49)*MIN(G$3-$O$2,$Q$2)/$Q$2)) -> 582.85213 | H52: =G52*(1+IF(H$3<=$O$2,$D52,$D52-($D52-$I$49)*MIN(H$3-$O$2,$Q$2)/$Q$2)) -> 509.99561 | I52: =H52*(1+IF(I$3<=$O$2,$D52,$D52-($D52-$I$49)*MIN(I$3-$O$2,$Q$2)/$Q$2)) -> 446.24616 | J52: =I52*(1+IF(J$3<=$O$2,$D52,$D52-($D52-$I$49)*MIN(J$3-$O$2,$Q$2)/$Q$2)) -> 403.25481 | K52: =J52*(1+IF(K$3<=$O$2,$D52,$D52-($D52-$I$49)*MIN(K$3-$O$2,$Q$2)/$Q$2)) -> 375.96252 | L52: =K52*(1+IF(L$3<=$O$2,$D52,$D52-($D52-$I$49)*MIN(L$3-$O$2,$Q$2)/$Q$2)) -> 361.29246 | M52: =L52*(1+IF(M$3<=$O$2,$D52,$D52-($D52-$I$49)*MIN(M$3-$O$2,$Q$2)/$Q$2)) -> 357.54947 | N52: =M52*(1+IF(N$3<=$O$2,$D52,$D52-($D52-$I$49)*MIN(N$3-$O$2,$Q$2)/$Q$2)) -> 364.09263 | O52: =SUMPRODUCT(E52:N52,1/(1+$F$49)^$E$3:$N$3)*$E$2 -> 804.90563 | P52: =N52*$E$2*(1+$I$49)/($F$49-$I$49)/(1+$F$49)^$N$3 -> 875.55714 | Q52: =O52+P52 -> 1680.4628 | R52: =Q52-$G$2+$I$2 -> 1847.8628 | S52: =R52/$K$2 -> 52.511019 | T52: =S52-$M$2 -> -112.02436
A53: 3 | B53: =IF(T52>0,B52,D52) -> -0.125 | C53: =IF(T52>0,D52,C52) -> 0.25 | D53: =(B53+C53)/2 -> 0.0625 | E53: =$C$2*(1+IF(E$3<=$O$2,$D53,$D53-($D53-$I$49)*MIN(E$3-$O$2,$Q$2)/$Q$2)) -> 924.40688 | F53: =E53*(1+IF(F$3<=$O$2,$D53,$D53-($D53-$I$49)*MIN(F$3-$O$2,$Q$2)/$Q$2)) -> 982.1823 | G53: =F53*(1+IF(G$3<=$O$2,$D53,$D53-($D53-$I$49)*MIN(G$3-$O$2,$Q$2)/$Q$2)) -> 1043.5687 | H53: =G53*(1+IF(H$3<=$O$2,$D53,$D53-($D53-$I$49)*MIN(H$3-$O$2,$Q$2)/$Q$2)) -> 1108.7917 | I53: =H53*(1+IF(I$3<=$O$2,$D53,$D53-($D53-$I$49)*MIN(I$3-$O$2,$Q$2)/$Q$2)) -> 1178.0912 | J53: =I53*(1+IF(J$3<=$O$2,$D53,$D53-($D53-$I$49)*MIN(J$3-$O$2,$Q$2)/$Q$2)) -> 1241.3076 | K53: =J53*(1+IF(K$3<=$O$2,$D53,$D53-($D53-$I$49)*MIN(K$3-$O$2,$Q$2)/$Q$2)) -> 1296.943 | L53: =K53*(1+IF(L$3<=$O$2,$D53,$D53-($D53-$I$49)*MIN(L$3-$O$2,$Q$2)/$Q$2)) -> 1343.607 | M53: =L53*(1+IF(M$3<=$O$2,$D53,$D53-($D53-$I$49)*MIN(M$3-$O$2,$Q$2)/$Q$2)) -> 1380.0725 | N53: =M53*(1+IF(N$3<=$O$2,$D53,$D53-($D53-$I$49)*MIN(N$3-$O$2,$Q$2)/$Q$2)) -> 1405.3278 | O53: =SUMPRODUCT(E53:N53,1/(1+$F$49)^$E$3:$N$3)*$E$2 -> 1841.0137 | P53: =N53*$E$2*(1+$I$49)/($F$49-$I$49)/(1+$F$49)^$N$3 -> 3379.4829 | Q53: =O53+P53 -> 5220.4966 | R53: =Q53-$G$2+$I$2 -> 5387.8966 | S53: =R53/$K$2 -> 153.10874 | T53: =S53-$M$2 -> -11.426638
A54: 4 | B54: =IF(T53>0,B53,D53) -> 0.0625 | C54: =IF(T53>0,D53,C53) -> 0.25 | D54: =(B54+C54)/2 -> 0.15625 | E54: =$C$2*(1+IF(E$3<=$O$2,$D54,$D54-($D54-$I$49)*MIN(E$3-$O$2,$Q$2)/$Q$2)) -> 1005.9722 | F54: =E54*(1+IF(F$3<=$O$2,$D54,$D54-($D54-$I$49)*MIN(F$3-$O$2,$Q$2)/$Q$2)) -> 1163.1553 | G54: =F54*(1+IF(G$3<=$O$2,$D54,$D54-($D54-$I$49)*MIN(G$3-$O$2,$Q$2)/$Q$2)) -> 1344.8984 | H54: =G54*(1+IF(H$3<=$O$2,$D54,$D54-($D54-$I$49)*MIN(H$3-$O$2,$Q$2)/$Q$2)) -> 1555.0387 | I54: =H54*(1+IF(I$3<=$O$2,$D54,$D54-($D54-$I$49)*MIN(I$3-$O$2,$Q$2)/$Q$2)) -> 1798.0135 | J54: =I54*(1+IF(J$3<=$O$2,$D54,$D54-($D54-$I$49)*MIN(J$3-$O$2,$Q$2)/$Q$2)) -> 2029.346 | K54: =J54*(1+IF(K$3<=$O$2,$D54,$D54-($D54-$I$49)*MIN(K$3-$O$2,$Q$2)/$Q$2)) -> 2234.452 | L54: =K54*(1+IF(L$3<=$O$2,$D54,$D54-($D54-$I$49)*MIN(L$3-$O$2,$Q$2)/$Q$2)) -> 2398.6395 | M54: =L54*(1+IF(M$3<=$O$2,$D54,$D54-($D54-$I$49)*MIN(M$3-$O$2,$Q$2)/$Q$2)) -> 2508.713 | N54: =M54*(1+IF(N$3<=$O$2,$D54,$D54-($D54-$I$49)*MIN(N$3-$O$2,$Q$2)/$Q$2)) -> 2554.6225 | O54: =SUMPRODUCT(E54:N54,1/(1+$F$49)^$E$3:$N$3)*$E$2 -> 2790.1988 | P54: =N54*$E$2*(1+$I$49)/($F$49-$I$49)/(1+$F$49)^$N$3 -> 6143.2663 | Q54: =O54+P54 -> 8933.4651 | R54: =Q54-$G$2+$I$2 -> 9100.8651 | S54: =R54/$K$2 -> 258.62077 | T54: =S54-$M$2 -> 94.085395
A55: 5 | B55: =IF(T54>0,B54,D54) -> 0.0625 | C55: =IF(T54>0,D54,C54) -> 0.15625 | D55: =(B55+C55)/2 -> 0.109375 | E55: =$C$2*(1+IF(E$3<=$O$2,$D55,$D55-($D55-$I$49)*MIN(E$3-$O$2,$Q$2)/$Q$2)) -> 965.18953 | F55: =E55*(1+IF(F$3<=$O$2,$D55,$D55-($D55-$I$49)*MIN(F$3-$O$2,$Q$2)/$Q$2)) -> 1070.7571 | G55: =F55*(1+IF(G$3<=$O$2,$D55,$D55-($D55-$I$49)*MIN(G$3-$O$2,$Q$2)/$Q$2)) -> 1187.8712 | H55: =G55*(1+IF(H$3<=$O$2,$D55,$D55-($D55-$I$49)*MIN(H$3-$O$2,$Q$2)/$Q$2)) -> 1317.7946 | I55: =H55*(1+IF(I$3<=$O$2,$D55,$D55-($D55-$I$49)*MIN(I$3-$O$2,$Q$2)/$Q$2)) -> 1461.9284 | J55: =I55*(1+IF(J$3<=$O$2,$D55,$D55-($D55-$I$49)*MIN(J$3-$O$2,$Q$2)/$Q$2)) -> 1595.1978 | K55: =J55*(1+IF(K$3<=$O$2,$D55,$D55-($D55-$I$49)*MIN(K$3-$O$2,$Q$2)/$Q$2)) -> 1711.5595 | L55: =K55*(1+IF(L$3<=$O$2,$D55,$D55-($D55-$I$49)*MIN(L$3-$O$2,$Q$2)/$Q$2)) -> 1805.2331 | M55: =L55*(1+IF(M$3<=$O$2,$D55,$D55-($D55-$I$49)*MIN(M$3-$O$2,$Q$2)/$Q$2)) -> 1871.1512 | N55: =M55*(1+IF(N$3<=$O$2,$D55,$D55-($D55-$I$49)*MIN(N$3-$O$2,$Q$2)/$Q$2)) -> 1905.3933 | O55: =SUMPRODUCT(E55:N55,1/(1+$F$49)^$E$3:$N$3)*$E$2 -> 2267.2397 | P55: =N55*$E$2*(1+$I$49)/($F$49-$I$49)/(1+$F$49)^$N$3 -> 4582.0227 | Q55: =O55+P55 -> 6849.2625 | R55: =Q55-$G$2+$I$2 -> 7016.6625 | S55: =R55/$K$2 -> 199.39365 | T55: =S55-$M$2 -> 34.858269
A56: 6 | B56: =IF(T55>0,B55,D55) -> 0.0625 | C56: =IF(T55>0,D55,C55) -> 0.109375 | D56: =(B56+C56)/2 -> 0.0859375 | E56: =$C$2*(1+IF(E$3<=$O$2,$D56,$D56-($D56-$I$49)*MIN(E$3-$O$2,$Q$2)/$Q$2)) -> 944.7982 | F56: =E56*(1+IF(F$3<=$O$2,$D56,$D56-($D56-$I$49)*MIN(F$3-$O$2,$Q$2)/$Q$2)) -> 1025.9918 | G56: =F56*(1+IF(G$3<=$O$2,$D56,$D56-($D56-$I$49)*MIN(G$3-$O$2,$Q$2)/$Q$2)) -> 1114.163 | H56: =G56*(1+IF(H$3<=$O$2,$D56,$D56-($D56-$I$49)*MIN(H$3-$O$2,$Q$2)/$Q$2)) -> 1209.9113 | I56: =H56*(1+IF(I$3<=$O$2,$D56,$D56-($D56-$I$49)*MIN(I$3-$O$2,$Q$2)/$Q$2)) -> 1313.8881 | J56: =I56*(1+IF(J$3<=$O$2,$D56,$D56-($D56-$I$49)*MIN(J$3-$O$2,$Q$2)/$Q$2)) -> 1409.0267 | K56: =J56*(1+IF(K$3<=$O$2,$D56,$D56-($D56-$I$49)*MIN(K$3-$O$2,$Q$2)/$Q$2)) -> 1491.9938 | L56: =K56*(1+IF(L$3<=$O$2,$D56,$D56-($D56-$I$49)*MIN(L$3-$O$2,$Q$2)/$Q$2)) -> 1559.6631 | M56: =L56*(1+IF(M$3<=$O$2,$D56,$D56-($D56-$I$49)*MIN(M$3-$O$2,$Q$2)/$Q$2)) -> 1609.3033 | N56: =M56*(1+IF(N$3<=$O$2,$D56,$D56-($D56-$I$49)*MIN(N$3-$O$2,$Q$2)/$Q$2)) -> 1638.7536 | O56: =SUMPRODUCT(E56:N56,1/(1+$F$49)^$E$3:$N$3)*$E$2 -> 2043.1473 | P56: =N56*$E$2*(1+$I$49)/($F$49-$I$49)/(1+$F$49)^$N$3 -> 3940.8169 | Q56: =O56+P56 -> 5983.9642 | R56: =Q56-$G$2+$I$2 -> 6151.3642 | S56: =R56/$K$2 -> 174.80433 | T56: =S56-$M$2 -> 10.268946
A57: 7 | B57: =IF(T56>0,B56,D56) -> 0.0625 | C57: =IF(T56>0,D56,C56) -> 0.0859375 | D57: =(B57+C57)/2 -> 0.07421875 | E57: =$C$2*(1+IF(E$3<=$O$2,$D57,$D57-($D57-$I$49)*MIN(E$3-$O$2,$Q$2)/$Q$2)) -> 934.60254 | F57: =E57*(1+IF(F$3<=$O$2,$D57,$D57-($D57-$I$49)*MIN(F$3-$O$2,$Q$2)/$Q$2)) -> 1003.9676 | G57: =F57*(1+IF(G$3<=$O$2,$D57,$D57-($D57-$I$49)*MIN(G$3-$O$2,$Q$2)/$Q$2)) -> 1078.4808 | H57: =G57*(1+IF(H$3<=$O$2,$D57,$D57-($D57-$I$49)*MIN(H$3-$O$2,$Q$2)/$Q$2)) -> 1158.5243 | I57: =H57*(1+IF(I$3<=$O$2,$D57,$D57-($D57-$I$49)*MIN(I$3-$O$2,$Q$2)/$Q$2)) -> 1244.5085 | J57: =I57*(1+IF(J$3<=$O$2,$D57,$D57-($D57-$I$49)*MIN(J$3-$O$2,$Q$2)/$Q$2)) -> 1322.9561 | K57: =J57*(1+IF(K$3<=$O$2,$D57,$D57-($D57-$I$49)*MIN(K$3-$O$2,$Q$2)/$Q$2)) -> 1391.553 | L57: =K57*(1+IF(L$3<=$O$2,$D57,$D57-($D57-$I$49)*MIN(L$3-$O$2,$Q$2)/$Q$2)) -> 1448.144 | M57: =L57*(1+IF(M$3<=$O$2,$D57,$D57-($D57-$I$49)*MIN(M$3-$O$2,$Q$2)/$Q$2)) -> 1490.8407 | N57: =M57*(1+IF(N$3<=$O$2,$D57,$D57-($D57-$I$49)*MIN(N$3-$O$2,$Q$2)/$Q$2)) -> 1518.1231 | O57: =SUMPRODUCT(E57:N57,1/(1+$F$49)^$E$3:$N$3)*$E$2 -> 1939.4649 | P57: =N57*$E$2*(1+$I$49)/($F$49-$I$49)/(1+$F$49)^$N$3 -> 3650.729 | Q57: =O57+P57 -> 5590.194 | R57: =Q57-$G$2+$I$2 -> 5757.594 | S57: =R57/$K$2 -> 163.61449 | T57: =S57-$M$2 -> -0.92088758
A58: 8 | B58: =IF(T57>0,B57,D57) -> 0.07421875 | C58: =IF(T57>0,D57,C57) -> 0.0859375 | D58: =(B58+C58)/2 -> 0.080078125 | E58: =$C$2*(1+IF(E$3<=$O$2,$D58,$D58-($D58-$I$49)*MIN(E$3-$O$2,$Q$2)/$Q$2)) -> 939.70037 | F58: =E58*(1+IF(F$3<=$O$2,$D58,$D58-($D58-$I$49)*MIN(F$3-$O$2,$Q$2)/$Q$2)) -> 1014.9498 | G58: =F58*(1+IF(G$3<=$O$2,$D58,$D58-($D58-$I$49)*MIN(G$3-$O$2,$Q$2)/$Q$2)) -> 1096.2251 | H58: =G58*(1+IF(H$3<=$O$2,$D58,$D58-($D58-$I$49)*MIN(H$3-$O$2,$Q$2)/$Q$2)) -> 1184.0087 | I58: =H58*(1+IF(I$3<=$O$2,$D58,$D58-($D58-$I$49)*MIN(I$3-$O$2,$Q$2)/$Q$2)) -> 1278.8219 | J58: =I58*(1+IF(J$3<=$O$2,$D58,$D58-($D58-$I$49)*MIN(J$3-$O$2,$Q$2)/$Q$2)) -> 1365.427 | K58: =J58*(1+IF(K$3<=$O$2,$D58,$D58-($D58-$I$49)*MIN(K$3-$O$2,$Q$2)/$Q$2)) -> 1441.0264 | L58: =K58*(1+IF(L$3<=$O$2,$D58,$D58-($D58-$I$49)*MIN(L$3-$O$2,$Q$2)/$Q$2)) -> 1503.0067 | M58: =L58*(1+IF(M$3<=$O$2,$D58,$D58-($D58-$I$49)*MIN(M$3-$O$2,$Q$2)/$Q$2)) -> 1549.0823 | N58: =M58*(1+IF(N$3<=$O$2,$D58,$D58-($D58-$I$49)*MIN(N$3-$O$2,$Q$2)/$Q$2)) -> 1577.4305 | O58: =SUMPRODUCT(E58:N58,1/(1+$F$49)^$E$3:$N$3)*$E$2 -> 1990.6365 | P58: =N58*$E$2*(1+$I$49)/($F$49-$I$49)/(1+$F$49)^$N$3 -> 3793.3495 | Q58: =O58+P58 -> 5783.9859 | R58: =Q58-$G$2+$I$2 -> 5951.3859 | S58: =R58/$K$2 -> 169.12151 | T58: =S58-$M$2 -> 4.5861309
A59: 9 | B59: =IF(T58>0,B58,D58) -> 0.07421875 | C59: =IF(T58>0,D58,C58) -> 0.080078125 | D59: =(B59+C59)/2 -> 0.077148438 | E59: =$C$2*(1+IF(E$3<=$O$2,$D59,$D59-($D59-$I$49)*MIN(E$3-$O$2,$Q$2)/$Q$2)) -> 937.15146 | F59: =E59*(1+IF(F$3<=$O$2,$D59,$D59-($D59-$I$49)*MIN(F$3-$O$2,$Q$2)/$Q$2)) -> 1009.4512 | G59: =F59*(1+IF(G$3<=$O$2,$D59,$D59-($D59-$I$49)*MIN(G$3-$O$2,$Q$2)/$Q$2)) -> 1087.3288 | H59: =G59*(1+IF(H$3<=$O$2,$D59,$D59-($D59-$I$49)*MIN(H$3-$O$2,$Q$2)/$Q$2)) -> 1171.2145 | I59: =H59*(1+IF(I$3<=$O$2,$D59,$D59-($D59-$I$49)*MIN(I$3-$O$2,$Q$2)/$Q$2)) -> 1261.5719 | J59: =I59*(1+IF(J$3<=$O$2,$D59,$D59-($D59-$I$49)*MIN(J$3-$O$2,$Q$2)/$Q$2)) -> 1344.0519 | K59: =J59*(1+IF(K$3<=$O$2,$D59,$D59-($D59-$I$49)*MIN(K$3-$O$2,$Q$2)/$Q$2)) -> 1416.1053 | L59: =K59*(1+IF(L$3<=$O$2,$D59,$D59-($D59-$I$49)*MIN(L$3-$O$2,$Q$2)/$Q$2)) -> 1475.3542 | M59: =L59*(1+IF(M$3<=$O$2,$D59,$D59-($D59-$I$49)*MIN(M$3-$O$2,$Q$2)/$Q$2)) -> 1519.7177 | N59: =M59*(1+IF(N$3<=$O$2,$D59,$D59-($D59-$I$49)*MIN(N$3-$O$2,$Q$2)/$Q$2)) -> 1547.5285 | O59: =SUMPRODUCT(E59:N59,1/(1+$F$49)^$E$3:$N$3)*$E$2 -> 1964.8853 | P59: =N59*$E$2*(1+$I$49)/($F$49-$I$49)/(1+$F$49)^$N$3 -> 3721.442 | Q59: =O59+P59 -> 5686.3273 | R59: =Q59-$G$2+$I$2 -> 5853.7273 | S59: =R59/$K$2 -> 166.34633 | T59: =S59-$M$2 -> 1.81095
A60: 10 | B60: =IF(T59>0,B59,D59) -> 0.07421875 | C60: =IF(T59>0,D59,C59) -> 0.077148438 | D60: =(B60+C60)/2 -> 0.075683594 | E60: =$C$2*(1+IF(E$3<=$O$2,$D60,$D60-($D60-$I$49)*MIN(E$3-$O$2,$Q$2)/$Q$2)) -> 935.877 | F60: =E60*(1+IF(F$3<=$O$2,$D60,$D60-($D60-$I$49)*MIN(F$3-$O$2,$Q$2)/$Q$2)) -> 1006.7075 | G60: =F60*(1+IF(G$3<=$O$2,$D60,$D60-($D60-$I$49)*MIN(G$3-$O$2,$Q$2)/$Q$2)) -> 1082.8988 | H60: =G60*(1+IF(H$3<=$O$2,$D60,$D60-($D60-$I$49)*MIN(H$3-$O$2,$Q$2)/$Q$2)) -> 1164.8564 | I60: =H60*(1+IF(I$3<=$O$2,$D60,$D60-($D60-$I$49)*MIN(I$3-$O$2,$Q$2)/$Q$2)) -> 1253.017 | J60: =I60*(1+IF(J$3<=$O$2,$D60,$D60-($D60-$I$49)*MIN(J$3-$O$2,$Q$2)/$Q$2)) -> 1333.4693 | K60: =J60*(1+IF(K$3<=$O$2,$D60,$D60-($D60-$I$49)*MIN(K$3-$O$2,$Q$2)/$Q$2)) -> 1403.7833 | L60: =K60*(1+IF(L$3<=$O$2,$D60,$D60-($D60-$I$49)*MIN(L$3-$O$2,$Q$2)/$Q$2)) -> 1461.6942 | M60: =L60*(1+IF(M$3<=$O$2,$D60,$D60-($D60-$I$49)*MIN(M$3-$O$2,$Q$2)/$Q$2)) -> 1505.2187 | N60: =M60*(1+IF(N$3<=$O$2,$D60,$D60-($D60-$I$49)*MIN(N$3-$O$2,$Q$2)/$Q$2)) -> 1532.7642 | O60: =SUMPRODUCT(E60:N60,1/(1+$F$49)^$E$3:$N$3)*$E$2 -> 1952.134 | P60: =N60*$E$2*(1+$I$49)/($F$49-$I$49)/(1+$F$49)^$N$3 -> 3685.9373 | Q60: =O60+P60 -> 5638.0713 | R60: =Q60-$G$2+$I$2 -> 5805.4713 | S60: =R60/$K$2 -> 164.97503 | T60: =S60-$M$2 -> 0.43965075
A61: 11 | B61: =IF(T60>0,B60,D60) -> 0.07421875 | C61: =IF(T60>0,D60,C60) -> 0.075683594 | D61: =(B61+C61)/2 -> 0.074951172 | E61: =$C$2*(1+IF(E$3<=$O$2,$D61,$D61-($D61-$I$49)*MIN(E$3-$O$2,$Q$2)/$Q$2)) -> 935.23977 | F61: =E61*(1+IF(F$3<=$O$2,$D61,$D61-($D61-$I$49)*MIN(F$3-$O$2,$Q$2)/$Q$2)) -> 1005.3371 | G61: =F61*(1+IF(G$3<=$O$2,$D61,$D61-($D61-$I$49)*MIN(G$3-$O$2,$Q$2)/$Q$2)) -> 1080.6883 | H61: =G61*(1+IF(H$3<=$O$2,$D61,$D61-($D61-$I$49)*MIN(H$3-$O$2,$Q$2)/$Q$2)) -> 1161.6871 | I61: =H61*(1+IF(I$3<=$O$2,$D61,$D61-($D61-$I$49)*MIN(I$3-$O$2,$Q$2)/$Q$2)) -> 1248.7569 | J61: =I61*(1+IF(J$3<=$O$2,$D61,$D61-($D61-$I$49)*MIN(J$3-$O$2,$Q$2)/$Q$2)) -> 1328.204 | K61: =J61*(1+IF(K$3<=$O$2,$D61,$D61-($D61-$I$49)*MIN(K$3-$O$2,$Q$2)/$Q$2)) -> 1397.6568 | L61: =K61*(1+IF(L$3<=$O$2,$D61,$D61-($D61-$I$49)*MIN(L$3-$O$2,$Q$2)/$Q$2)) -> 1454.9054 | M61: =L61*(1+IF(M$3<=$O$2,$D61,$D61-($D61-$I$49)*MIN(M$3-$O$2,$Q$2)/$Q$2)) -> 1498.0146 | N61: =M61*(1+IF(N$3<=$O$2,$D61,$D61-($D61-$I$49)*MIN(N$3-$O$2,$Q$2)/$Q$2)) -> 1525.4283 | O61: =SUMPRODUCT(E61:N61,1/(1+$F$49)^$E$3:$N$3)*$E$2 -> 1945.7892 | P61: =N61*$E$2*(1+$I$49)/($F$49-$I$49)/(1+$F$49)^$N$3 -> 3668.2963 | Q61: =O61+P61 -> 5614.0855 | R61: =Q61-$G$2+$I$2 -> 5781.4855 | S61: =R61/$K$2 -> 164.29342 | T61: =S61-$M$2 -> -0.24195887
A62: 12 | B62: =IF(T61>0,B61,D61) -> 0.074951172 | C62: =IF(T61>0,D61,C61) -> 0.075683594 | D62: =(B62+C62)/2 -> 0.075317383 | E62: =$C$2*(1+IF(E$3<=$O$2,$D62,$D62-($D62-$I$49)*MIN(E$3-$O$2,$Q$2)/$Q$2)) -> 935.55838 | F62: =E62*(1+IF(F$3<=$O$2,$D62,$D62-($D62-$I$49)*MIN(F$3-$O$2,$Q$2)/$Q$2)) -> 1006.0222 | G62: =F62*(1+IF(G$3<=$O$2,$D62,$D62-($D62-$I$49)*MIN(G$3-$O$2,$Q$2)/$Q$2)) -> 1081.7931 | H62: =G62*(1+IF(H$3<=$O$2,$D62,$D62-($D62-$I$49)*MIN(H$3-$O$2,$Q$2)/$Q$2)) -> 1163.271 | I62: =H62*(1+IF(I$3<=$O$2,$D62,$D62-($D62-$I$49)*MIN(I$3-$O$2,$Q$2)/$Q$2)) -> 1250.8855 | J62: =I62*(1+IF(J$3<=$O$2,$D62,$D62-($D62-$I$49)*MIN(J$3-$O$2,$Q$2)/$Q$2)) -> 1330.8345 | K62: =J62*(1+IF(K$3<=$O$2,$D62,$D62-($D62-$I$49)*MIN(K$3-$O$2,$Q$2)/$Q$2)) -> 1400.7172 | L62: =K62*(1+IF(L$3<=$O$2,$D62,$D62-($D62-$I$49)*MIN(L$3-$O$2,$Q$2)/$Q$2)) -> 1458.2964 | M62: =L62*(1+IF(M$3<=$O$2,$D62,$D62-($D62-$I$49)*MIN(M$3-$O$2,$Q$2)/$Q$2)) -> 1501.6129 | N62: =M62*(1+IF(N$3<=$O$2,$D62,$D62-($D62-$I$49)*MIN(N$3-$O$2,$Q$2)/$Q$2)) -> 1529.0924 | O62: =SUMPRODUCT(E62:N62,1/(1+$F$49)^$E$3:$N$3)*$E$2 -> 1948.959 | P62: =N62*$E$2*(1+$I$49)/($F$49-$I$49)/(1+$F$49)^$N$3 -> 3677.1075 | Q62: =O62+P62 -> 5626.0666 | R62: =Q62-$G$2+$I$2 -> 5793.4666 | S62: =R62/$K$2 -> 164.63389 | T62: =S62-$M$2 -> 0.098510246
A63: 13 | B63: =IF(T62>0,B62,D62) -> 0.074951172 | C63: =IF(T62>0,D62,C62) -> 0.075317383 | D63: =(B63+C63)/2 -> 0.075134277 | E63: =$C$2*(1+IF(E$3<=$O$2,$D63,$D63-($D63-$I$49)*MIN(E$3-$O$2,$Q$2)/$Q$2)) -> 935.39908 | F63: =E63*(1+IF(F$3<=$O$2,$D63,$D63-($D63-$I$49)*MIN(F$3-$O$2,$Q$2)/$Q$2)) -> 1005.6796 | G63: =F63*(1+IF(G$3<=$O$2,$D63,$D63-($D63-$I$49)*MIN(G$3-$O$2,$Q$2)/$Q$2)) -> 1081.2406 | H63: =G63*(1+IF(H$3<=$O$2,$D63,$D63-($D63-$I$49)*MIN(H$3-$O$2,$Q$2)/$Q$2)) -> 1162.4789 | I63: =H63*(1+IF(I$3<=$O$2,$D63,$D63-($D63-$I$49)*MIN(I$3-$O$2,$Q$2)/$Q$2)) -> 1249.8209 | J63: =I63*(1+IF(J$3<=$O$2,$D63,$D63-($D63-$I$49)*MIN(J$3-$O$2,$Q$2)/$Q$2)) -> 1329.5187 | K63: =J63*(1+IF(K$3<=$O$2,$D63,$D63-($D63-$I$49)*MIN(K$3-$O$2,$Q$2)/$Q$2)) -> 1399.1862 | L63: =K63*(1+IF(L$3<=$O$2,$D63,$D63-($D63-$I$49)*MIN(L$3-$O$2,$Q$2)/$Q$2)) -> 1456.6001 | M63: =L63*(1+IF(M$3<=$O$2,$D63,$D63-($D63-$I$49)*MIN(M$3-$O$2,$Q$2)/$Q$2)) -> 1499.8128 | N63: =M63*(1+IF(N$3<=$O$2,$D63,$D63-($D63-$I$49)*MIN(N$3-$O$2,$Q$2)/$Q$2)) -> 1527.2594 | O63: =SUMPRODUCT(E63:N63,1/(1+$F$49)^$E$3:$N$3)*$E$2 -> 1947.3735 | P63: =N63*$E$2*(1+$I$49)/($F$49-$I$49)/(1+$F$49)^$N$3 -> 3672.6996 | Q63: =O63+P63 -> 5620.0731 | R63: =Q63-$G$2+$I$2 -> 5787.4731 | S63: =R63/$K$2 -> 164.46357 | T63: =S63-$M$2 -> -0.071808162
... A74: 24 | B74: =IF(T73>0,B73,D73) -> 0.075211346 | C74: =IF(T73>0,D73,C73) -> 0.075211525 | D74: =(B74+C74)/2 -> 0.075211436 | E74: =$C$2*(1+IF(E$3<=$O$2,$D74,$D74-($D74-$I$49)*MIN(E$3-$O$2,$Q$2)/$Q$2)) -> 935.46621 | F74: =E74*(1+IF(F$3<=$O$2,$D74,$D74-($D74-$I$49)*MIN(F$3-$O$2,$Q$2)/$Q$2)) -> 1005.824 | G74: =F74*(1+IF(G$3<=$O$2,$D74,$D74-($D74-$I$49)*MIN(G$3-$O$2,$Q$2)/$Q$2)) -> 1081.4734 | H74: =G74*(1+IF(H$3<=$O$2,$D74,$D74-($D74-$I$49)*MIN(H$3-$O$2,$Q$2)/$Q$2)) -> 1162.8126 | I74: =H74*(1+IF(I$3<=$O$2,$D74,$D74-($D74-$I$49)*MIN(I$3-$O$2,$Q$2)/$Q$2)) -> 1250.2694 | J74: =I74*(1+IF(J$3<=$O$2,$D74,$D74-($D74-$I$49)*MIN(J$3-$O$2,$Q$2)/$Q$2)) -> 1330.073 | K74: =J74*(1+IF(K$3<=$O$2,$D74,$D74-($D74-$I$49)*MIN(K$3-$O$2,$Q$2)/$Q$2)) -> 1399.8312 | L74: =K74*(1+IF(L$3<=$O$2,$D74,$D74-($D74-$I$49)*MIN(L$3-$O$2,$Q$2)/$Q$2)) -> 1457.3147 | M74: =L74*(1+IF(M$3<=$O$2,$D74,$D74-($D74-$I$49)*MIN(M$3-$O$2,$Q$2)/$Q$2)) -> 1500.5711 | N74: =M74*(1+IF(N$3<=$O$2,$D74,$D74-($D74-$I$49)*MIN(N$3-$O$2,$Q$2)/$Q$2)) -> 1528.0315 | O74: =SUMPRODUCT(E74:N74,1/(1+$F$49)^$E$3:$N$3)*$E$2 -> 1948.0415 | P74: =N74*$E$2*(1+$I$49)/($F$49-$I$49)/(1+$F$49)^$N$3 -> 3674.5565 | Q74: =O74+P74 -> 5622.5979 | R74: =Q74-$G$2+$I$2 -> 5789.9979 | S74: =R74/$K$2 -> 164.53532 | T74: =S74-$M$2 -> -5.8700017e-05
A76: Grid block 3: row 1, column 2 of table A (24 steps) | E76: WACC | F76: =Sensitivity!$B$10 -> 0.067507582 | G76: Terminal growth | I76: =Sensitivity!$D$9 -> 0.0233
A77: Step | B77: Low | C77: High | D77: Mid | E77: Rev Y1 | F77: Rev Y2 | G77: Rev Y3 | H77: Rev Y4 | I77: Rev Y5 | J77: Rev Y6 | K77: Rev Y7 | L77: Rev Y8 | M77: Rev Y9 | N77: Rev Y10 | O77: PV of FCF | P77: PV of TV | Q77: EV | R77: Equity | S77: Per share | T77: Value - price
A78: 1 | B78: -0.5 | C78: 1 | D78: =(B78+C78)/2 -> 0.25 | E78: =$C$2*(1+IF(E$3<=$O$2,$D78,$D78-($D78-$I$76)*MIN(E$3-$O$2,$Q$2)/$Q$2)) -> 1087.5375 | F78: =E78*(1+IF(F$3<=$O$2,$D78,$D78-($D78-$I$76)*MIN(F$3-$O$2,$Q$2)/$Q$2)) -> 1359.4219 | G78: =F78*(1+IF(G$3<=$O$2,$D78,$D78-($D78-$I$76)*MIN(G$3-$O$2,$Q$2)/$Q$2)) -> 1699.2773 | H78: =G78*(1+IF(H$3<=$O$2,$D78,$D78-($D78-$I$76)*MIN(H$3-$O$2,$Q$2)/$Q$2)) -> 2124.0967 | I78: =H78*(1+IF(I$3<=$O$2,$D78,$D78-($D78-$I$76)*MIN(I$3-$O$2,$Q$2)/$Q$2)) -> 2655.1208 | J78: =I78*(1+IF(J$3<=$O$2,$D78,$D78-($D78-$I$76)*MIN(J$3-$O$2,$Q$2)/$Q$2)) -> 3198.5179 | K78: =J78*(1+IF(K$3<=$O$2,$D78,$D78-($D78-$I$76)*MIN(K$3-$O$2,$Q$2)/$Q$2)) -> 3708.1058 | L78: =K78*(1+IF(L$3<=$O$2,$D78,$D78-($D78-$I$76)*MIN(L$3-$O$2,$Q$2)/$Q$2)) -> 4130.7556 | M78: =L78*(1+IF(M$3<=$O$2,$D78,$D78-($D78-$I$76)*MIN(M$3-$O$2,$Q$2)/$Q$2)) -> 4414.2907 | N78: =M78*(1+IF(N$3<=$O$2,$D78,$D78-($D78-$I$76)*MIN(N$3-$O$2,$Q$2)/$Q$2)) -> 4517.1437 | O78: =SUMPRODUCT(E78:N78,1/(1+$F$76)^$E$3:$N$3)*$E$2 -> 4225.302 | P78: =N78*$E$2*(1+$I$76)/($F$76-$I$76)/(1+$F$76)^$N$3 -> 12150.636 | Q78: =O78+P78 -> 16375.938 | R78: =Q78-$G$2+$I$2 -> 16543.338 | S78: =R78/$K$2 -> 470.11475 | T78: =S78-$M$2 -> 305.57937
A79: 2 | B79: =IF(T78>0,B78,D78) -> -0.5 | C79: =IF(T78>0,D78,C78) -> 0.25 | D79: =(B79+C79)/2 -> -0.125 | E79: =$C$2*(1+IF(E$3<=$O$2,$D79,$D79-($D79-$I$76)*MIN(E$3-$O$2,$Q$2)/$Q$2)) -> 761.27625 | F79: =E79*(1+IF(F$3<=$O$2,$D79,$D79-($D79-$I$76)*MIN(F$3-$O$2,$Q$2)/$Q$2)) -> 666.11672 | G79: =F79*(1+IF(G$3<=$O$2,$D79,$D79-($D79-$I$76)*MIN(G$3-$O$2,$Q$2)/$Q$2)) -> 582.85213 | H79: =G79*(1+IF(H$3<=$O$2,$D79,$D79-($D79-$I$76)*MIN(H$3-$O$2,$Q$2)/$Q$2)) -> 509.99561 | I79: =H79*(1+IF(I$3<=$O$2,$D79,$D79-($D79-$I$76)*MIN(I$3-$O$2,$Q$2)/$Q$2)) -> 446.24616 | J79: =I79*(1+IF(J$3<=$O$2,$D79,$D79-($D79-$I$76)*MIN(J$3-$O$2,$Q$2)/$Q$2)) -> 403.70105 | K79: =J79*(1+IF(K$3<=$O$2,$D79,$D79-($D79-$I$76)*MIN(K$3-$O$2,$Q$2)/$Q$2)) -> 377.18597 | L79: =K79*(1+IF(L$3<=$O$2,$D79,$D79-($D79-$I$76)*MIN(L$3-$O$2,$Q$2)/$Q$2)) -> 363.59973 | M79: =L79*(1+IF(M$3<=$O$2,$D79,$D79-($D79-$I$76)*MIN(M$3-$O$2,$Q$2)/$Q$2)) -> 361.28723 | N79: =M79*(1+IF(N$3<=$O$2,$D79,$D79-($D79-$I$76)*MIN(N$3-$O$2,$Q$2)/$Q$2)) -> 369.70523 | O79: =SUMPRODUCT(E79:N79,1/(1+$F$76)^$E$3:$N$3)*$E$2 -> 806.56735 | P79: =N79*$E$2*(1+$I$76)/($F$76-$I$76)/(1+$F$76)^$N$3 -> 994.46772 | Q79: =O79+P79 -> 1801.0351 | R79: =Q79-$G$2+$I$2 -> 1968.4351 | S79: =R79/$K$2 -> 55.937342 | T79: =S79-$M$2 -> -108.59804
...

Sheet DCF
B2: MarketAxess (MKTX): discounted cash flow
B3: Panel A runs the model at the solved growth rate, so it should land on the price. Panel B runs it at your view.
B5: A. At the solved (implied) growth rate
B6: Year | C6: 1 | D6: 2 | E6: 3 | F6: 4 | G6: 5 | H6: 6 | I6: 7 | J6: 8 | K6: 9 | L6: 10
B7: Revenue growth | C7: =IF(C$6<=Inputs!$C$46,Solver!$W$7,Solver!$W$7-(Solver!$W$7-Inputs!$C$37)*MIN(C$6-Inputs!$C$46,Inputs!$C$47)/Inputs!$C$47) -> 0.084007684 | D7: =IF(D$6<=Inputs!$C$46,Solver!$W$7,Solver!$W$7-(Solver!$W$7-Inputs!$C$37)*MIN(D$6-Inputs!$C$46,Inputs!$C$47)/Inputs!$C$47) -> 0.084007684 | E7: =IF(E$6<=Inputs!$C$46,Solver!$W$7,Solver!$W$7-(Solver!$W$7-Inputs!$C$37)*MIN(E$6-Inputs!$C$46,Inputs!$C$47)/Inputs!$C$47) -> 0.084007684 | F7: =IF(F$6<=Inputs!$C$46,Solver!$W$7,Solver!$W$7-(Solver!$W$7-Inputs!$C$37)*MIN(F$6-Inputs!$C$46,Inputs!$C$47)/Inputs!$C$47) -> 0.084007684 | G7: =IF(G$6<=Inputs!$C$46,Solver!$W$7,Solver!$W$7-(Solver!$W$7-Inputs!$C$37)*MIN(G$6-Inputs!$C$46,Inputs!$C$47)/Inputs!$C$47) -> 0.084007684 | H7: =IF(H$6<=Inputs!$C$46,Solver!$W$7,Solver!$W$7-(Solver!$W$7-Inputs!$C$37)*MIN(H$6-Inputs!$C$46,Inputs!$C$47)/Inputs!$C$47) -> 0.072866147 | I7: =IF(I$6<=Inputs!$C$46,Solver!$W$7,Solver!$W$7-(Solver!$W$7-Inputs!$C$37)*MIN(I$6-Inputs!$C$46,Inputs!$C$47)/Inputs!$C$47) -> 0.06172461 | J7: =IF(J$6<=Inputs!$C$46,Solver!$W$7,Solver!$W$7-(Solver!$W$7-Inputs!$C$37)*MIN(J$6-Inputs!$C$46,Inputs!$C$47)/Inputs!$C$47) -> 0.050583074 | ... L7: =IF(L$6<=Inputs!$C$46,Solver!$W$7,Solver!$W$7-(Solver!$W$7-Inputs!$C$37)*MIN(L$6-Inputs!$C$46,Inputs!$C$47)/Inputs!$C$47) -> 0.0283
B8: Revenue ($mm) | C8: =Inputs!$C$12*(1+C7) -> 943.11921 | D8: =C8*(1+D7) -> 1022.3485 | E8: =D8*(1+E7) -> 1108.2336 | F8: =E8*(1+F7) -> 1201.3337 | G8: =F8*(1+G7) -> 1302.255 | H8: =G8*(1+H7) -> 1397.1453 | I8: =H8*(1+I7) -> 1483.3835 | J8: =I8*(1+J7) -> 1558.4176 | K8: =J8*(1+K7) -> 1619.884 | L8: =K8*(1+L7) -> 1665.7267
B9: Unlevered free cash flow ($mm) | C9: =C8*Inputs!$C$23 -> 210.62269 | D9: =D8*Inputs!$C$23 -> 228.31662 | E9: =E8*Inputs!$C$23 -> 247.49697 | F9: =F8*Inputs!$C$23 -> 268.28861 | G9: =G8*Inputs!$C$23 -> 290.82692 | H9: =H8*Inputs!$C$23 -> 312.01836 | I9: =I8*Inputs!$C$23 -> 331.27757 | J9: =J8*Inputs!$C$23 -> 348.03461 | ... L9: =L8*Inputs!$C$23 -> 371.99948
B10: Discount factor | C10: =1/(1+WACC!$C$37)^C$6 -> 0.92806772 | D10: =1/(1+WACC!$C$37)^D$6 -> 0.86130968 | E10: =1/(1+WACC!$C$37)^E$6 -> 0.79935371 | F10: =1/(1+WACC!$C$37)^F$6 -> 0.74185437 | G10: =1/(1+WACC!$C$37)^G$6 -> 0.68849109 | H10: =1/(1+WACC!$C$37)^H$6 -> 0.63896636 | I10: =1/(1+WACC!$C$37)^I$6 -> 0.59300405 | J10: =1/(1+WACC!$C$37)^J$6 -> 0.55034791 | ... L10: =1/(1+WACC!$C$37)^L$6 -> 0.47401998
B11: Present value ($mm) | C11: =C9*C10 -> 195.47212 | D11: =D9*D10 -> 196.65131 | E11: =E9*E10 -> 197.83762 | F11: =F9*F10 -> 199.03108 | G11: =G9*G10 -> 200.23174 | H11: =H9*H10 -> 199.36923 | I11: =I9*I10 -> 196.44894 | J11: =J9*J10 -> 191.54012 | ... L11: =L9*L10 -> 176.33519
B13: Sum of present values, years 1 to 10 | C13: =SUM(C11:L11) -> 1937.6908
B14: Terminal value at year 10 | C14: =L9*(1+Inputs!$C$37)/(WACC!$C$37-Inputs!$C$37) -> 7773.7424
B15: Present value of terminal value | C15: =C14*L10 -> 3684.9092
B16: Enterprise value | C16: =C13+C15 -> 5622.6
B17: Less: debt | C17: =-Inputs!$C$27 -> -178.91
B18: Plus: cash | C18: =Inputs!$C$28 -> 346.31
B19: Equity value | C19: =SUM(C16:C18) -> 5790
B20: Shares (mm) | C20: =Inputs!$C$7 -> 35.19
B21: Value per share ($) | C21: =C19/C20 -> 164.53538
B22: Price at the lock ($) | C22: =Inputs!$C$6 -> 164.53538
B23: Value / price - 1 | C23: =C21/C22-1 -> -4.2071902e-12
B24: Terminal value share of enterprise value | C24: =C15/C16 -> 0.6553746
B25: B. At your view of growth (Inputs tab, yellow cell)
B26: Year | C26: 1 | D26: 2 | E26: 3 | F26: 4 | G26: 5 | H26: 6 | I26: 7 | J26: 8 | K26: 9 | L26: 10
B27: Revenue growth | C27: =IF(C$26<=Inputs!$C$46,Inputs!$C$45,Inputs!$C$45-(Inputs!$C$45-Inputs!$C$37)*MIN(C$26-Inputs!$C$46,Inputs!$C$47)/Inputs!$C$47) -> 0.057829158 | D27: =IF(D$26<=Inputs!$C$46,Inputs!$C$45,Inputs!$C$45-(Inputs!$C$45-Inputs!$C$37)*MIN(D$26-Inputs!$C$46,Inputs!$C$47)/Inputs!$C$47) -> 0.057829158 | E27: =IF(E$26<=Inputs!$C$46,Inputs!$C$45,Inputs!$C$45-(Inputs!$C$45-Inputs!$C$37)*MIN(E$26-Inputs!$C$46,Inputs!$C$47)/Inputs!$C$47) -> 0.057829158 | F27: =IF(F$26<=Inputs!$C$46,Inputs!$C$45,Inputs!$C$45-(Inputs!$C$45-Inputs!$C$37)*MIN(F$26-Inputs!$C$46,Inputs!$C$47)/Inputs!$C$47) -> 0.057829158 | G27: =IF(G$26<=Inputs!$C$46,Inputs!$C$45,Inputs!$C$45-(Inputs!$C$45-Inputs!$C$37)*MIN(G$26-Inputs!$C$46,Inputs!$C$47)/Inputs!$C$47) -> 0.057829158 | H27: =IF(H$26<=Inputs!$C$46,Inputs!$C$45,Inputs!$C$45-(Inputs!$C$45-Inputs!$C$37)*MIN(H$26-Inputs!$C$46,Inputs!$C$47)/Inputs!$C$47) -> 0.051923327 | I27: =IF(I$26<=Inputs!$C$46,Inputs!$C$45,Inputs!$C$45-(Inputs!$C$45-Inputs!$C$37)*MIN(I$26-Inputs!$C$46,Inputs!$C$47)/Inputs!$C$47) -> 0.046017495 | J27: =IF(J$26<=Inputs!$C$46,Inputs!$C$45,Inputs!$C$45-(Inputs!$C$45-Inputs!$C$37)*MIN(J$26-Inputs!$C$46,Inputs!$C$47)/Inputs!$C$47) -> 0.040111663 | ... L27: =IF(L$26<=Inputs!$C$46,Inputs!$C$45,Inputs!$C$45-(Inputs!$C$45-Inputs!$C$37)*MIN(L$26-Inputs!$C$46,Inputs!$C$47)/Inputs!$C$47) -> 0.0283
B28: Revenue ($mm) | C28: =Inputs!$C$12*(1+C27) -> 920.3431 | D28: =C28*(1+D27) -> 973.56577 | E28: =D28*(1+E27) -> 1029.8663 | F28: =E28*(1+F27) -> 1089.4226 | G28: =F28*(1+G27) -> 1152.4229 | H28: =G28*(1+H27) -> 1212.2606 | I28: =H28*(1+I27) -> 1268.0458 | J28: =I28*(1+J27) -> 1318.9092 | K28: =J28*(1+K27) -> 1364.0236 | L28: =K28*(1+L27) -> 1402.6255
B29: Unlevered free cash flow ($mm) | C29: =C28*Inputs!$C$23 -> 205.53621 | D29: =D28*Inputs!$C$23 -> 217.42219 | E29: =E28*Inputs!$C$23 -> 229.99553 | F29: =F28*Inputs!$C$23 -> 243.29598 | G29: =G28*Inputs!$C$23 -> 257.36558 | H29: =H28*Inputs!$C$23 -> 270.72886 | I29: =I28*Inputs!$C$23 -> 283.18713 | J29: =J28*Inputs!$C$23 -> 294.54623 | ... L29: =L28*Inputs!$C$23 -> 313.24222
B30: Discount factor | C30: =1/(1+WACC!$C$37)^C$26 -> 0.92806772 | D30: =1/(1+WACC!$C$37)^D$26 -> 0.86130968 | E30: =1/(1+WACC!$C$37)^E$26 -> 0.79935371 | F30: =1/(1+WACC!$C$37)^F$26 -> 0.74185437 | G30: =1/(1+WACC!$C$37)^G$26 -> 0.68849109 | H30: =1/(1+WACC!$C$37)^H$26 -> 0.63896636 | I30: =1/(1+WACC!$C$37)^I$26 -> 0.59300405 | J30: =1/(1+WACC!$C$37)^J$26 -> 0.55034791 | ... L30: =1/(1+WACC!$C$37)^L$26 -> 0.47401998
B31: Present value ($mm) | C31: =C29*C30 -> 190.75152 | D31: =D29*D30 -> 187.26784 | E31: =E29*E30 -> 183.84778 | F31: =F29*F30 -> 180.49019 | G31: =G29*G30 -> 177.19391 | H31: =H29*H30 -> 172.98663 | I31: =I29*I30 -> 167.93111 | J31: =J29*J30 -> 162.1029 | ... L31: =L29*L30 -> 148.48307
B33: Sum of present values, years 1 to 10 | C33: =SUM(C31:L31) -> 1726.6434
B34: Terminal value at year 10 | C34: =L29*(1+Inputs!$C$37)/(WACC!$C$37-Inputs!$C$37) -> 6545.8809
B35: Present value of terminal value | C35: =C34*L30 -> 3102.8784
B36: Enterprise value | C36: =C33+C35 -> 4829.5218
B37: Less: debt | C37: =-Inputs!$C$27 -> -178.91
B38: Plus: cash | C38: =Inputs!$C$28 -> 346.31
B39: Equity value | C39: =SUM(C36:C38) -> 4996.9218
B40: Shares (mm) | C40: =Inputs!$C$7 -> 35.19
B41: Value per share ($) | C41: =C39/C40 -> 141.99835
B42: Price at the lock ($) | C42: =Inputs!$C$6 -> 164.53538
B43: Value / price - 1 | C43: =C41/C42-1 -> -0.13697378
B44: Terminal value share of enterprise value | C44: =C35/C36 -> 0.64248149

Sheet Sensitivity
B2: MarketAxess (MKTX): sensitivity
B3: Table A re-solves implied growth for each pair of inputs (Solver tab, blocks 2 to 26). Table B values the stock at a growth view.
B5: WACC step | C5: 0.005 | D5: Terminal-growth step | F5: 0.005
B6: Growth-view step | C6: 0.02
B8: A. Implied 5-year growth: WACC (rows) by terminal growth (columns)
C9: =Inputs!$C$37+(0-2)*$F$5 -> 0.0183 | D9: =Inputs!$C$37+(1-2)*$F$5 -> 0.0233 | E9: =Inputs!$C$37+(2-2)*$F$5 -> 0.0283 | F9: =Inputs!$C$37+(3-2)*$F$5 -> 0.0333 | G9: =Inputs!$C$37+(4-2)*$F$5 -> 0.0383
B10: =WACC!$C$37+(0-2)*$C$5 -> 0.067507582 | C10: =Solver!$D$74 -> 0.075211436 | D10: =Solver!$D$101 -> 0.060713559 | E10: =Solver!$D$128 -> 0.044556648 | F10: =Solver!$D$155 -> 0.026312262 | G10: =Solver!$D$182 -> 0.0053566992 | I10: Centre cell = the base case. Each step changes one input by the step size above.
B11: =WACC!$C$37+(1-2)*$C$5 -> 0.072507582 | C11: =Solver!$D$209 -> 0.092817277 | D11: =Solver!$D$236 -> 0.079610974 | E11: =Solver!$D$263 -> 0.065048009 | F11: =Solver!$D$290 -> 0.048819214 | G11: =Solver!$D$317 -> 0.030493826
B12: =WACC!$C$37+(2-2)*$C$5 -> 0.077507582 | C12: =Solver!$D$344 -> 0.10940674 | D12: =Solver!$D$371 -> 0.097273141 | E12: =Solver!$D$398 -> 0.084007651 | F12: =Solver!$D$425 -> 0.069379777 | G12: =Solver!$D$452 -> 0.053078741
B13: =WACC!$C$37+(3-2)*$C$5 -> 0.082507582 | C13: =Solver!$D$479 -> 0.12514272 | D13: =Solver!$D$506 -> 0.11391428 | E13: =Solver!$D$533 -> 0.10172614 | F13: =Solver!$D$560 -> 0.088401467 | G13: =Solver!$D$587 -> 0.073708504
B14: =WACC!$C$37+(4-2)*$C$5 -> 0.087507582 | C14: =Solver!$D$614 -> 0.14015165 | D14: =Solver!$D$641 -> 0.12969765 | E14: =Solver!$D$668 -> 0.11841896 | F14: =Solver!$D$695 -> 0.10617647 | G14: =Solver!$D$722 -> 0.0927926
B17: B. Value per share: WACC (rows) by your growth view (columns)
C18: =Inputs!$C$45+(0-2)*$C$6 -> 0.017829158 | D18: =Inputs!$C$45+(1-2)*$C$6 -> 0.037829158 | E18: =Inputs!$C$45+(2-2)*$C$6 -> 0.057829158 | F18: =Inputs!$C$45+(3-2)*$C$6 -> 0.077829158 | G18: =Inputs!$C$45+(4-2)*$C$6 -> 0.097829158
