Workbook

Sheet Cover
B2: Priced In: Morningstar (MORN)
B3: Reverse DCF, model v1.0. Inputs as of the Oct 13, 2026 close; model locked Oct 14, 2026 (commit 0735af0).
B4: Ratings and indexes | US | reports in USD
B6: The question
B7: What revenue growth over the next five years does today's price imply, and is that more or less than the company has delivered and analysts expect?
B9: Answer
B10: Price at the lock ($) | C10: =Inputs!$C$6 -> 204.47881
B11: Implied 5-year revenue growth | C11: =Solver!$W$7 -> 0.049811827
B12: Anchor (history and analysts) | C12: =Inputs!$C$43 -> 0.082073834
B13: Gap (implied - anchor) | C13: =C11-C12 -> -0.032262007
B14: Verdict | C14: =IF(C13>=Inputs!$C$44,"Expectations too high",IF(C13<=-Inputs!$C$44,"Expectations too low","About right")) -> Expectations too low
B15: WACC | C15: =WACC!$C$34 -> 0.094183338
B16: Terminal growth | C16: =Inputs!$C$37 -> 0.0283
B17: Unlevered free-cash-flow margin | C17: =Inputs!$C$23 -> 0.19976654
B18: Your view of growth (Inputs, yellow) | C18: =Inputs!$C$45 -> 0.082073834
B19: Value per share at your view ($) | C19: =DCF!$C$41 -> 252.16673
B20: Upside or downside at your view | C20: =DCF!$C$43 -> 0.23321697
B25: How to use this file
B26: 1. Change any blue cell on Inputs, History or WACC; everything recalculates, including the solver.
B27: 2. The Solver tab finds implied growth by bisection with formulas, so you never need Goal Seek. 40 steps narrow a 150-point range to well under 0.0001%.
B28: 3. Type your own growth view in the yellow cell on Inputs; DCF panel B and this page show what the stock is worth if you're right.
B29: 4. Check confirms this workbook matches the Python pipeline that runs the site.
B31: Colour key
B32: Typed input with a source | C32: 1234
B33: Formula | C33: =C32*2 -> 2468
B34: Link to another tab | C34: =Inputs!$C$12 -> 2570
B35: Your view (edit this one) | C35: =Inputs!$C$45 -> 0.082073834
B37: Live site
B38: https://claude.ai/artifact/DS3n4CgaKxaSLzkXDsBKuK
B40: Built by Rohan Jayapalan. Not investment advice.

Sheet Inputs
B2: Morningstar (MORN): inputs
B3: Blue cells are typed inputs with a source. Black cells are formulas. Change a blue cell and every tab recalculates.
B5: Market and price
B6: Price per share at the lock ($) | C6: 204.47881 | E6: Market cap divided by shares from Stock Analysis at the Oct 13, 2026 close.
B7: Diluted shares outstanding (mm) | C7: 37.51 | E7: Stock Analysis statistics page, Oct 13, 2026.
B8: Market value of equity ($mm) | C8: =C6*C7 -> 7670 | E8: Price x shares.
B10: Trailing 12 months
B11: Revenue, reported ($mm) | C11: 2570 | E11: Stock Analysis income statement, trailing 12 months.
B12: Revenue used in the model ($mm) | C12: =C11 -> 2570 | E12: Same as reported.
B13: Free cash flow, reported (cash from operations - capex) ($mm) | C13: 497.5 | E13: Stock Analysis cash flow statement, trailing 12 months.
B14: Free cash flow before adjustments ($mm) | C14: =C13 -> 497.5 | E14: Same as reported.
B15: Less: adjustments ($mm) | C15: 0 | E15: None for this company.
B16: Free cash flow used ($mm) | C16: =C14-C15 -> 497.5
B17: Operating income ($mm) | C17: 583.5 | E17: Stock Analysis, trailing 12 months.
B18: Pretax income ($mm) | C18: 562.3 | E18: Stock Analysis, trailing 12 months.
B19: Interest proxy: operating income - pretax, floored at zero ($mm) | C19: =MAX(0,C17-C18) -> 21.2 | E19: Net interest and other non-operating costs. Adding it back (after tax) turns levered FCF into unlevered FCF.
B20: Tax rate | C20: 0.25 | E20: Statutory blend: 25% US (21% federal plus state), 26.5% Canada (federal plus Ontario).
B21: After-tax interest added back ($mm) | C21: =C19*(1-C20) -> 15.9
B22: Unlevered free cash flow ($mm) | C22: =C16+C21 -> 513.4
B23: Unlevered free-cash-flow margin | C23: =C22/C12 -> 0.19976654 | E23: Held flat for all 10 years in the model.
B24: EBITDA ($mm) | C24: 680.1 | E24: Stock Analysis, trailing 12 months.
B26: Balance sheet
B27: Total debt ($mm) | C27: 1900 | E27: Stock Analysis balance sheet, latest quarter.
B28: Cash and equivalents ($mm) | C28: 523.8 | E28: Stock Analysis balance sheet, latest quarter.
B29: Net debt ($mm) | C29: =C27-C28 -> 1376.2
B31: Rates
B32: 10-year US Treasury yield | C32: 0.0521 | E32: US Treasury daily par yield curve, Oct 13, 2026.
B33: 10-year TIPS real yield | C33: 0.0288 | E33: US Treasury daily real yield curve, Oct 13, 2026.
B34: Breakeven inflation | C34: =C32-C33 -> 0.0233 | E34: Nominal minus real: the market's inflation expectation.
B35: Risk-free rate used | C35: =C32 -> 0.0521
B36: Real growth added to inflation | C36: 0.005 | E36: Half a point of long-run real growth.
B37: Terminal growth | C37: =MIN(C34+C36,C35) -> 0.0283 | E37: Capped at the risk-free rate.
B38: Equity risk premium | C38: 0.0423 | E38: Damodaran implied equity risk premium, start of 2026.
B40: Growth anchor and verdict
B41: Past revenue growth (CAGR) | C41: =History!$C$12 -> 0.096047667 | E41: FY2021 to the 12 months ended June 2026
B42: Analysts' revenue growth forecast | C42: 0.0681 | E42: Analysts' 3-year revenue CAGR forecast (stockanalysis)
B43: Anchor (average of the two) | C43: =AVERAGE(C41:C42) -> 0.082073834 | E43: AVERAGE skips the n/a text when history isn't used.
B44: Verdict band (+/-) | C44: 0.03 | E44: Set before any backtest and never changed.
B45: Your view of 5-year revenue growth | C45: 0.082073834 | E45: Type your own view. It starts at the anchor. DCF panel B and the Cover show what the stock is worth at your view.
B46: Years at the solved growth rate | C46: 5 | E46: Model v1.0: 5 years at the growth rate, then a straight-line fade.
...

Sheet History
B2: Morningstar (MORN): revenue history
B3: Revenue from Stock Analysis income statements; the window is chosen so acquisitions and disposals don't count as growth.
B5: Fiscal year | C5: FY2021 | D5: FY2022 | E5: FY2023 | F5: FY2024 | G5: FY2025 | H5: TTM Jun-26
B6: Revenue ($mm) | C6: 1699 | D6: 1871 | E6: 2039 | F6: 2275 | G6: 2446 | H6: 2567
B7: Growth on the prior year | D7: =D6/C6-1 -> 0.10123602 | E7: =E6/D6-1 -> 0.089791555 | F7: =F6/E6-1 -> 0.11574301 | G7: =G6/F6-1 -> 0.075164835
B10: History window
B11: Start year | C11: FY2021 | E11: Years from start to TTM | G11: 4.5
B12: Revenue CAGR, start to TTM | C12: =(H6/INDEX(C6:H6,MATCH(C11,C5:H5,0)))^(1/G11)-1 -> 0.096047667 | I12: FY2021 to the 12 months ended June 2026
B15: Free-cash-flow margin history
B16: Fiscal year | C16: 2021 | D16: 2022 | E16: 2023 | F16: 2024 | G16: 2025
B17: (CFO - capex) / revenue | C17: 0.2048 | D17: 0.09 | E17: 0.0968 | F17: 0.1973 | G17: 0.181 | I17: SEC XBRL filings (NetCashProvidedByOperatingActivities, PaymentsToAcquirePropertyPlantAndEquipment, revenue tags).
B18: Plus today's interest add-back | C18: =C17+(Inputs!$C$23-Inputs!$C$16/Inputs!$C$12) -> 0.21098677 | D18: =D17+(Inputs!$C$23-Inputs!$C$16/Inputs!$C$12) -> 0.09618677 | E18: =E17+(Inputs!$C$23-Inputs!$C$16/Inputs!$C$12) -> 0.10298677 | F18: =F17+(Inputs!$C$23-Inputs!$C$16/Inputs!$C$12) -> 0.20348677 | G18: =G17+(Inputs!$C$23-Inputs!$C$16/Inputs!$C$12) -> 0.18718677
B19: Range (the margin slider's shaded zone) | C19: =MIN(C18:G18) -> 0.09618677 | D19: =MAX(C18:G18) -> 0.21098677

Sheet WACC
B2: Morningstar (MORN): cost of capital
B3: Bottom-up beta: the median unlevered beta of the company's group, relevered for this company's debt.
B5: Peer | C5: Raw beta | D5: Debt ($mm) | E5: Equity ($mm) | F5: Tax rate | G5: Unlevered beta
B6: S&P Global (SPGI) | C6: 1.0925017 | D6: 15750 | E6: 120850 | F6: 0.25 | G6: =C6/(1+(1-F6)*D6/E6) -> 0.99522342 | H6: Raw betas: 60 monthly returns to Sep 2026 against the S&P 500 (S&P/TSX for TMX); Cboe uses Stock Analysis's 5-year beta. Debt and equity from Stock Analysis, Oct 13, 2026.
B7: Moody's (MCO) | C7: 1.3479367 | D7: 7620 | E7: 80380 | F7: 0.25 | G7: =C7/(1+(1-F7)*D7/E7) -> 1.2584604
B8: MSCI (MSCI) | C8: 1.2419463 | D8: 6540 | E8: 40770 | F8: 0.25 | G8: =C8/(1+(1-F8)*D8/E8) -> 1.1085748
B9: Morningstar (MORN) | C9: 1.0250328 | D9: 1900 | E9: 7670 | F9: 0.25 | G9: =C9/(1+(1-F9)*D9/E9) -> 0.86443117
B11: Group median unlevered beta | C11: =MEDIAN(G6:G9) -> 1.0518991
B12: Debt ($mm) | C12: =Inputs!$C$27 -> 1900
B13: Market value of equity ($mm) | C13: =Inputs!$C$8 -> 7670
B14: Tax rate | C14: =Inputs!$C$20 -> 0.25
B15: Relevered beta | C15: =WACC!$C$11*(1+(1-WACC!$C$14)*WACC!$C$12/WACC!$C$13) -> 1.2473301 | H15: Hamada: unlevered beta x (1 + (1 - tax) x debt / equity).
B16: Risk-free rate | C16: =Inputs!$C$35 -> 0.0521
B17: Equity risk premium | C17: =Inputs!$C$38 -> 0.0423
B18: Cost of equity | C18: =WACC!$C$16+WACC!$C$15*WACC!$C$17 -> 0.10486207 | H18: CAPM: risk-free + beta x premium.
B20: Debt-to-EBITDA spread table
B21: Debt / EBITDA below | C21: Spread
B22: 1 | C22: 0.01 | H22: Synthetic spread over the risk-free rate by leverage, a simplified version of Damodaran's ratings table; the last row covers anything at 4x or above.
B23: 2 | C23: 0.0125
B24: 3 | C24: 0.016
B25: 4 | C25: 0.02
B26: 99 | C26: 0.0275
B28: Debt / EBITDA | C28: =Inputs!$C$27/Inputs!$C$24 -> 2.7937068
B29: Credit spread | C29: =INDEX(C22:C26,COUNTIF(B22:B26,"<="&WACC!$C$28)+1) -> 0.016 | H29: First row whose limit is above this company's leverage.
B30: Pre-tax cost of debt | C30: =WACC!$C$16+WACC!$C$29 -> 0.0681
B31: After-tax cost of debt | C31: =WACC!$C$30*(1-WACC!$C$14) -> 0.051075
B32: Weight of debt | C32: =WACC!$C$12/(WACC!$C$12+WACC!$C$13) -> 0.1985371 | H32: Market-value weights.
B33: Weight of equity | C33: =1-WACC!$C$32 -> 0.8014629
B34: WACC | C34: =WACC!$C$33*WACC!$C$18+WACC!$C$32*WACC!$C$31 -> 0.094183338

Sheet Solver
A1: Solver: bisection for the growth rate that makes the model equal the price (replaces Goal Seek)
B2: Revenue | C2: =Inputs!$C$12 -> 2570 | D2: Margin | E2: =Inputs!$C$23 -> 0.19976654 | F2: Debt | G2: =Inputs!$C$27 -> 1900 | H2: Cash | I2: =Inputs!$C$28 -> 523.8 | J2: Shares | K2: =Inputs!$C$7 -> 37.51 | L2: Price | M2: =Inputs!$C$6 -> 204.47881 | N2: Years | O2: =Inputs!$C$46 -> 5 | P2: Fade | Q2: =Inputs!$C$47 -> 5
D3: Year | E3: 1 | F3: 2 | G3: 3 | H3: 4 | I3: 5 | J3: 6 | K3: 7 | L3: 8 | M3: 9 | N3: 10
A4: Each row tries the midpoint of the current range. If the value per share is above the price, the answer is lower, so the top of the range moves down; otherwise the bottom moves up.
A6: Base case: model WACC and terminal growth (40 steps) | E6: WACC | F6: =WACC!$C$34 -> 0.094183338 | G6: Terminal growth | I6: =Inputs!$C$37 -> 0.0283 | W6: Implied growth
A7: Step | B7: Low | C7: High | D7: Mid | E7: Rev Y1 | F7: Rev Y2 | G7: Rev Y3 | H7: Rev Y4 | I7: Rev Y5 | J7: Rev Y6 | K7: Rev Y7 | L7: Rev Y8 | M7: Rev Y9 | N7: Rev Y10 | O7: PV of FCF | P7: PV of TV | Q7: EV | R7: Equity | S7: Per share | T7: Value - price | W7: =$D$47 -> 0.049811827
A8: 1 | B8: -0.5 | C8: 1 | D8: =(B8+C8)/2 -> 0.25 | E8: =$C$2*(1+IF(E$3<=$O$2,$D8,$D8-($D8-$I$6)*MIN(E$3-$O$2,$Q$2)/$Q$2)) -> 3212.5 | F8: =E8*(1+IF(F$3<=$O$2,$D8,$D8-($D8-$I$6)*MIN(F$3-$O$2,$Q$2)/$Q$2)) -> 4015.625 | G8: =F8*(1+IF(G$3<=$O$2,$D8,$D8-($D8-$I$6)*MIN(G$3-$O$2,$Q$2)/$Q$2)) -> 5019.5312 | H8: =G8*(1+IF(H$3<=$O$2,$D8,$D8-($D8-$I$6)*MIN(H$3-$O$2,$Q$2)/$Q$2)) -> 6274.4141 | I8: =H8*(1+IF(I$3<=$O$2,$D8,$D8-($D8-$I$6)*MIN(I$3-$O$2,$Q$2)/$Q$2)) -> 7843.0176 | J8: =I8*(1+IF(J$3<=$O$2,$D8,$D8-($D8-$I$6)*MIN(J$3-$O$2,$Q$2)/$Q$2)) -> 9456.0126 | K8: =J8*(1+IF(K$3<=$O$2,$D8,$D8-($D8-$I$6)*MIN(K$3-$O$2,$Q$2)/$Q$2)) -> 10981.457 | L8: =K8*(1+IF(L$3<=$O$2,$D8,$D8-($D8-$I$6)*MIN(L$3-$O$2,$Q$2)/$Q$2)) -> 12266.067 | M8: =L8*(1+IF(M$3<=$O$2,$D8,$D8-($D8-$I$6)*MIN(M$3-$O$2,$Q$2)/$Q$2)) -> 13157.074 | N8: =M8*(1+IF(N$3<=$O$2,$D8,$D8-($D8-$I$6)*MIN(N$3-$O$2,$Q$2)/$Q$2)) -> 13529.42 | O8: =SUMPRODUCT(E8:N8,1/(1+$F$6)^$E$3:$N$3)*$E$2 -> 9625.0081 | P8: =N8*$E$2*(1+$I$6)/($F$6-$I$6)/(1+$F$6)^$N$3 -> 17149.252 | Q8: =O8+P8 -> 26774.26 | R8: =Q8-$G$2+$I$2 -> 25398.06 | S8: =R8/$K$2 -> 677.10104 | T8: =S8-$M$2 -> 472.62224 | W8: =IF(OR(ABS(W7+0.5)<0.000001,ABS(W7-1)<0.000001),"Out of range","Solved") -> Solved
A9: 2 | B9: =IF(T8>0,B8,D8) -> -0.5 | C9: =IF(T8>0,D8,C8) -> 0.25 | D9: =(B9+C9)/2 -> -0.125 | E9: =$C$2*(1+IF(E$3<=$O$2,$D9,$D9-($D9-$I$6)*MIN(E$3-$O$2,$Q$2)/$Q$2)) -> 2248.75 | F9: =E9*(1+IF(F$3<=$O$2,$D9,$D9-($D9-$I$6)*MIN(F$3-$O$2,$Q$2)/$Q$2)) -> 1967.6562 | G9: =F9*(1+IF(G$3<=$O$2,$D9,$D9-($D9-$I$6)*MIN(G$3-$O$2,$Q$2)/$Q$2)) -> 1721.6992 | H9: =G9*(1+IF(H$3<=$O$2,$D9,$D9-($D9-$I$6)*MIN(H$3-$O$2,$Q$2)/$Q$2)) -> 1506.4868 | I9: =H9*(1+IF(I$3<=$O$2,$D9,$D9-($D9-$I$6)*MIN(I$3-$O$2,$Q$2)/$Q$2)) -> 1318.176 | J9: =I9*(1+IF(J$3<=$O$2,$D9,$D9-($D9-$I$6)*MIN(J$3-$O$2,$Q$2)/$Q$2)) -> 1193.8192 | K9: =J9*(1+IF(K$3<=$O$2,$D9,$D9-($D9-$I$6)*MIN(K$3-$O$2,$Q$2)/$Q$2)) -> 1117.7968 | L9: =K9*(1+IF(L$3<=$O$2,$D9,$D9-($D9-$I$6)*MIN(L$3-$O$2,$Q$2)/$Q$2)) -> 1080.8872 | M9: =L9*(1+IF(M$3<=$O$2,$D9,$D9-($D9-$I$6)*MIN(M$3-$O$2,$Q$2)/$Q$2)) -> 1078.3363 | N9: =M9*(1+IF(N$3<=$O$2,$D9,$D9-($D9-$I$6)*MIN(N$3-$O$2,$Q$2)/$Q$2)) -> 1108.8532 | O9: =SUMPRODUCT(E9:N9,1/(1+$F$6)^$E$3:$N$3)*$E$2 -> 1928.1352 | P9: =N9*$E$2*(1+$I$6)/($F$6-$I$6)/(1+$F$6)^$N$3 -> 1405.5298 | Q9: =O9+P9 -> 3333.665 | R9: =Q9-$G$2+$I$2 -> 1957.465 | S9: =R9/$K$2 -> 52.185151 | T9: =S9-$M$2 -> -152.29365
A10: 3 | B10: =IF(T9>0,B9,D9) -> -0.125 | C10: =IF(T9>0,D9,C9) -> 0.25 | D10: =(B10+C10)/2 -> 0.0625 | E10: =$C$2*(1+IF(E$3<=$O$2,$D10,$D10-($D10-$I$6)*MIN(E$3-$O$2,$Q$2)/$Q$2)) -> 2730.625 | F10: =E10*(1+IF(F$3<=$O$2,$D10,$D10-($D10-$I$6)*MIN(F$3-$O$2,$Q$2)/$Q$2)) -> 2901.2891 | G10: =F10*(1+IF(G$3<=$O$2,$D10,$D10-($D10-$I$6)*MIN(G$3-$O$2,$Q$2)/$Q$2)) -> 3082.6196 | H10: =G10*(1+IF(H$3<=$O$2,$D10,$D10-($D10-$I$6)*MIN(H$3-$O$2,$Q$2)/$Q$2)) -> 3275.2834 | I10: =H10*(1+IF(I$3<=$O$2,$D10,$D10-($D10-$I$6)*MIN(I$3-$O$2,$Q$2)/$Q$2)) -> 3479.9886 | J10: =I10*(1+IF(J$3<=$O$2,$D10,$D10-($D10-$I$6)*MIN(J$3-$O$2,$Q$2)/$Q$2)) -> 3673.6847 | K10: =J10*(1+IF(K$3<=$O$2,$D10,$D10-($D10-$I$6)*MIN(K$3-$O$2,$Q$2)/$Q$2)) -> 3853.034 | L10: =K10*(1+IF(L$3<=$O$2,$D10,$D10-($D10-$I$6)*MIN(L$3-$O$2,$Q$2)/$Q$2)) -> 4014.7844 | M10: =L10*(1+IF(M$3<=$O$2,$D10,$D10-($D10-$I$6)*MIN(M$3-$O$2,$Q$2)/$Q$2)) -> 4155.8639 | N10: =M10*(1+IF(N$3<=$O$2,$D10,$D10-($D10-$I$6)*MIN(N$3-$O$2,$Q$2)/$Q$2)) -> 4273.4749 | O10: =SUMPRODUCT(E10:N10,1/(1+$F$6)^$E$3:$N$3)*$E$2 -> 4296.7073 | P10: =N10*$E$2*(1+$I$6)/($F$6-$I$6)/(1+$F$6)^$N$3 -> 5416.8545 | Q10: =O10+P10 -> 9713.5618 | R10: =Q10-$G$2+$I$2 -> 8337.3618 | S10: =R10/$K$2 -> 222.27038 | T10: =S10-$M$2 -> 17.79157
A11: 4 | B11: =IF(T10>0,B10,D10) -> -0.125 | C11: =IF(T10>0,D10,C10) -> 0.0625 | D11: =(B11+C11)/2 -> -0.03125 | E11: =$C$2*(1+IF(E$3<=$O$2,$D11,$D11-($D11-$I$6)*MIN(E$3-$O$2,$Q$2)/$Q$2)) -> 2489.6875 | F11: =E11*(1+IF(F$3<=$O$2,$D11,$D11-($D11-$I$6)*MIN(F$3-$O$2,$Q$2)/$Q$2)) -> 2411.8848 | G11: =F11*(1+IF(G$3<=$O$2,$D11,$D11-($D11-$I$6)*MIN(G$3-$O$2,$Q$2)/$Q$2)) -> 2336.5134 | H11: =G11*(1+IF(H$3<=$O$2,$D11,$D11-($D11-$I$6)*MIN(H$3-$O$2,$Q$2)/$Q$2)) -> 2263.4973 | I11: =H11*(1+IF(I$3<=$O$2,$D11,$D11-($D11-$I$6)*MIN(I$3-$O$2,$Q$2)/$Q$2)) -> 2192.763 | J11: =I11*(1+IF(J$3<=$O$2,$D11,$D11-($D11-$I$6)*MIN(J$3-$O$2,$Q$2)/$Q$2)) -> 2150.355 | K11: =J11*(1+IF(K$3<=$O$2,$D11,$D11-($D11-$I$6)*MIN(K$3-$O$2,$Q$2)/$Q$2)) -> 2134.3779 | L11: =K11*(1+IF(L$3<=$O$2,$D11,$D11-($D11-$I$6)*MIN(L$3-$O$2,$Q$2)/$Q$2)) -> 2143.9399 | M11: =L11*(1+IF(M$3<=$O$2,$D11,$D11-($D11-$I$6)*MIN(M$3-$O$2,$Q$2)/$Q$2)) -> 2179.079 | N11: =M11*(1+IF(N$3<=$O$2,$D11,$D11-($D11-$I$6)*MIN(N$3-$O$2,$Q$2)/$Q$2)) -> 2240.747 | O11: =SUMPRODUCT(E11:N11,1/(1+$F$6)^$E$3:$N$3)*$E$2 -> 2869.4996 | P11: =N11*$E$2*(1+$I$6)/($F$6-$I$6)/(1+$F$6)^$N$3 -> 2840.2648 | Q11: =O11+P11 -> 5709.7644 | R11: =Q11-$G$2+$I$2 -> 4333.5644 | S11: =R11/$K$2 -> 115.53091 | T11: =S11-$M$2 -> -88.947896
A12: 5 | B12: =IF(T11>0,B11,D11) -> -0.03125 | C12: =IF(T11>0,D11,C11) -> 0.0625 | D12: =(B12+C12)/2 -> 0.015625 | E12: =$C$2*(1+IF(E$3<=$O$2,$D12,$D12-($D12-$I$6)*MIN(E$3-$O$2,$Q$2)/$Q$2)) -> 2610.1562 | F12: =E12*(1+IF(F$3<=$O$2,$D12,$D12-($D12-$I$6)*MIN(F$3-$O$2,$Q$2)/$Q$2)) -> 2650.9399 | G12: =F12*(1+IF(G$3<=$O$2,$D12,$D12-($D12-$I$6)*MIN(G$3-$O$2,$Q$2)/$Q$2)) -> 2692.3609 | H12: =G12*(1+IF(H$3<=$O$2,$D12,$D12-($D12-$I$6)*MIN(H$3-$O$2,$Q$2)/$Q$2)) -> 2734.429 | I12: =H12*(1+IF(I$3<=$O$2,$D12,$D12-($D12-$I$6)*MIN(I$3-$O$2,$Q$2)/$Q$2)) -> 2777.1545 | J12: =I12*(1+IF(J$3<=$O$2,$D12,$D12-($D12-$I$6)*MIN(J$3-$O$2,$Q$2)/$Q$2)) -> 2827.5876 | K12: =J12*(1+IF(K$3<=$O$2,$D12,$D12-($D12-$I$6)*MIN(K$3-$O$2,$Q$2)/$Q$2)) -> 2886.1045 | L12: =K12*(1+IF(L$3<=$O$2,$D12,$D12-($D12-$I$6)*MIN(L$3-$O$2,$Q$2)/$Q$2)) -> 2953.1487 | M12: =L12*(1+IF(M$3<=$O$2,$D12,$D12-($D12-$I$6)*MIN(M$3-$O$2,$Q$2)/$Q$2)) -> 3029.2366 | N12: =M12*(1+IF(N$3<=$O$2,$D12,$D12-($D12-$I$6)*MIN(N$3-$O$2,$Q$2)/$Q$2)) -> 3114.964 | O12: =SUMPRODUCT(E12:N12,1/(1+$F$6)^$E$3:$N$3)*$E$2 -> 3509.7463 | P12: =N12*$E$2*(1+$I$6)/($F$6-$I$6)/(1+$F$6)^$N$3 -> 3948.3809 | Q12: =O12+P12 -> 7458.1272 | R12: =Q12-$G$2+$I$2 -> 6081.9272 | S12: =R12/$K$2 -> 162.14149 | T12: =S12-$M$2 -> -42.337318
A13: 6 | B13: =IF(T12>0,B12,D12) -> 0.015625 | C13: =IF(T12>0,D12,C12) -> 0.0625 | D13: =(B13+C13)/2 -> 0.0390625 | E13: =$C$2*(1+IF(E$3<=$O$2,$D13,$D13-($D13-$I$6)*MIN(E$3-$O$2,$Q$2)/$Q$2)) -> 2670.3906 | F13: =E13*(1+IF(F$3<=$O$2,$D13,$D13-($D13-$I$6)*MIN(F$3-$O$2,$Q$2)/$Q$2)) -> 2774.7028 | G13: =F13*(1+IF(G$3<=$O$2,$D13,$D13-($D13-$I$6)*MIN(G$3-$O$2,$Q$2)/$Q$2)) -> 2883.0896 | H13: =G13*(1+IF(H$3<=$O$2,$D13,$D13-($D13-$I$6)*MIN(H$3-$O$2,$Q$2)/$Q$2)) -> 2995.7103 | I13: =H13*(1+IF(I$3<=$O$2,$D13,$D13-($D13-$I$6)*MIN(I$3-$O$2,$Q$2)/$Q$2)) -> 3112.7302 | J13: =I13*(1+IF(J$3<=$O$2,$D13,$D13-($D13-$I$6)*MIN(J$3-$O$2,$Q$2)/$Q$2)) -> 3227.6211 | K13: =J13*(1+IF(K$3<=$O$2,$D13,$D13-($D13-$I$6)*MIN(K$3-$O$2,$Q$2)/$Q$2)) -> 3339.8051 | L13: =K13*(1+IF(L$3<=$O$2,$D13,$D13-($D13-$I$6)*MIN(L$3-$O$2,$Q$2)/$Q$2)) -> 3448.6995 | M13: =L13*(1+IF(M$3<=$O$2,$D13,$D13-($D13-$I$6)*MIN(M$3-$O$2,$Q$2)/$Q$2)) -> 3553.721 | N13: =M13*(1+IF(N$3<=$O$2,$D13,$D13-($D13-$I$6)*MIN(N$3-$O$2,$Q$2)/$Q$2)) -> 3654.2913 | O13: =SUMPRODUCT(E13:N13,1/(1+$F$6)^$E$3:$N$3)*$E$2 -> 3883.06 | P13: =N13*$E$2*(1+$I$6)/($F$6-$I$6)/(1+$F$6)^$N$3 -> 4632.0067 | Q13: =O13+P13 -> 8515.0667 | R13: =Q13-$G$2+$I$2 -> 7138.8667 | S13: =R13/$K$2 -> 190.31903 | T13: =S13-$M$2 -> -14.159779
A14: 7 | B14: =IF(T13>0,B13,D13) -> 0.0390625 | C14: =IF(T13>0,D13,C13) -> 0.0625 | D14: =(B14+C14)/2 -> 0.05078125 | E14: =$C$2*(1+IF(E$3<=$O$2,$D14,$D14-($D14-$I$6)*MIN(E$3-$O$2,$Q$2)/$Q$2)) -> 2700.5078 | F14: =E14*(1+IF(F$3<=$O$2,$D14,$D14-($D14-$I$6)*MIN(F$3-$O$2,$Q$2)/$Q$2)) -> 2837.643 | G14: =F14*(1+IF(G$3<=$O$2,$D14,$D14-($D14-$I$6)*MIN(G$3-$O$2,$Q$2)/$Q$2)) -> 2981.742 | H14: =G14*(1+IF(H$3<=$O$2,$D14,$D14-($D14-$I$6)*MIN(H$3-$O$2,$Q$2)/$Q$2)) -> 3133.1586 | I14: =H14*(1+IF(I$3<=$O$2,$D14,$D14-($D14-$I$6)*MIN(I$3-$O$2,$Q$2)/$Q$2)) -> 3292.2643 | J14: =I14*(1+IF(J$3<=$O$2,$D14,$D14-($D14-$I$6)*MIN(J$3-$O$2,$Q$2)/$Q$2)) -> 3444.6468 | K14: =J14*(1+IF(K$3<=$O$2,$D14,$D14-($D14-$I$6)*MIN(K$3-$O$2,$Q$2)/$Q$2)) -> 3588.5943 | L14: =K14*(1+IF(L$3<=$O$2,$D14,$D14-($D14-$I$6)*MIN(L$3-$O$2,$Q$2)/$Q$2)) -> 3722.4219 | M14: =L14*(1+IF(M$3<=$O$2,$D14,$D14-($D14-$I$6)*MIN(M$3-$O$2,$Q$2)/$Q$2)) -> 3844.5034 | N14: =M14*(1+IF(N$3<=$O$2,$D14,$D14-($D14-$I$6)*MIN(N$3-$O$2,$Q$2)/$Q$2)) -> 3953.3028 | O14: =SUMPRODUCT(E14:N14,1/(1+$F$6)^$E$3:$N$3)*$E$2 -> 4084.5962 | P14: =N14*$E$2*(1+$I$6)/($F$6-$I$6)/(1+$F$6)^$N$3 -> 5011.0196 | Q14: =O14+P14 -> 9095.6158 | R14: =Q14-$G$2+$I$2 -> 7719.4158 | S14: =R14/$K$2 -> 205.79621 | T14: =S14-$M$2 -> 1.317404
A15: 8 | B15: =IF(T14>0,B14,D14) -> 0.0390625 | C15: =IF(T14>0,D14,C14) -> 0.05078125 | D15: =(B15+C15)/2 -> 0.044921875 | E15: =$C$2*(1+IF(E$3<=$O$2,$D15,$D15-($D15-$I$6)*MIN(E$3-$O$2,$Q$2)/$Q$2)) -> 2685.4492 | F15: =E15*(1+IF(F$3<=$O$2,$D15,$D15-($D15-$I$6)*MIN(F$3-$O$2,$Q$2)/$Q$2)) -> 2806.0846 | G15: =F15*(1+IF(G$3<=$O$2,$D15,$D15-($D15-$I$6)*MIN(G$3-$O$2,$Q$2)/$Q$2)) -> 2932.1392 | H15: =G15*(1+IF(H$3<=$O$2,$D15,$D15-($D15-$I$6)*MIN(H$3-$O$2,$Q$2)/$Q$2)) -> 3063.8564 | I15: =H15*(1+IF(I$3<=$O$2,$D15,$D15-($D15-$I$6)*MIN(I$3-$O$2,$Q$2)/$Q$2)) -> 3201.4906 | J15: =I15*(1+IF(J$3<=$O$2,$D15,$D15-($D15-$I$6)*MIN(J$3-$O$2,$Q$2)/$Q$2)) -> 3334.6646 | K15: =J15*(1+IF(K$3<=$O$2,$D15,$D15-($D15-$I$6)*MIN(K$3-$O$2,$Q$2)/$Q$2)) -> 3462.2926 | L15: =K15*(1+IF(L$3<=$O$2,$D15,$D15-($D15-$I$6)*MIN(L$3-$O$2,$Q$2)/$Q$2)) -> 3583.2954 | M15: =L15*(1+IF(M$3<=$O$2,$D15,$D15-($D15-$I$6)*MIN(M$3-$O$2,$Q$2)/$Q$2)) -> 3696.6149 | N15: =M15*(1+IF(N$3<=$O$2,$D15,$D15-($D15-$I$6)*MIN(N$3-$O$2,$Q$2)/$Q$2)) -> 3801.2291 | O15: =SUMPRODUCT(E15:N15,1/(1+$F$6)^$E$3:$N$3)*$E$2 -> 3982.5378 | P15: =N15*$E$2*(1+$I$6)/($F$6-$I$6)/(1+$F$6)^$N$3 -> 4818.2581 | Q15: =O15+P15 -> 8800.7959 | R15: =Q15-$G$2+$I$2 -> 7424.5959 | S15: =R15/$K$2 -> 197.93644 | T15: =S15-$M$2 -> -6.5423651
A16: 9 | B16: =IF(T15>0,B15,D15) -> 0.044921875 | C16: =IF(T15>0,D15,C15) -> 0.05078125 | D16: =(B16+C16)/2 -> 0.047851562 | E16: =$C$2*(1+IF(E$3<=$O$2,$D16,$D16-($D16-$I$6)*MIN(E$3-$O$2,$Q$2)/$Q$2)) -> 2692.9785 | F16: =E16*(1+IF(F$3<=$O$2,$D16,$D16-($D16-$I$6)*MIN(F$3-$O$2,$Q$2)/$Q$2)) -> 2821.8417 | G16: =F16*(1+IF(G$3<=$O$2,$D16,$D16-($D16-$I$6)*MIN(G$3-$O$2,$Q$2)/$Q$2)) -> 2956.8713 | H16: =G16*(1+IF(H$3<=$O$2,$D16,$D16-($D16-$I$6)*MIN(H$3-$O$2,$Q$2)/$Q$2)) -> 3098.3622 | I16: =H16*(1+IF(I$3<=$O$2,$D16,$D16-($D16-$I$6)*MIN(I$3-$O$2,$Q$2)/$Q$2)) -> 3246.6237 | J16: =I16*(1+IF(J$3<=$O$2,$D16,$D16-($D16-$I$6)*MIN(J$3-$O$2,$Q$2)/$Q$2)) -> 3389.2844 | K16: =J16*(1+IF(K$3<=$O$2,$D16,$D16-($D16-$I$6)*MIN(K$3-$O$2,$Q$2)/$Q$2)) -> 3524.9606 | L16: =K16*(1+IF(L$3<=$O$2,$D16,$D16-($D16-$I$6)*MIN(L$3-$O$2,$Q$2)/$Q$2)) -> 3652.2844 | M16: =L16*(1+IF(M$3<=$O$2,$D16,$D16-($D16-$I$6)*MIN(M$3-$O$2,$Q$2)/$Q$2)) -> 3769.9256 | N16: =M16*(1+IF(N$3<=$O$2,$D16,$D16-($D16-$I$6)*MIN(N$3-$O$2,$Q$2)/$Q$2)) -> 3876.6145 | O16: =SUMPRODUCT(E16:N16,1/(1+$F$6)^$E$3:$N$3)*$E$2 -> 4033.2405 | P16: =N16*$E$2*(1+$I$6)/($F$6-$I$6)/(1+$F$6)^$N$3 -> 4913.8131 | Q16: =O16+P16 -> 8947.0536 | R16: =Q16-$G$2+$I$2 -> 7570.8536 | S16: =R16/$K$2 -> 201.83561 | T16: =S16-$M$2 -> -2.6431992
A17: 10 | B17: =IF(T16>0,B16,D16) -> 0.047851562 | C17: =IF(T16>0,D16,C16) -> 0.05078125 | D17: =(B17+C17)/2 -> 0.049316406 | E17: =$C$2*(1+IF(E$3<=$O$2,$D17,$D17-($D17-$I$6)*MIN(E$3-$O$2,$Q$2)/$Q$2)) -> 2696.7432 | F17: =E17*(1+IF(F$3<=$O$2,$D17,$D17-($D17-$I$6)*MIN(F$3-$O$2,$Q$2)/$Q$2)) -> 2829.7368 | G17: =F17*(1+IF(G$3<=$O$2,$D17,$D17-($D17-$I$6)*MIN(G$3-$O$2,$Q$2)/$Q$2)) -> 2969.2893 | H17: =G17*(1+IF(H$3<=$O$2,$D17,$D17-($D17-$I$6)*MIN(H$3-$O$2,$Q$2)/$Q$2)) -> 3115.724 | I17: =H17*(1+IF(I$3<=$O$2,$D17,$D17-($D17-$I$6)*MIN(I$3-$O$2,$Q$2)/$Q$2)) -> 3269.3803 | J17: =I17*(1+IF(J$3<=$O$2,$D17,$D17-($D17-$I$6)*MIN(J$3-$O$2,$Q$2)/$Q$2)) -> 3416.8722 | K17: =J17*(1+IF(K$3<=$O$2,$D17,$D17-($D17-$I$6)*MIN(K$3-$O$2,$Q$2)/$Q$2)) -> 3556.656 | L17: =K17*(1+IF(L$3<=$O$2,$D17,$D17-($D17-$I$6)*MIN(L$3-$O$2,$Q$2)/$Q$2)) -> 3687.2086 | M17: =L17*(1+IF(M$3<=$O$2,$D17,$D17-($D17-$I$6)*MIN(M$3-$O$2,$Q$2)/$Q$2)) -> 3807.0549 | N17: =M17*(1+IF(N$3<=$O$2,$D17,$D17-($D17-$I$6)*MIN(N$3-$O$2,$Q$2)/$Q$2)) -> 3914.7946 | O17: =SUMPRODUCT(E17:N17,1/(1+$F$6)^$E$3:$N$3)*$E$2 -> 4058.8363 | P17: =N17*$E$2*(1+$I$6)/($F$6-$I$6)/(1+$F$6)^$N$3 -> 4962.2084 | Q17: =O17+P17 -> 9021.0446 | R17: =Q17-$G$2+$I$2 -> 7644.8446 | S17: =R17/$K$2 -> 203.80817 | T17: =S17-$M$2 -> -0.67063088
A18: 11 | B18: =IF(T17>0,B17,D17) -> 0.049316406 | C18: =IF(T17>0,D17,C17) -> 0.05078125 | D18: =(B18+C18)/2 -> 0.050048828 | E18: =$C$2*(1+IF(E$3<=$O$2,$D18,$D18-($D18-$I$6)*MIN(E$3-$O$2,$Q$2)/$Q$2)) -> 2698.6255 | F18: =E18*(1+IF(F$3<=$O$2,$D18,$D18-($D18-$I$6)*MIN(F$3-$O$2,$Q$2)/$Q$2)) -> 2833.6885 | G18: =F18*(1+IF(G$3<=$O$2,$D18,$D18-($D18-$I$6)*MIN(G$3-$O$2,$Q$2)/$Q$2)) -> 2975.5113 | H18: =G18*(1+IF(H$3<=$O$2,$D18,$D18-($D18-$I$6)*MIN(H$3-$O$2,$Q$2)/$Q$2)) -> 3124.4322 | I18: =H18*(1+IF(I$3<=$O$2,$D18,$D18-($D18-$I$6)*MIN(I$3-$O$2,$Q$2)/$Q$2)) -> 3280.8063 | J18: =I18*(1+IF(J$3<=$O$2,$D18,$D18-($D18-$I$6)*MIN(J$3-$O$2,$Q$2)/$Q$2)) -> 3430.7361 | K18: =J18*(1+IF(K$3<=$O$2,$D18,$D18-($D18-$I$6)*MIN(K$3-$O$2,$Q$2)/$Q$2)) -> 3572.5946 | L18: =K18*(1+IF(L$3<=$O$2,$D18,$D18-($D18-$I$6)*MIN(L$3-$O$2,$Q$2)/$Q$2)) -> 3704.779 | M18: =L18*(1+IF(M$3<=$O$2,$D18,$D18-($D18-$I$6)*MIN(M$3-$O$2,$Q$2)/$Q$2)) -> 3825.7391 | N18: =M18*(1+IF(N$3<=$O$2,$D18,$D18-($D18-$I$6)*MIN(N$3-$O$2,$Q$2)/$Q$2)) -> 3934.0076 | O18: =SUMPRODUCT(E18:N18,1/(1+$F$6)^$E$3:$N$3)*$E$2 -> 4071.6957 | P18: =N18*$E$2*(1+$I$6)/($F$6-$I$6)/(1+$F$6)^$N$3 -> 4986.5618 | Q18: =O18+P18 -> 9058.2575 | R18: =Q18-$G$2+$I$2 -> 7682.0575 | S18: =R18/$K$2 -> 204.80025 | T18: =S18-$M$2 -> 0.3214465
A19: 12 | B19: =IF(T18>0,B18,D18) -> 0.049316406 | C19: =IF(T18>0,D18,C18) -> 0.050048828 | D19: =(B19+C19)/2 -> 0.049682617 | E19: =$C$2*(1+IF(E$3<=$O$2,$D19,$D19-($D19-$I$6)*MIN(E$3-$O$2,$Q$2)/$Q$2)) -> 2697.6843 | F19: =E19*(1+IF(F$3<=$O$2,$D19,$D19-($D19-$I$6)*MIN(F$3-$O$2,$Q$2)/$Q$2)) -> 2831.7123 | G19: =F19*(1+IF(G$3<=$O$2,$D19,$D19-($D19-$I$6)*MIN(G$3-$O$2,$Q$2)/$Q$2)) -> 2972.3992 | H19: =G19*(1+IF(H$3<=$O$2,$D19,$D19-($D19-$I$6)*MIN(H$3-$O$2,$Q$2)/$Q$2)) -> 3120.0758 | I19: =H19*(1+IF(I$3<=$O$2,$D19,$D19-($D19-$I$6)*MIN(I$3-$O$2,$Q$2)/$Q$2)) -> 3275.0893 | J19: =I19*(1+IF(J$3<=$O$2,$D19,$D19-($D19-$I$6)*MIN(J$3-$O$2,$Q$2)/$Q$2)) -> 3423.7983 | K19: =J19*(1+IF(K$3<=$O$2,$D19,$D19-($D19-$I$6)*MIN(K$3-$O$2,$Q$2)/$Q$2)) -> 3564.6177 | L19: =K19*(1+IF(L$3<=$O$2,$D19,$D19-($D19-$I$6)*MIN(L$3-$O$2,$Q$2)/$Q$2)) -> 3695.9847 | M19: =L19*(1+IF(M$3<=$O$2,$D19,$D19-($D19-$I$6)*MIN(M$3-$O$2,$Q$2)/$Q$2)) -> 3816.3871 | N19: =M19*(1+IF(N$3<=$O$2,$D19,$D19-($D19-$I$6)*MIN(N$3-$O$2,$Q$2)/$Q$2)) -> 3924.3908 | O19: =SUMPRODUCT(E19:N19,1/(1+$F$6)^$E$3:$N$3)*$E$2 -> 4065.2608 | P19: =N19*$E$2*(1+$I$6)/($F$6-$I$6)/(1+$F$6)^$N$3 -> 4974.3721 | Q19: =O19+P19 -> 9039.6329 | R19: =Q19-$G$2+$I$2 -> 7663.4329 | S19: =R19/$K$2 -> 204.30373 | T19: =S19-$M$2 -> -0.17507636
A20: 13 | B20: =IF(T19>0,B19,D19) -> 0.049682617 | C20: =IF(T19>0,D19,C19) -> 0.050048828 | D20: =(B20+C20)/2 -> 0.049865723 | E20: =$C$2*(1+IF(E$3<=$O$2,$D20,$D20-($D20-$I$6)*MIN(E$3-$O$2,$Q$2)/$Q$2)) -> 2698.1549 | F20: =E20*(1+IF(F$3<=$O$2,$D20,$D20-($D20-$I$6)*MIN(F$3-$O$2,$Q$2)/$Q$2)) -> 2832.7004 | G20: =F20*(1+IF(G$3<=$O$2,$D20,$D20-($D20-$I$6)*MIN(G$3-$O$2,$Q$2)/$Q$2)) -> 2973.955 | H20: =G20*(1+IF(H$3<=$O$2,$D20,$D20-($D20-$I$6)*MIN(H$3-$O$2,$Q$2)/$Q$2)) -> 3122.2534 | I20: =H20*(1+IF(I$3<=$O$2,$D20,$D20-($D20-$I$6)*MIN(I$3-$O$2,$Q$2)/$Q$2)) -> 3277.9468 | J20: =I20*(1+IF(J$3<=$O$2,$D20,$D20-($D20-$I$6)*MIN(J$3-$O$2,$Q$2)/$Q$2)) -> 3427.2658 | K20: =J20*(1+IF(K$3<=$O$2,$D20,$D20-($D20-$I$6)*MIN(K$3-$O$2,$Q$2)/$Q$2)) -> 3568.6043 | L20: =K20*(1+IF(L$3<=$O$2,$D20,$D20-($D20-$I$6)*MIN(L$3-$O$2,$Q$2)/$Q$2)) -> 3700.3796 | M20: =L20*(1+IF(M$3<=$O$2,$D20,$D20-($D20-$I$6)*MIN(M$3-$O$2,$Q$2)/$Q$2)) -> 3821.0606 | N20: =M20*(1+IF(N$3<=$O$2,$D20,$D20-($D20-$I$6)*MIN(N$3-$O$2,$Q$2)/$Q$2)) -> 3929.1966 | O20: =SUMPRODUCT(E20:N20,1/(1+$F$6)^$E$3:$N$3)*$E$2 -> 4068.477 | P20: =N20*$E$2*(1+$I$6)/($F$6-$I$6)/(1+$F$6)^$N$3 -> 4980.4637 | Q20: =O20+P20 -> 9048.9406 | R20: =Q20-$G$2+$I$2 -> 7672.7406 | S20: =R20/$K$2 -> 204.55187 | T20: =S20-$M$2 -> 0.073063926
... A47: 40 | B47: =IF(T46>0,B46,D46) -> 0.049811827 | C47: =IF(T46>0,D46,C46) -> 0.049811827 | D47: =(B47+C47)/2 -> 0.049811827 | E47: =$C$2*(1+IF(E$3<=$O$2,$D47,$D47-($D47-$I$6)*MIN(E$3-$O$2,$Q$2)/$Q$2)) -> 2698.0164 | F47: =E47*(1+IF(F$3<=$O$2,$D47,$D47-($D47-$I$6)*MIN(F$3-$O$2,$Q$2)/$Q$2)) -> 2832.4095 | G47: =F47*(1+IF(G$3<=$O$2,$D47,$D47-($D47-$I$6)*MIN(G$3-$O$2,$Q$2)/$Q$2)) -> 2973.497 | H47: =G47*(1+IF(H$3<=$O$2,$D47,$D47-($D47-$I$6)*MIN(H$3-$O$2,$Q$2)/$Q$2)) -> 3121.6123 | I47: =H47*(1+IF(I$3<=$O$2,$D47,$D47-($D47-$I$6)*MIN(I$3-$O$2,$Q$2)/$Q$2)) -> 3277.1055 | J47: =I47*(1+IF(J$3<=$O$2,$D47,$D47-($D47-$I$6)*MIN(J$3-$O$2,$Q$2)/$Q$2)) -> 3426.2448 | K47: =J47*(1+IF(K$3<=$O$2,$D47,$D47-($D47-$I$6)*MIN(K$3-$O$2,$Q$2)/$Q$2)) -> 3567.4304 | L47: =K47*(1+IF(L$3<=$O$2,$D47,$D47-($D47-$I$6)*MIN(L$3-$O$2,$Q$2)/$Q$2)) -> 3699.0855 | M47: =L47*(1+IF(M$3<=$O$2,$D47,$D47-($D47-$I$6)*MIN(M$3-$O$2,$Q$2)/$Q$2)) -> 3819.6844 | N47: =M47*(1+IF(N$3<=$O$2,$D47,$D47-($D47-$I$6)*MIN(N$3-$O$2,$Q$2)/$Q$2)) -> 3927.7815 | O47: =SUMPRODUCT(E47:N47,1/(1+$F$6)^$E$3:$N$3)*$E$2 -> 4067.53 | P47: =N47*$E$2*(1+$I$6)/($F$6-$I$6)/(1+$F$6)^$N$3 -> 4978.67 | Q47: =O47+P47 -> 9046.2 | R47: =Q47-$G$2+$I$2 -> 7670 | S47: =R47/$K$2 -> 204.47881 | T47: =S47-$M$2 -> -1.690637e-09
A49: Grid block 2: row 1, column 1 of table A (24 steps) | E49: WACC | F49: =Sensitivity!$B$10 -> 0.084183338 | G49: Terminal growth | I49: =Sensitivity!$C$9 -> 0.0183
A50: Step | B50: Low | C50: High | D50: Mid | E50: Rev Y1 | F50: Rev Y2 | G50: Rev Y3 | H50: Rev Y4 | I50: Rev Y5 | J50: Rev Y6 | K50: Rev Y7 | L50: Rev Y8 | M50: Rev Y9 | N50: Rev Y10 | O50: PV of FCF | P50: PV of TV | Q50: EV | R50: Equity | S50: Per share | T50: Value - price
A51: 1 | B51: -0.5 | C51: 1 | D51: =(B51+C51)/2 -> 0.25 | E51: =$C$2*(1+IF(E$3<=$O$2,$D51,$D51-($D51-$I$49)*MIN(E$3-$O$2,$Q$2)/$Q$2)) -> 3212.5 | F51: =E51*(1+IF(F$3<=$O$2,$D51,$D51-($D51-$I$49)*MIN(F$3-$O$2,$Q$2)/$Q$2)) -> 4015.625 | G51: =F51*(1+IF(G$3<=$O$2,$D51,$D51-($D51-$I$49)*MIN(G$3-$O$2,$Q$2)/$Q$2)) -> 5019.5312 | H51: =G51*(1+IF(H$3<=$O$2,$D51,$D51-($D51-$I$49)*MIN(H$3-$O$2,$Q$2)/$Q$2)) -> 6274.4141 | I51: =H51*(1+IF(I$3<=$O$2,$D51,$D51-($D51-$I$49)*MIN(I$3-$O$2,$Q$2)/$Q$2)) -> 7843.0176 | J51: =I51*(1+IF(J$3<=$O$2,$D51,$D51-($D51-$I$49)*MIN(J$3-$O$2,$Q$2)/$Q$2)) -> 9440.3265 | K51: =J51*(1+IF(K$3<=$O$2,$D51,$D51-($D51-$I$49)*MIN(K$3-$O$2,$Q$2)/$Q$2)) -> 10925.479 | L51: =K51*(1+IF(L$3<=$O$2,$D51,$D51-($D51-$I$49)*MIN(L$3-$O$2,$Q$2)/$Q$2)) -> 12137.988 | M51: =L51*(1+IF(M$3<=$O$2,$D51,$D51-($D51-$I$49)*MIN(M$3-$O$2,$Q$2)/$Q$2)) -> 12922.588 | N51: =M51*(1+IF(N$3<=$O$2,$D51,$D51-($D51-$I$49)*MIN(N$3-$O$2,$Q$2)/$Q$2)) -> 13159.071 | O51: =SUMPRODUCT(E51:N51,1/(1+$F$49)^$E$3:$N$3)*$E$2 -> 10103.721 | P51: =N51*$E$2*(1+$I$49)/($F$49-$I$49)/(1+$F$49)^$N$3 -> 18105.93 | Q51: =O51+P51 -> 28209.652 | R51: =Q51-$G$2+$I$2 -> 26833.452 | S51: =R51/$K$2 -> 715.36795 | T51: =S51-$M$2 -> 510.88914
A52: 2 | B52: =IF(T51>0,B51,D51) -> -0.5 | C52: =IF(T51>0,D51,C51) -> 0.25 | D52: =(B52+C52)/2 -> -0.125 | E52: =$C$2*(1+IF(E$3<=$O$2,$D52,$D52-($D52-$I$49)*MIN(E$3-$O$2,$Q$2)/$Q$2)) -> 2248.75 | F52: =E52*(1+IF(F$3<=$O$2,$D52,$D52-($D52-$I$49)*MIN(F$3-$O$2,$Q$2)/$Q$2)) -> 1967.6562 | G52: =F52*(1+IF(G$3<=$O$2,$D52,$D52-($D52-$I$49)*MIN(G$3-$O$2,$Q$2)/$Q$2)) -> 1721.6992 | H52: =G52*(1+IF(H$3<=$O$2,$D52,$D52-($D52-$I$49)*MIN(H$3-$O$2,$Q$2)/$Q$2)) -> 1506.4868 | I52: =H52*(1+IF(I$3<=$O$2,$D52,$D52-($D52-$I$49)*MIN(I$3-$O$2,$Q$2)/$Q$2)) -> 1318.176 | J52: =I52*(1+IF(J$3<=$O$2,$D52,$D52-($D52-$I$49)*MIN(J$3-$O$2,$Q$2)/$Q$2)) -> 1191.1829 | K52: =J52*(1+IF(K$3<=$O$2,$D52,$D52-($D52-$I$49)*MIN(K$3-$O$2,$Q$2)/$Q$2)) -> 1110.5636 | L52: =K52*(1+IF(L$3<=$O$2,$D52,$D52-($D52-$I$49)*MIN(L$3-$O$2,$Q$2)/$Q$2)) -> 1067.2294 | M52: =L52*(1+IF(M$3<=$O$2,$D52,$D52-($D52-$I$49)*MIN(M$3-$O$2,$Q$2)/$Q$2)) -> 1056.1729 | N52: =M52*(1+IF(N$3<=$O$2,$D52,$D52-($D52-$I$49)*MIN(N$3-$O$2,$Q$2)/$Q$2)) -> 1075.5009 | O52: =SUMPRODUCT(E52:N52,1/(1+$F$49)^$E$3:$N$3)*$E$2 -> 1994.0849 | P52: =N52*$E$2*(1+$I$49)/($F$49-$I$49)/(1+$F$49)^$N$3 -> 1479.8115 | Q52: =O52+P52 -> 3473.8964 | R52: =Q52-$G$2+$I$2 -> 2097.6964 | S52: =R52/$K$2 -> 55.923658 | T52: =S52-$M$2 -> -148.55515
A53: 3 | B53: =IF(T52>0,B52,D52) -> -0.125 | C53: =IF(T52>0,D52,C52) -> 0.25 | D53: =(B53+C53)/2 -> 0.0625 | E53: =$C$2*(1+IF(E$3<=$O$2,$D53,$D53-($D53-$I$49)*MIN(E$3-$O$2,$Q$2)/$Q$2)) -> 2730.625 | F53: =E53*(1+IF(F$3<=$O$2,$D53,$D53-($D53-$I$49)*MIN(F$3-$O$2,$Q$2)/$Q$2)) -> 2901.2891 | G53: =F53*(1+IF(G$3<=$O$2,$D53,$D53-($D53-$I$49)*MIN(G$3-$O$2,$Q$2)/$Q$2)) -> 3082.6196 | H53: =G53*(1+IF(H$3<=$O$2,$D53,$D53-($D53-$I$49)*MIN(H$3-$O$2,$Q$2)/$Q$2)) -> 3275.2834 | I53: =H53*(1+IF(I$3<=$O$2,$D53,$D53-($D53-$I$49)*MIN(I$3-$O$2,$Q$2)/$Q$2)) -> 3479.9886 | J53: =I53*(1+IF(J$3<=$O$2,$D53,$D53-($D53-$I$49)*MIN(J$3-$O$2,$Q$2)/$Q$2)) -> 3666.7248 | K53: =J53*(1+IF(K$3<=$O$2,$D53,$D53-($D53-$I$49)*MIN(K$3-$O$2,$Q$2)/$Q$2)) -> 3831.0674 | L53: =K53*(1+IF(L$3<=$O$2,$D53,$D53-($D53-$I$49)*MIN(L$3-$O$2,$Q$2)/$Q$2)) -> 3968.9092 | M53: =L53*(1+IF(M$3<=$O$2,$D53,$D53-($D53-$I$49)*MIN(M$3-$O$2,$Q$2)/$Q$2)) -> 4076.6254 | N53: =M53*(1+IF(N$3<=$O$2,$D53,$D53-($D53-$I$49)*MIN(N$3-$O$2,$Q$2)/$Q$2)) -> 4151.2276 | O53: =SUMPRODUCT(E53:N53,1/(1+$F$49)^$E$3:$N$3)*$E$2 -> 4480.9877 | P53: =N53*$E$2*(1+$I$49)/($F$49-$I$49)/(1+$F$49)^$N$3 -> 5711.789 | Q53: =O53+P53 -> 10192.777 | R53: =Q53-$G$2+$I$2 -> 8816.5767 | S53: =R53/$K$2 -> 235.04603 | T53: =S53-$M$2 -> 30.567227
A54: 4 | B54: =IF(T53>0,B53,D53) -> -0.125 | C54: =IF(T53>0,D53,C53) -> 0.0625 | D54: =(B54+C54)/2 -> -0.03125 | E54: =$C$2*(1+IF(E$3<=$O$2,$D54,$D54-($D54-$I$49)*MIN(E$3-$O$2,$Q$2)/$Q$2)) -> 2489.6875 | F54: =E54*(1+IF(F$3<=$O$2,$D54,$D54-($D54-$I$49)*MIN(F$3-$O$2,$Q$2)/$Q$2)) -> 2411.8848 | G54: =F54*(1+IF(G$3<=$O$2,$D54,$D54-($D54-$I$49)*MIN(G$3-$O$2,$Q$2)/$Q$2)) -> 2336.5134 | H54: =G54*(1+IF(H$3<=$O$2,$D54,$D54-($D54-$I$49)*MIN(H$3-$O$2,$Q$2)/$Q$2)) -> 2263.4973 | I54: =H54*(1+IF(I$3<=$O$2,$D54,$D54-($D54-$I$49)*MIN(I$3-$O$2,$Q$2)/$Q$2)) -> 2192.763 | J54: =I54*(1+IF(J$3<=$O$2,$D54,$D54-($D54-$I$49)*MIN(J$3-$O$2,$Q$2)/$Q$2)) -> 2145.9695 | K54: =J54*(1+IF(K$3<=$O$2,$D54,$D54-($D54-$I$49)*MIN(K$3-$O$2,$Q$2)/$Q$2)) -> 2121.441 | L54: =K54*(1+IF(L$3<=$O$2,$D54,$D54-($D54-$I$49)*MIN(L$3-$O$2,$Q$2)/$Q$2)) -> 2118.2164 | M54: =L54*(1+IF(M$3<=$O$2,$D54,$D54-($D54-$I$49)*MIN(M$3-$O$2,$Q$2)/$Q$2)) -> 2135.9883 | N54: =M54*(1+IF(N$3<=$O$2,$D54,$D54-($D54-$I$49)*MIN(N$3-$O$2,$Q$2)/$Q$2)) -> 2175.0769 | O54: =SUMPRODUCT(E54:N54,1/(1+$F$49)^$E$3:$N$3)*$E$2 -> 2980.6328 | P54: =N54*$E$2*(1+$I$49)/($F$49-$I$49)/(1+$F$49)^$N$3 -> 2992.7485 | Q54: =O54+P54 -> 5973.3813 | R54: =Q54-$G$2+$I$2 -> 4597.1813 | S54: =R54/$K$2 -> 122.55882 | T54: =S54-$M$2 -> -81.919988
A55: 5 | B55: =IF(T54>0,B54,D54) -> -0.03125 | C55: =IF(T54>0,D54,C54) -> 0.0625 | D55: =(B55+C55)/2 -> 0.015625 | E55: =$C$2*(1+IF(E$3<=$O$2,$D55,$D55-($D55-$I$49)*MIN(E$3-$O$2,$Q$2)/$Q$2)) -> 2610.1562 | F55: =E55*(1+IF(F$3<=$O$2,$D55,$D55-($D55-$I$49)*MIN(F$3-$O$2,$Q$2)/$Q$2)) -> 2650.9399 | G55: =F55*(1+IF(G$3<=$O$2,$D55,$D55-($D55-$I$49)*MIN(G$3-$O$2,$Q$2)/$Q$2)) -> 2692.3609 | H55: =G55*(1+IF(H$3<=$O$2,$D55,$D55-($D55-$I$49)*MIN(H$3-$O$2,$Q$2)/$Q$2)) -> 2734.429 | I55: =H55*(1+IF(I$3<=$O$2,$D55,$D55-($D55-$I$49)*MIN(I$3-$O$2,$Q$2)/$Q$2)) -> 2777.1545 | J55: =I55*(1+IF(J$3<=$O$2,$D55,$D55-($D55-$I$49)*MIN(J$3-$O$2,$Q$2)/$Q$2)) -> 2822.0333 | K55: =J55*(1+IF(K$3<=$O$2,$D55,$D55-($D55-$I$49)*MIN(K$3-$O$2,$Q$2)/$Q$2)) -> 2869.1471 | L55: =K55*(1+IF(L$3<=$O$2,$D55,$D55-($D55-$I$49)*MIN(L$3-$O$2,$Q$2)/$Q$2)) -> 2918.5825 | M55: =L55*(1+IF(M$3<=$O$2,$D55,$D55-($D55-$I$49)*MIN(M$3-$O$2,$Q$2)/$Q$2)) -> 2970.4312 | N55: =M55*(1+IF(N$3<=$O$2,$D55,$D55-($D55-$I$49)*MIN(N$3-$O$2,$Q$2)/$Q$2)) -> 3024.79 | O55: =SUMPRODUCT(E55:N55,1/(1+$F$49)^$E$3:$N$3)*$E$2 -> 3653.17 | P55: =N55*$E$2*(1+$I$49)/($F$49-$I$49)/(1+$F$49)^$N$3 -> 4161.8924 | Q55: =O55+P55 -> 7815.0624 | R55: =Q55-$G$2+$I$2 -> 6438.8624 | S55: =R55/$K$2 -> 171.65722 | T55: =S55-$M$2 -> -32.821584
A56: 6 | B56: =IF(T55>0,B55,D55) -> 0.015625 | C56: =IF(T55>0,D55,C55) -> 0.0625 | D56: =(B56+C56)/2 -> 0.0390625 | E56: =$C$2*(1+IF(E$3<=$O$2,$D56,$D56-($D56-$I$49)*MIN(E$3-$O$2,$Q$2)/$Q$2)) -> 2670.3906 | F56: =E56*(1+IF(F$3<=$O$2,$D56,$D56-($D56-$I$49)*MIN(F$3-$O$2,$Q$2)/$Q$2)) -> 2774.7028 | G56: =F56*(1+IF(G$3<=$O$2,$D56,$D56-($D56-$I$49)*MIN(G$3-$O$2,$Q$2)/$Q$2)) -> 2883.0896 | H56: =G56*(1+IF(H$3<=$O$2,$D56,$D56-($D56-$I$49)*MIN(H$3-$O$2,$Q$2)/$Q$2)) -> 2995.7103 | I56: =H56*(1+IF(I$3<=$O$2,$D56,$D56-($D56-$I$49)*MIN(I$3-$O$2,$Q$2)/$Q$2)) -> 3112.7302 | J56: =I56*(1+IF(J$3<=$O$2,$D56,$D56-($D56-$I$49)*MIN(J$3-$O$2,$Q$2)/$Q$2)) -> 3221.3956 | K56: =J56*(1+IF(K$3<=$O$2,$D56,$D56-($D56-$I$49)*MIN(K$3-$O$2,$Q$2)/$Q$2)) -> 3320.4777 | L56: =K56*(1+IF(L$3<=$O$2,$D56,$D56-($D56-$I$49)*MIN(L$3-$O$2,$Q$2)/$Q$2)) -> 3408.819 | M56: =L56*(1+IF(M$3<=$O$2,$D56,$D56-($D56-$I$49)*MIN(M$3-$O$2,$Q$2)/$Q$2)) -> 3485.3555 | N56: =M56*(1+IF(N$3<=$O$2,$D56,$D56-($D56-$I$49)*MIN(N$3-$O$2,$Q$2)/$Q$2)) -> 3549.1375 | O56: =SUMPRODUCT(E56:N56,1/(1+$F$49)^$E$3:$N$3)*$E$2 -> 4045.7264 | P56: =N56*$E$2*(1+$I$49)/($F$49-$I$49)/(1+$F$49)^$N$3 -> 4883.3566 | Q56: =O56+P56 -> 8929.083 | R56: =Q56-$G$2+$I$2 -> 7552.883 | S56: =R56/$K$2 -> 201.35652 | T56: =S56-$M$2 -> -3.1222882
A57: 7 | B57: =IF(T56>0,B56,D56) -> 0.0390625 | C57: =IF(T56>0,D56,C56) -> 0.0625 | D57: =(B57+C57)/2 -> 0.05078125 | E57: =$C$2*(1+IF(E$3<=$O$2,$D57,$D57-($D57-$I$49)*MIN(E$3-$O$2,$Q$2)/$Q$2)) -> 2700.5078 | F57: =E57*(1+IF(F$3<=$O$2,$D57,$D57-($D57-$I$49)*MIN(F$3-$O$2,$Q$2)/$Q$2)) -> 2837.643 | G57: =F57*(1+IF(G$3<=$O$2,$D57,$D57-($D57-$I$49)*MIN(G$3-$O$2,$Q$2)/$Q$2)) -> 2981.742 | H57: =G57*(1+IF(H$3<=$O$2,$D57,$D57-($D57-$I$49)*MIN(H$3-$O$2,$Q$2)/$Q$2)) -> 3133.1586 | I57: =H57*(1+IF(I$3<=$O$2,$D57,$D57-($D57-$I$49)*MIN(I$3-$O$2,$Q$2)/$Q$2)) -> 3292.2643 | J57: =I57*(1+IF(J$3<=$O$2,$D57,$D57-($D57-$I$49)*MIN(J$3-$O$2,$Q$2)/$Q$2)) -> 3438.0623 | K57: =J57*(1+IF(K$3<=$O$2,$D57,$D57-($D57-$I$49)*MIN(K$3-$O$2,$Q$2)/$Q$2)) -> 3567.9823 | L57: =K57*(1+IF(L$3<=$O$2,$D57,$D57-($D57-$I$49)*MIN(L$3-$O$2,$Q$2)/$Q$2)) -> 3679.6334 | M57: =L57*(1+IF(M$3<=$O$2,$D57,$D57-($D57-$I$49)*MIN(M$3-$O$2,$Q$2)/$Q$2)) -> 3770.8745 | N57: =M57*(1+IF(N$3<=$O$2,$D57,$D57-($D57-$I$49)*MIN(N$3-$O$2,$Q$2)/$Q$2)) -> 3839.8815 | O57: =SUMPRODUCT(E57:N57,1/(1+$F$49)^$E$3:$N$3)*$E$2 -> 4257.7577 | P57: =N57*$E$2*(1+$I$49)/($F$49-$I$49)/(1+$F$49)^$N$3 -> 5283.3993 | Q57: =O57+P57 -> 9541.157 | R57: =Q57-$G$2+$I$2 -> 8164.957 | S57: =R57/$K$2 -> 217.67414 | T57: =S57-$M$2 -> 13.195335
A58: 8 | B58: =IF(T57>0,B57,D57) -> 0.0390625 | C58: =IF(T57>0,D57,C57) -> 0.05078125 | D58: =(B58+C58)/2 -> 0.044921875 | E58: =$C$2*(1+IF(E$3<=$O$2,$D58,$D58-($D58-$I$49)*MIN(E$3-$O$2,$Q$2)/$Q$2)) -> 2685.4492 | F58: =E58*(1+IF(F$3<=$O$2,$D58,$D58-($D58-$I$49)*MIN(F$3-$O$2,$Q$2)/$Q$2)) -> 2806.0846 | G58: =F58*(1+IF(G$3<=$O$2,$D58,$D58-($D58-$I$49)*MIN(G$3-$O$2,$Q$2)/$Q$2)) -> 2932.1392 | H58: =G58*(1+IF(H$3<=$O$2,$D58,$D58-($D58-$I$49)*MIN(H$3-$O$2,$Q$2)/$Q$2)) -> 3063.8564 | I58: =H58*(1+IF(I$3<=$O$2,$D58,$D58-($D58-$I$49)*MIN(I$3-$O$2,$Q$2)/$Q$2)) -> 3201.4906 | J58: =I58*(1+IF(J$3<=$O$2,$D58,$D58-($D58-$I$49)*MIN(J$3-$O$2,$Q$2)/$Q$2)) -> 3328.2616 | K58: =J58*(1+IF(K$3<=$O$2,$D58,$D58-($D58-$I$49)*MIN(K$3-$O$2,$Q$2)/$Q$2)) -> 3442.3315 | L58: =K58*(1+IF(L$3<=$O$2,$D58,$D58-($D58-$I$49)*MIN(L$3-$O$2,$Q$2)/$Q$2)) -> 3541.9827 | M58: =L58*(1+IF(M$3<=$O$2,$D58,$D58-($D58-$I$49)*MIN(M$3-$O$2,$Q$2)/$Q$2)) -> 3625.6599 | N58: =M58*(1+IF(N$3<=$O$2,$D58,$D58-($D58-$I$49)*MIN(N$3-$O$2,$Q$2)/$Q$2)) -> 3692.0094 | O58: =SUMPRODUCT(E58:N58,1/(1+$F$49)^$E$3:$N$3)*$E$2 -> 4150.3757 | P58: =N58*$E$2*(1+$I$49)/($F$49-$I$49)/(1+$F$49)^$N$3 -> 5079.938 | Q58: =O58+P58 -> 9230.3137 | R58: =Q58-$G$2+$I$2 -> 7854.1137 | S58: =R58/$K$2 -> 209.3872 | T58: =S58-$M$2 -> 4.9083904
A59: 9 | B59: =IF(T58>0,B58,D58) -> 0.0390625 | C59: =IF(T58>0,D58,C58) -> 0.044921875 | D59: =(B59+C59)/2 -> 0.041992188 | E59: =$C$2*(1+IF(E$3<=$O$2,$D59,$D59-($D59-$I$49)*MIN(E$3-$O$2,$Q$2)/$Q$2)) -> 2677.9199 | F59: =E59*(1+IF(F$3<=$O$2,$D59,$D59-($D59-$I$49)*MIN(F$3-$O$2,$Q$2)/$Q$2)) -> 2790.3716 | G59: =F59*(1+IF(G$3<=$O$2,$D59,$D59-($D59-$I$49)*MIN(G$3-$O$2,$Q$2)/$Q$2)) -> 2907.5454 | H59: =G59*(1+IF(H$3<=$O$2,$D59,$D59-($D59-$I$49)*MIN(H$3-$O$2,$Q$2)/$Q$2)) -> 3029.6396 | I59: =H59*(1+IF(I$3<=$O$2,$D59,$D59-($D59-$I$49)*MIN(I$3-$O$2,$Q$2)/$Q$2)) -> 3156.8608 | J59: =I59*(1+IF(J$3<=$O$2,$D59,$D59-($D59-$I$49)*MIN(J$3-$O$2,$Q$2)/$Q$2)) -> 3274.4657 | K59: =J59*(1+IF(K$3<=$O$2,$D59,$D59-($D59-$I$49)*MIN(K$3-$O$2,$Q$2)/$Q$2)) -> 3380.936 | L59: =K59*(1+IF(L$3<=$O$2,$D59,$D59-($D59-$I$49)*MIN(L$3-$O$2,$Q$2)/$Q$2)) -> 3474.8479 | M59: =L59*(1+IF(M$3<=$O$2,$D59,$D59-($D59-$I$49)*MIN(M$3-$O$2,$Q$2)/$Q$2)) -> 3554.9029 | N59: =M59*(1+IF(N$3<=$O$2,$D59,$D59-($D59-$I$49)*MIN(N$3-$O$2,$Q$2)/$Q$2)) -> 3619.9576 | O59: =SUMPRODUCT(E59:N59,1/(1+$F$49)^$E$3:$N$3)*$E$2 -> 4097.7136 | P59: =N59*$E$2*(1+$I$49)/($F$49-$I$49)/(1+$F$49)^$N$3 -> 4980.7999 | Q59: =O59+P59 -> 9078.5135 | R59: =Q59-$G$2+$I$2 -> 7702.3135 | S59: =R59/$K$2 -> 205.34027 | T59: =S59-$M$2 -> 0.86146471
A60: 10 | B60: =IF(T59>0,B59,D59) -> 0.0390625 | C60: =IF(T59>0,D59,C59) -> 0.041992188 | D60: =(B60+C60)/2 -> 0.040527344 | E60: =$C$2*(1+IF(E$3<=$O$2,$D60,$D60-($D60-$I$49)*MIN(E$3-$O$2,$Q$2)/$Q$2)) -> 2674.1553 | F60: =E60*(1+IF(F$3<=$O$2,$D60,$D60-($D60-$I$49)*MIN(F$3-$O$2,$Q$2)/$Q$2)) -> 2782.5317 | G60: =F60*(1+IF(G$3<=$O$2,$D60,$D60-($D60-$I$49)*MIN(G$3-$O$2,$Q$2)/$Q$2)) -> 2895.3003 | H60: =G60*(1+IF(H$3<=$O$2,$D60,$D60-($D60-$I$49)*MIN(H$3-$O$2,$Q$2)/$Q$2)) -> 3012.6391 | I60: =H60*(1+IF(I$3<=$O$2,$D60,$D60-($D60-$I$49)*MIN(I$3-$O$2,$Q$2)/$Q$2)) -> 3134.7334 | J60: =I60*(1+IF(J$3<=$O$2,$D60,$D60-($D60-$I$49)*MIN(J$3-$O$2,$Q$2)/$Q$2)) -> 3247.8405 | K60: =J60*(1+IF(K$3<=$O$2,$D60,$D60-($D60-$I$49)*MIN(K$3-$O$2,$Q$2)/$Q$2)) -> 3350.5905 | L60: =K60*(1+IF(L$3<=$O$2,$D60,$D60-($D60-$I$49)*MIN(L$3-$O$2,$Q$2)/$Q$2)) -> 3441.6961 | M60: =L60*(1+IF(M$3<=$O$2,$D60,$D60-($D60-$I$49)*MIN(M$3-$O$2,$Q$2)/$Q$2)) -> 3519.9791 | N60: =M60*(1+IF(N$3<=$O$2,$D60,$D60-($D60-$I$49)*MIN(N$3-$O$2,$Q$2)/$Q$2)) -> 3584.3948 | O60: =SUMPRODUCT(E60:N60,1/(1+$F$49)^$E$3:$N$3)*$E$2 -> 4071.6362 | P60: =N60*$E$2*(1+$I$49)/($F$49-$I$49)/(1+$F$49)^$N$3 -> 4931.868 | Q60: =O60+P60 -> 9003.5041 | R60: =Q60-$G$2+$I$2 -> 7627.3041 | S60: =R60/$K$2 -> 203.34055 | T60: =S60-$M$2 -> -1.1382531
A61: 11 | B61: =IF(T60>0,B60,D60) -> 0.040527344 | C61: =IF(T60>0,D60,C60) -> 0.041992188 | D61: =(B61+C61)/2 -> 0.041259766 | E61: =$C$2*(1+IF(E$3<=$O$2,$D61,$D61-($D61-$I$49)*MIN(E$3-$O$2,$Q$2)/$Q$2)) -> 2676.0376 | F61: =E61*(1+IF(F$3<=$O$2,$D61,$D61-($D61-$I$49)*MIN(F$3-$O$2,$Q$2)/$Q$2)) -> 2786.4503 | G61: =F61*(1+IF(G$3<=$O$2,$D61,$D61-($D61-$I$49)*MIN(G$3-$O$2,$Q$2)/$Q$2)) -> 2901.4186 | H61: =G61*(1+IF(H$3<=$O$2,$D61,$D61-($D61-$I$49)*MIN(H$3-$O$2,$Q$2)/$Q$2)) -> 3021.1304 | I61: =H61*(1+IF(I$3<=$O$2,$D61,$D61-($D61-$I$49)*MIN(I$3-$O$2,$Q$2)/$Q$2)) -> 3145.7816 | J61: =I61*(1+IF(J$3<=$O$2,$D61,$D61-($D61-$I$49)*MIN(J$3-$O$2,$Q$2)/$Q$2)) -> 3261.1305 | K61: =J61*(1+IF(K$3<=$O$2,$D61,$D61-($D61-$I$49)*MIN(K$3-$O$2,$Q$2)/$Q$2)) -> 3365.734 | L61: =K61*(1+IF(L$3<=$O$2,$D61,$D61-($D61-$I$49)*MIN(L$3-$O$2,$Q$2)/$Q$2)) -> 3458.2376 | M61: =L61*(1+IF(M$3<=$O$2,$D61,$D61-($D61-$I$49)*MIN(M$3-$O$2,$Q$2)/$Q$2)) -> 3537.4034 | N61: =M61*(1+IF(N$3<=$O$2,$D61,$D61-($D61-$I$49)*MIN(N$3-$O$2,$Q$2)/$Q$2)) -> 3602.1379 | O61: =SUMPRODUCT(E61:N61,1/(1+$F$49)^$E$3:$N$3)*$E$2 -> 4084.6539 | P61: =N61*$E$2*(1+$I$49)/($F$49-$I$49)/(1+$F$49)^$N$3 -> 4956.2812 | Q61: =O61+P61 -> 9040.935 | R61: =Q61-$G$2+$I$2 -> 7664.735 | S61: =R61/$K$2 -> 204.33844 | T61: =S61-$M$2 -> -0.14036139
A62: 12 | B62: =IF(T61>0,B61,D61) -> 0.041259766 | C62: =IF(T61>0,D61,C61) -> 0.041992188 | D62: =(B62+C62)/2 -> 0.041625977 | E62: =$C$2*(1+IF(E$3<=$O$2,$D62,$D62-($D62-$I$49)*MIN(E$3-$O$2,$Q$2)/$Q$2)) -> 2676.9788 | F62: =E62*(1+IF(F$3<=$O$2,$D62,$D62-($D62-$I$49)*MIN(F$3-$O$2,$Q$2)/$Q$2)) -> 2788.4106 | G62: =F62*(1+IF(G$3<=$O$2,$D62,$D62-($D62-$I$49)*MIN(G$3-$O$2,$Q$2)/$Q$2)) -> 2904.4809 | H62: =G62*(1+IF(H$3<=$O$2,$D62,$D62-($D62-$I$49)*MIN(H$3-$O$2,$Q$2)/$Q$2)) -> 3025.3828 | I62: =H62*(1+IF(I$3<=$O$2,$D62,$D62-($D62-$I$49)*MIN(I$3-$O$2,$Q$2)/$Q$2)) -> 3151.3173 | J62: =I62*(1+IF(J$3<=$O$2,$D62,$D62-($D62-$I$49)*MIN(J$3-$O$2,$Q$2)/$Q$2)) -> 3267.7924 | K62: =J62*(1+IF(K$3<=$O$2,$D62,$D62-($D62-$I$49)*MIN(K$3-$O$2,$Q$2)/$Q$2)) -> 3373.3277 | L62: =K62*(1+IF(L$3<=$O$2,$D62,$D62-($D62-$I$49)*MIN(L$3-$O$2,$Q$2)/$Q$2)) -> 3466.5341 | M62: =L62*(1+IF(M$3<=$O$2,$D62,$D62-($D62-$I$49)*MIN(M$3-$O$2,$Q$2)/$Q$2)) -> 3546.1437 | N62: =M62*(1+IF(N$3<=$O$2,$D62,$D62-($D62-$I$49)*MIN(N$3-$O$2,$Q$2)/$Q$2)) -> 3611.0381 | O62: =SUMPRODUCT(E62:N62,1/(1+$F$49)^$E$3:$N$3)*$E$2 -> 4091.1785 | P62: =N62*$E$2*(1+$I$49)/($F$49-$I$49)/(1+$F$49)^$N$3 -> 4968.5273 | Q62: =O62+P62 -> 9059.7058 | R62: =Q62-$G$2+$I$2 -> 7683.5058 | S62: =R62/$K$2 -> 204.83886 | T62: =S62-$M$2 -> 0.360059
A63: 13 | B63: =IF(T62>0,B62,D62) -> 0.041259766 | C63: =IF(T62>0,D62,C62) -> 0.041625977 | D63: =(B63+C63)/2 -> 0.041442871 | E63: =$C$2*(1+IF(E$3<=$O$2,$D63,$D63-($D63-$I$49)*MIN(E$3-$O$2,$Q$2)/$Q$2)) -> 2676.5082 | F63: =E63*(1+IF(F$3<=$O$2,$D63,$D63-($D63-$I$49)*MIN(F$3-$O$2,$Q$2)/$Q$2)) -> 2787.4304 | G63: =F63*(1+IF(G$3<=$O$2,$D63,$D63-($D63-$I$49)*MIN(G$3-$O$2,$Q$2)/$Q$2)) -> 2902.9495 | H63: =G63*(1+IF(H$3<=$O$2,$D63,$D63-($D63-$I$49)*MIN(H$3-$O$2,$Q$2)/$Q$2)) -> 3023.256 | I63: =H63*(1+IF(I$3<=$O$2,$D63,$D63-($D63-$I$49)*MIN(I$3-$O$2,$Q$2)/$Q$2)) -> 3148.5485 | J63: =I63*(1+IF(J$3<=$O$2,$D63,$D63-($D63-$I$49)*MIN(J$3-$O$2,$Q$2)/$Q$2)) -> 3264.46 | K63: =J63*(1+IF(K$3<=$O$2,$D63,$D63-($D63-$I$49)*MIN(K$3-$O$2,$Q$2)/$Q$2)) -> 3369.5291 | L63: =K63*(1+IF(L$3<=$O$2,$D63,$D63-($D63-$I$49)*MIN(L$3-$O$2,$Q$2)/$Q$2)) -> 3462.3837 | M63: =L63*(1+IF(M$3<=$O$2,$D63,$D63-($D63-$I$49)*MIN(M$3-$O$2,$Q$2)/$Q$2)) -> 3541.7712 | N63: =M63*(1+IF(N$3<=$O$2,$D63,$D63-($D63-$I$49)*MIN(N$3-$O$2,$Q$2)/$Q$2)) -> 3606.5856 | O63: =SUMPRODUCT(E63:N63,1/(1+$F$49)^$E$3:$N$3)*$E$2 -> 4087.9148 | P63: =N63*$E$2*(1+$I$49)/($F$49-$I$49)/(1+$F$49)^$N$3 -> 4962.401 | Q63: =O63+P63 -> 9050.3158 | R63: =Q63-$G$2+$I$2 -> 7674.1158 | S63: =R63/$K$2 -> 204.58853 | T63: =S63-$M$2 -> 0.10972574
... A74: 24 | B74: =IF(T73>0,B73,D73) -> 0.041362405 | C74: =IF(T73>0,D73,C73) -> 0.041362584 | D74: =(B74+C74)/2 -> 0.041362494 | E74: =$C$2*(1+IF(E$3<=$O$2,$D74,$D74-($D74-$I$49)*MIN(E$3-$O$2,$Q$2)/$Q$2)) -> 2676.3016 | F74: =E74*(1+IF(F$3<=$O$2,$D74,$D74-($D74-$I$49)*MIN(F$3-$O$2,$Q$2)/$Q$2)) -> 2787.0001 | G74: =F74*(1+IF(G$3<=$O$2,$D74,$D74-($D74-$I$49)*MIN(G$3-$O$2,$Q$2)/$Q$2)) -> 2902.2774 | H74: =G74*(1+IF(H$3<=$O$2,$D74,$D74-($D74-$I$49)*MIN(H$3-$O$2,$Q$2)/$Q$2)) -> 3022.3228 | I74: =H74*(1+IF(I$3<=$O$2,$D74,$D74-($D74-$I$49)*MIN(I$3-$O$2,$Q$2)/$Q$2)) -> 3147.3336 | J74: =I74*(1+IF(J$3<=$O$2,$D74,$D74-($D74-$I$49)*MIN(J$3-$O$2,$Q$2)/$Q$2)) -> 3262.9981 | K74: =J74*(1+IF(K$3<=$O$2,$D74,$D74-($D74-$I$49)*MIN(K$3-$O$2,$Q$2)/$Q$2)) -> 3367.8627 | L74: =K74*(1+IF(L$3<=$O$2,$D74,$D74-($D74-$I$49)*MIN(L$3-$O$2,$Q$2)/$Q$2)) -> 3460.5631 | M74: =L74*(1+IF(M$3<=$O$2,$D74,$D74-($D74-$I$49)*MIN(M$3-$O$2,$Q$2)/$Q$2)) -> 3539.8533 | N74: =M74*(1+IF(N$3<=$O$2,$D74,$D74-($D74-$I$49)*MIN(N$3-$O$2,$Q$2)/$Q$2)) -> 3604.6326 | O74: =SUMPRODUCT(E74:N74,1/(1+$F$49)^$E$3:$N$3)*$E$2 -> 4086.4831 | P74: =N74*$E$2*(1+$I$49)/($F$49-$I$49)/(1+$F$49)^$N$3 -> 4959.7138 | Q74: =O74+P74 -> 9046.1968 | R74: =Q74-$G$2+$I$2 -> 7669.9968 | S74: =R74/$K$2 -> 204.47872 | T74: =S74-$M$2 -> -8.4008877e-05
A76: Grid block 3: row 1, column 2 of table A (24 steps) | E76: WACC | F76: =Sensitivity!$B$10 -> 0.084183338 | G76: Terminal growth | I76: =Sensitivity!$D$9 -> 0.0233
A77: Step | B77: Low | C77: High | D77: Mid | E77: Rev Y1 | F77: Rev Y2 | G77: Rev Y3 | H77: Rev Y4 | I77: Rev Y5 | J77: Rev Y6 | K77: Rev Y7 | L77: Rev Y8 | M77: Rev Y9 | N77: Rev Y10 | O77: PV of FCF | P77: PV of TV | Q77: EV | R77: Equity | S77: Per share | T77: Value - price
A78: 1 | B78: -0.5 | C78: 1 | D78: =(B78+C78)/2 -> 0.25 | E78: =$C$2*(1+IF(E$3<=$O$2,$D78,$D78-($D78-$I$76)*MIN(E$3-$O$2,$Q$2)/$Q$2)) -> 3212.5 | F78: =E78*(1+IF(F$3<=$O$2,$D78,$D78-($D78-$I$76)*MIN(F$3-$O$2,$Q$2)/$Q$2)) -> 4015.625 | G78: =F78*(1+IF(G$3<=$O$2,$D78,$D78-($D78-$I$76)*MIN(G$3-$O$2,$Q$2)/$Q$2)) -> 5019.5312 | H78: =G78*(1+IF(H$3<=$O$2,$D78,$D78-($D78-$I$76)*MIN(H$3-$O$2,$Q$2)/$Q$2)) -> 6274.4141 | I78: =H78*(1+IF(I$3<=$O$2,$D78,$D78-($D78-$I$76)*MIN(I$3-$O$2,$Q$2)/$Q$2)) -> 7843.0176 | J78: =I78*(1+IF(J$3<=$O$2,$D78,$D78-($D78-$I$76)*MIN(J$3-$O$2,$Q$2)/$Q$2)) -> 9448.1696 | K78: =J78*(1+IF(K$3<=$O$2,$D78,$D78-($D78-$I$76)*MIN(K$3-$O$2,$Q$2)/$Q$2)) -> 10953.452 | L78: =K78*(1+IF(L$3<=$O$2,$D78,$D78-($D78-$I$76)*MIN(L$3-$O$2,$Q$2)/$Q$2)) -> 12201.926 | M78: =L78*(1+IF(M$3<=$O$2,$D78,$D78-($D78-$I$76)*MIN(M$3-$O$2,$Q$2)/$Q$2)) -> 13039.467 | N78: =M78*(1+IF(N$3<=$O$2,$D78,$D78-($D78-$I$76)*MIN(N$3-$O$2,$Q$2)/$Q$2)) -> 13343.286 | O78: =SUMPRODUCT(E78:N78,1/(1+$F$76)^$E$3:$N$3)*$E$2 -> 10142.23 | P78: =N78*$E$2*(1+$I$76)/($F$76-$I$76)/(1+$F$76)^$N$3 -> 19964.7 | Q78: =O78+P78 -> 30106.929 | R78: =Q78-$G$2+$I$2 -> 28730.729 | S78: =R78/$K$2 -> 765.94853 | T78: =S78-$M$2 -> 561.46972
A79: 2 | B79: =IF(T78>0,B78,D78) -> -0.5 | C79: =IF(T78>0,D78,C78) -> 0.25 | D79: =(B79+C79)/2 -> -0.125 | E79: =$C$2*(1+IF(E$3<=$O$2,$D79,$D79-($D79-$I$76)*MIN(E$3-$O$2,$Q$2)/$Q$2)) -> 2248.75 | F79: =E79*(1+IF(F$3<=$O$2,$D79,$D79-($D79-$I$76)*MIN(F$3-$O$2,$Q$2)/$Q$2)) -> 1967.6562 | G79: =F79*(1+IF(G$3<=$O$2,$D79,$D79-($D79-$I$76)*MIN(G$3-$O$2,$Q$2)/$Q$2)) -> 1721.6992 | H79: =G79*(1+IF(H$3<=$O$2,$D79,$D79-($D79-$I$76)*MIN(H$3-$O$2,$Q$2)/$Q$2)) -> 1506.4868 | I79: =H79*(1+IF(I$3<=$O$2,$D79,$D79-($D79-$I$76)*MIN(I$3-$O$2,$Q$2)/$Q$2)) -> 1318.176 | J79: =I79*(1+IF(J$3<=$O$2,$D79,$D79-($D79-$I$76)*MIN(J$3-$O$2,$Q$2)/$Q$2)) -> 1192.5011 | K79: =J79*(1+IF(K$3<=$O$2,$D79,$D79-($D79-$I$76)*MIN(K$3-$O$2,$Q$2)/$Q$2)) -> 1114.1776 | L79: =K79*(1+IF(L$3<=$O$2,$D79,$D79-($D79-$I$76)*MIN(L$3-$O$2,$Q$2)/$Q$2)) -> 1074.0449 | M79: =L79*(1+IF(M$3<=$O$2,$D79,$D79-($D79-$I$76)*MIN(M$3-$O$2,$Q$2)/$Q$2)) -> 1067.214 | N79: =M79*(1+IF(N$3<=$O$2,$D79,$D79-($D79-$I$76)*MIN(N$3-$O$2,$Q$2)/$Q$2)) -> 1092.0801 | O79: =SUMPRODUCT(E79:N79,1/(1+$F$76)^$E$3:$N$3)*$E$2 -> 1997.9118 | P79: =N79*$E$2*(1+$I$76)/($F$76-$I$76)/(1+$F$76)^$N$3 -> 1634.0091 | Q79: =O79+P79 -> 3631.9209 | R79: =Q79-$G$2+$I$2 -> 2255.7209 | S79: =R79/$K$2 -> 60.13652 | T79: =S79-$M$2 -> -144.34229
...

Sheet DCF
B2: Morningstar (MORN): discounted cash flow
B3: Panel A runs the model at the solved growth rate, so it should land on the price. Panel B runs it at your view.
B5: A. At the solved (implied) growth rate
B6: Year | C6: 1 | D6: 2 | E6: 3 | F6: 4 | G6: 5 | H6: 6 | I6: 7 | J6: 8 | K6: 9 | L6: 10
B7: Revenue growth | C7: =IF(C$6<=Inputs!$C$46,Solver!$W$7,Solver!$W$7-(Solver!$W$7-Inputs!$C$37)*MIN(C$6-Inputs!$C$46,Inputs!$C$47)/Inputs!$C$47) -> 0.049811827 | D7: =IF(D$6<=Inputs!$C$46,Solver!$W$7,Solver!$W$7-(Solver!$W$7-Inputs!$C$37)*MIN(D$6-Inputs!$C$46,Inputs!$C$47)/Inputs!$C$47) -> 0.049811827 | E7: =IF(E$6<=Inputs!$C$46,Solver!$W$7,Solver!$W$7-(Solver!$W$7-Inputs!$C$37)*MIN(E$6-Inputs!$C$46,Inputs!$C$47)/Inputs!$C$47) -> 0.049811827 | F7: =IF(F$6<=Inputs!$C$46,Solver!$W$7,Solver!$W$7-(Solver!$W$7-Inputs!$C$37)*MIN(F$6-Inputs!$C$46,Inputs!$C$47)/Inputs!$C$47) -> 0.049811827 | G7: =IF(G$6<=Inputs!$C$46,Solver!$W$7,Solver!$W$7-(Solver!$W$7-Inputs!$C$37)*MIN(G$6-Inputs!$C$46,Inputs!$C$47)/Inputs!$C$47) -> 0.049811827 | H7: =IF(H$6<=Inputs!$C$46,Solver!$W$7,Solver!$W$7-(Solver!$W$7-Inputs!$C$37)*MIN(H$6-Inputs!$C$46,Inputs!$C$47)/Inputs!$C$47) -> 0.045509461 | I7: =IF(I$6<=Inputs!$C$46,Solver!$W$7,Solver!$W$7-(Solver!$W$7-Inputs!$C$37)*MIN(I$6-Inputs!$C$46,Inputs!$C$47)/Inputs!$C$47) -> 0.041207096 | J7: =IF(J$6<=Inputs!$C$46,Solver!$W$7,Solver!$W$7-(Solver!$W$7-Inputs!$C$37)*MIN(J$6-Inputs!$C$46,Inputs!$C$47)/Inputs!$C$47) -> 0.036904731 | ... L7: =IF(L$6<=Inputs!$C$46,Solver!$W$7,Solver!$W$7-(Solver!$W$7-Inputs!$C$37)*MIN(L$6-Inputs!$C$46,Inputs!$C$47)/Inputs!$C$47) -> 0.0283
B8: Revenue ($mm) | C8: =Inputs!$C$12*(1+C7) -> 2698.0164 | D8: =C8*(1+D7) -> 2832.4095 | E8: =D8*(1+E7) -> 2973.497 | F8: =E8*(1+F7) -> 3121.6123 | G8: =F8*(1+G7) -> 3277.1055 | H8: =G8*(1+H7) -> 3426.2448 | I8: =H8*(1+I7) -> 3567.4304 | J8: =I8*(1+J7) -> 3699.0855 | K8: =J8*(1+K7) -> 3819.6844 | L8: =K8*(1+L7) -> 3927.7815
B9: Unlevered free cash flow ($mm) | C9: =C8*Inputs!$C$23 -> 538.97339 | D9: =D8*Inputs!$C$23 -> 565.82064 | E9: =E8*Inputs!$C$23 -> 594.0052 | F9: =F8*Inputs!$C$23 -> 623.59368 | G9: =G8*Inputs!$C$23 -> 654.65602 | H9: =H8*Inputs!$C$23 -> 684.44907 | I9: =I8*Inputs!$C$23 -> 712.65323 | J9: =J8*Inputs!$C$23 -> 738.9535 | ... L9: =L8*Inputs!$C$23 -> 784.63931
B10: Discount factor | C10: =1/(1+WACC!$C$34)^C$6 -> 0.91392362 | D10: =1/(1+WACC!$C$34)^D$6 -> 0.83525639 | E10: =1/(1+WACC!$C$34)^E$6 -> 0.76336054 | F10: =1/(1+WACC!$C$34)^F$6 -> 0.69765323 | G10: =1/(1+WACC!$C$34)^G$6 -> 0.63760177 | H10: =1/(1+WACC!$C$34)^H$6 -> 0.58271932 | I10: =1/(1+WACC!$C$34)^I$6 -> 0.53256095 | J10: =1/(1+WACC!$C$34)^J$6 -> 0.48672004 | ... L10: =1/(1+WACC!$C$34)^L$6 -> 0.40653602
B11: Present value ($mm) | C11: =C9*C10 -> 492.58051 | D11: =D9*D10 -> 472.60531 | E11: =E9*E10 -> 453.44013 | F11: =F9*F10 -> 435.05215 | G11: =G9*G10 -> 417.40984 | H11: =H9*H10 -> 398.8417 | I11: =I9*I10 -> 379.53128 | J11: =J9*J10 -> 359.66347 | ... L11: =L9*L10 -> 318.98414
B13: Sum of present values, years 1 to 10 | C13: =SUM(C11:L11) -> 4067.53
B14: Terminal value at year 10 | C14: =L9*(1+Inputs!$C$37)/(WACC!$C$34-Inputs!$C$37) -> 12246.565
B15: Present value of terminal value | C15: =C14*L10 -> 4978.67
B16: Enterprise value | C16: =C13+C15 -> 9046.2
B17: Less: debt | C17: =-Inputs!$C$27 -> -1900
B18: Plus: cash | C18: =Inputs!$C$28 -> 523.8
B19: Equity value | C19: =SUM(C16:C18) -> 7670
B20: Shares (mm) | C20: =Inputs!$C$7 -> 37.51
B21: Value per share ($) | C21: =C19/C20 -> 204.47881
B22: Price at the lock ($) | C22: =Inputs!$C$6 -> 204.47881
B23: Value / price - 1 | C23: =C21/C22-1 -> -8.2680529e-12
B24: Terminal value share of enterprise value | C24: =C15/C16 -> 0.55036037
B25: B. At your view of growth (Inputs tab, yellow cell)
B26: Year | C26: 1 | D26: 2 | E26: 3 | F26: 4 | G26: 5 | H26: 6 | I26: 7 | J26: 8 | K26: 9 | L26: 10
B27: Revenue growth | C27: =IF(C$26<=Inputs!$C$46,Inputs!$C$45,Inputs!$C$45-(Inputs!$C$45-Inputs!$C$37)*MIN(C$26-Inputs!$C$46,Inputs!$C$47)/Inputs!$C$47) -> 0.082073834 | D27: =IF(D$26<=Inputs!$C$46,Inputs!$C$45,Inputs!$C$45-(Inputs!$C$45-Inputs!$C$37)*MIN(D$26-Inputs!$C$46,Inputs!$C$47)/Inputs!$C$47) -> 0.082073834 | E27: =IF(E$26<=Inputs!$C$46,Inputs!$C$45,Inputs!$C$45-(Inputs!$C$45-Inputs!$C$37)*MIN(E$26-Inputs!$C$46,Inputs!$C$47)/Inputs!$C$47) -> 0.082073834 | F27: =IF(F$26<=Inputs!$C$46,Inputs!$C$45,Inputs!$C$45-(Inputs!$C$45-Inputs!$C$37)*MIN(F$26-Inputs!$C$46,Inputs!$C$47)/Inputs!$C$47) -> 0.082073834 | G27: =IF(G$26<=Inputs!$C$46,Inputs!$C$45,Inputs!$C$45-(Inputs!$C$45-Inputs!$C$37)*MIN(G$26-Inputs!$C$46,Inputs!$C$47)/Inputs!$C$47) -> 0.082073834 | H27: =IF(H$26<=Inputs!$C$46,Inputs!$C$45,Inputs!$C$45-(Inputs!$C$45-Inputs!$C$37)*MIN(H$26-Inputs!$C$46,Inputs!$C$47)/Inputs!$C$47) -> 0.071319067 | I27: =IF(I$26<=Inputs!$C$46,Inputs!$C$45,Inputs!$C$45-(Inputs!$C$45-Inputs!$C$37)*MIN(I$26-Inputs!$C$46,Inputs!$C$47)/Inputs!$C$47) -> 0.0605643 | J27: =IF(J$26<=Inputs!$C$46,Inputs!$C$45,Inputs!$C$45-(Inputs!$C$45-Inputs!$C$37)*MIN(J$26-Inputs!$C$46,Inputs!$C$47)/Inputs!$C$47) -> 0.049809533 | ... L27: =IF(L$26<=Inputs!$C$46,Inputs!$C$45,Inputs!$C$45-(Inputs!$C$45-Inputs!$C$37)*MIN(L$26-Inputs!$C$46,Inputs!$C$47)/Inputs!$C$47) -> 0.0283
B28: Revenue ($mm) | C28: =Inputs!$C$12*(1+C27) -> 2780.9298 | D28: =C28*(1+D27) -> 3009.1713 | E28: =D28*(1+E27) -> 3256.1455 | F28: =E28*(1+F27) -> 3523.3899 | G28: =F28*(1+G27) -> 3812.568 | H28: =G28*(1+H27) -> 4084.4768 | I28: =H28*(1+I27) -> 4331.8503 | J28: =I28*(1+J27) -> 4547.6177 | K28: =J28*(1+K27) -> 4725.2239 | L28: =K28*(1+L27) -> 4858.9477
B29: Unlevered free cash flow ($mm) | C29: =C28*Inputs!$C$23 -> 555.53671 | D29: =D28*Inputs!$C$23 -> 601.13173 | E29: =E28*Inputs!$C$23 -> 650.46892 | F29: =F28*Inputs!$C$23 -> 703.8554 | G29: =G28*Inputs!$C$23 -> 761.62351 | H29: =H28*Inputs!$C$23 -> 815.94179 | I29: =I28*Inputs!$C$23 -> 865.35873 | J29: =J28*Inputs!$C$23 -> 908.46184 | ... L29: =L28*Inputs!$C$23 -> 970.65516
B30: Discount factor | C30: =1/(1+WACC!$C$34)^C$26 -> 0.91392362 | D30: =1/(1+WACC!$C$34)^D$26 -> 0.83525639 | E30: =1/(1+WACC!$C$34)^E$26 -> 0.76336054 | F30: =1/(1+WACC!$C$34)^F$26 -> 0.69765323 | G30: =1/(1+WACC!$C$34)^G$26 -> 0.63760177 | H30: =1/(1+WACC!$C$34)^H$26 -> 0.58271932 | I30: =1/(1+WACC!$C$34)^I$26 -> 0.53256095 | J30: =1/(1+WACC!$C$34)^J$26 -> 0.48672004 | ... L30: =1/(1+WACC!$C$34)^L$26 -> 0.40653602
B31: Present value ($mm) | C31: =C29*C30 -> 507.71812 | D31: =D29*D30 -> 502.09912 | E31: =E29*E30 -> 496.54231 | F31: =F29*F30 -> 491.04699 | G31: =G29*G30 -> 485.6125 | H31: =H29*H30 -> 475.46504 | I31: =I29*I30 -> 460.85627 | J31: =J29*J30 -> 442.16658 | ... L31: =L29*L30 -> 394.60628
B33: Sum of present values, years 1 to 10 | C33: =SUM(C31:L31) -> 4676.002
B34: Terminal value at year 10 | C34: =L29*(1+Inputs!$C$37)/(WACC!$C$34-Inputs!$C$37) -> 15149.881
B35: Present value of terminal value | C35: =C34*L30 -> 6158.9722
B36: Enterprise value | C36: =C33+C35 -> 10834.974
B37: Less: debt | C37: =-Inputs!$C$27 -> -1900
B38: Plus: cash | C38: =Inputs!$C$28 -> 523.8
B39: Equity value | C39: =SUM(C36:C38) -> 9458.7741
B40: Shares (mm) | C40: =Inputs!$C$7 -> 37.51
B41: Value per share ($) | C41: =C39/C40 -> 252.16673
B42: Price at the lock ($) | C42: =Inputs!$C$6 -> 204.47881
B43: Value / price - 1 | C43: =C41/C42-1 -> 0.23321697
B44: Terminal value share of enterprise value | C44: =C35/C36 -> 0.56843441

Sheet Sensitivity
B2: Morningstar (MORN): sensitivity
B3: Table A re-solves implied growth for each pair of inputs (Solver tab, blocks 2 to 26). Table B values the stock at a growth view.
B5: WACC step | C5: 0.005 | D5: Terminal-growth step | F5: 0.005
B6: Growth-view step | C6: 0.02
B8: A. Implied 5-year growth: WACC (rows) by terminal growth (columns)
C9: =Inputs!$C$37+(0-2)*$F$5 -> 0.0183 | D9: =Inputs!$C$37+(1-2)*$F$5 -> 0.0233 | E9: =Inputs!$C$37+(2-2)*$F$5 -> 0.0283 | F9: =Inputs!$C$37+(3-2)*$F$5 -> 0.0333 | G9: =Inputs!$C$37+(4-2)*$F$5 -> 0.0383
B10: =WACC!$C$34+(0-2)*$C$5 -> 0.084183338 | C10: =Solver!$D$74 -> 0.041362494 | D10: =Solver!$D$101 -> 0.031519502 | E10: =Solver!$D$128 -> 0.020840019 | F10: =Solver!$D$155 -> 0.0091736615 | G10: =Solver!$D$182 -> -0.003674835 | I10: Centre cell = the base case. Each step changes one input by the step size above.
B11: =WACC!$C$34+(1-2)*$C$5 -> 0.089183338 | C11: =Solver!$D$209 -> 0.0547553 | D11: =Solver!$D$236 -> 0.045588583 | E11: =Solver!$D$263 -> 0.035700351 | F11: =Solver!$D$290 -> 0.024972051 | G11: =Solver!$D$317 -> 0.013252765
B12: =WACC!$C$34+(2-2)*$C$5 -> 0.094183338 | C12: =Solver!$D$344 -> 0.067600578 | D12: =Solver!$D$371 -> 0.059020728 | E12: =Solver!$D$398 -> 0.04981181 | F12: =Solver!$D$425 -> 0.039878517 | G12: =Solver!$D$452 -> 0.02910158
B13: =WACC!$C$34+(3-2)*$C$5 -> 0.099183338 | C13: =Solver!$D$479 -> 0.079968423 | D13: =Solver!$D$506 -> 0.071902663 | E13: =Solver!$D$533 -> 0.063283473 | F13: =Solver!$D$560 -> 0.054032534 | G13: =Solver!$D$587 -> 0.04405418
B14: =WACC!$C$34+(4-2)*$C$5 -> 0.10418334 | C14: =Solver!$D$614 -> 0.091916591 | D14: =Solver!$D$641 -> 0.084305018 | E14: =Solver!$D$668 -> 0.076202065 | F14: =Solver!$D$695 -> 0.067543536 | G14: =Solver!$D$722 -> 0.058250576
B17: B. Value per share: WACC (rows) by your growth view (columns)
C18: =Inputs!$C$45+(0-2)*$C$6 -> 0.042073834 | D18: =Inputs!$C$45+(1-2)*$C$6 -> 0.062073834 | E18: =Inputs!$C$45+(2-2)*$C$6 -> 0.082073834 | F18: =Inputs!$C$45+(3-2)*$C$6 -> 0.10207383 | G18: =Inputs!$C$45+(4-2)*$C$6 -> 0.12207383
