Workbook

Sheet Cover
B2: Priced In: Intercontinental Exchange (ICE)
B3: Reverse DCF, model v1.0. Inputs as of the Oct 13, 2026 close; model locked Oct 14, 2026 (commit 0735af0).
B4: Exchanges | US | reports in USD
B6: The question
B7: What revenue growth over the next five years does today's price imply, and is that more or less than the company has delivered and analysts expect?
B9: Answer
B10: Price at the lock ($) | C10: =Inputs!$C$6 -> 155.80969
B11: Implied 5-year revenue growth | C11: =Solver!$W$7 -> 0.022919701
B12: Anchor (history and analysts) | C12: =Inputs!$C$43 -> 0.0812
B13: Gap (implied - anchor) | C13: =C11-C12 -> -0.058280299
B14: Verdict | C14: =IF(C13>=Inputs!$C$44,"Expectations too high",IF(C13<=-Inputs!$C$44,"Expectations too low","About right")) -> Expectations too low
B15: WACC | C15: =WACC!$C$37 -> 0.077017203
B16: Terminal growth | C16: =Inputs!$C$37 -> 0.0283
B17: Unlevered free-cash-flow margin | C17: =Inputs!$C$23 -> 0.49526515
B18: Your view of growth (Inputs, yellow) | C18: =Inputs!$C$45 -> 0.0812
B19: Value per share at your view ($) | C19: =DCF!$C$41 -> 233.35771
B20: Upside or downside at your view | C20: =DCF!$C$43 -> 0.49770987
B22: Fit flag: History not comparable
B23: Black Knight joined in September 2023, so past growth includes an acquisition.
B25: How to use this file
B26: 1. Change any blue cell on Inputs, History or WACC; everything recalculates, including the solver.
B27: 2. The Solver tab finds implied growth by bisection with formulas, so you never need Goal Seek. 40 steps narrow a 150-point range to well under 0.0001%.
B28: 3. Type your own growth view in the yellow cell on Inputs; DCF panel B and this page show what the stock is worth if you're right.
B29: 4. Check confirms this workbook matches the Python pipeline that runs the site.
B31: Colour key
B32: Typed input with a source | C32: 1234
B33: Formula | C33: =C32*2 -> 2468
B34: Link to another tab | C34: =Inputs!$C$12 -> 10560
B35: Your view (edit this one) | C35: =Inputs!$C$45 -> 0.0812
B37: Live site
B38: https://claude.ai/artifact/DS3n4CgaKxaSLzkXDsBKuK
B40: Built by Rohan Jayapalan. Not investment advice.

Sheet Inputs
B2: Intercontinental Exchange (ICE): inputs
B3: Blue cells are typed inputs with a source. Black cells are formulas. Change a blue cell and every tab recalculates.
B5: Market and price
B6: Price per share at the lock ($) | C6: 155.80969 | E6: Market cap divided by shares from Stock Analysis at the Oct 13, 2026 close.
B7: Diluted shares outstanding (mm) | C7: 561.39 | E7: Stock Analysis statistics page, Oct 13, 2026.
B8: Market value of equity ($mm) | C8: =C6*C7 -> 87470 | E8: Price x shares.
B10: Trailing 12 months
B11: Revenue, reported ($mm) | C11: 10560 | E11: Stock Analysis income statement, trailing 12 months.
B12: Revenue used in the model ($mm) | C12: =C11 -> 10560 | E12: Same as reported.
B13: Free cash flow, reported (cash from operations - capex) ($mm) | C13: 5080 | E13: Stock Analysis cash flow statement, trailing 12 months.
B14: Free cash flow before adjustments ($mm) | C14: =C13 -> 5080 | E14: Same as reported.
B15: Less: adjustments ($mm) | C15: 0 | E15: None for this company.
B16: Free cash flow used ($mm) | C16: =C14-C15 -> 5080
B17: Operating income ($mm) | C17: 5530 | E17: Stock Analysis, trailing 12 months.
B18: Pretax income ($mm) | C18: 5330 | E18: Stock Analysis, trailing 12 months.
B19: Interest proxy: operating income - pretax, floored at zero ($mm) | C19: =MAX(0,C17-C18) -> 200 | E19: Net interest and other non-operating costs. Adding it back (after tax) turns levered FCF into unlevered FCF.
B20: Tax rate | C20: 0.25 | E20: Statutory blend: 25% US (21% federal plus state), 26.5% Canada (federal plus Ontario).
B21: After-tax interest added back ($mm) | C21: =C19*(1-C20) -> 150
B22: Unlevered free cash flow ($mm) | C22: =C16+C21 -> 5230
B23: Unlevered free-cash-flow margin | C23: =C22/C12 -> 0.49526515 | E23: Held flat for all 10 years in the model.
B24: EBITDA ($mm) | C24: 6710 | E24: Stock Analysis, trailing 12 months.
B26: Balance sheet
B27: Total debt ($mm) | C27: 20530 | E27: Stock Analysis balance sheet, latest quarter.
B28: Cash and equivalents ($mm) | C28: 1070 | E28: Stock Analysis balance sheet, latest quarter.
B29: Net debt ($mm) | C29: =C27-C28 -> 19460
B31: Rates
B32: 10-year US Treasury yield | C32: 0.0521 | E32: US Treasury daily par yield curve, Oct 13, 2026.
B33: 10-year TIPS real yield | C33: 0.0288 | E33: US Treasury daily real yield curve, Oct 13, 2026.
B34: Breakeven inflation | C34: =C32-C33 -> 0.0233 | E34: Nominal minus real: the market's inflation expectation.
B35: Risk-free rate used | C35: =C32 -> 0.0521
B36: Real growth added to inflation | C36: 0.005 | E36: Half a point of long-run real growth.
B37: Terminal growth | C37: =MIN(C34+C36,C35) -> 0.0283 | E37: Capped at the risk-free rate.
B38: Equity risk premium | C38: 0.0423 | E38: Damodaran implied equity risk premium, start of 2026.
B40: Growth anchor and verdict
B41: Past revenue growth (CAGR) | C41: n/a | E41: Not used: past growth isn't comparable (see Cover).
B42: Analysts' revenue growth forecast | C42: 0.0812 | E42: Analysts' 3-year revenue CAGR forecast (stockanalysis)
B43: Anchor (average of the two) | C43: =AVERAGE(C41:C42) -> 0.0812 | E43: AVERAGE skips the n/a text when history isn't used.
B44: Verdict band (+/-) | C44: 0.03 | E44: Set before any backtest and never changed.
B45: Your view of 5-year revenue growth | C45: 0.0812 | E45: Type your own view. It starts at the anchor. DCF panel B and the Cover show what the stock is worth at your view.
B46: Years at the solved growth rate | C46: 5 | E46: Model v1.0: 5 years at the growth rate, then a straight-line fade.
...

Sheet History
B2: Intercontinental Exchange (ICE): revenue history
B3: Revenue from Stock Analysis income statements; the window is chosen so acquisitions and disposals don't count as growth.
B5: Fiscal year | C5: FY2021 | D5: FY2022 | E5: FY2023 | F5: FY2024 | G5: FY2025 | H5: TTM Jun-26
B6: Revenue ($mm) | C6: 7146 | D6: 7292 | E6: 7988 | F6: 9279 | G6: 9931 | H6: 10558
B7: Growth on the prior year | D7: =D6/C6-1 -> 0.02043101 | E7: =E6/D6-1 -> 0.095447065 | F7: =F6/E6-1 -> 0.16161743 | G7: =G6/F6-1 -> 0.070266192
B8: Source note: net revenue
B10: History window
B11: Not used for this company: Black Knight joined in September 2023, so past growth includes an acquisition.
B15: Free-cash-flow margin history
B16: Fiscal year | C16: 2021 | D16: 2022 | E16: 2023 | F16: 2024 | G16: 2025
B17: (CFO - capex) / revenue | C17: 0.3211 | D17: 0.3455 | E17: 0.3385 | F17: 0.3574 | G17: 0.3393 | I17: SEC XBRL filings (NetCashProvidedByOperatingActivities, PaymentsToAcquirePropertyPlantAndEquipment, revenue tags).
B18: Plus today's interest add-back | C18: =C17+(Inputs!$C$23-Inputs!$C$16/Inputs!$C$12) -> 0.33530455 | D18: =D17+(Inputs!$C$23-Inputs!$C$16/Inputs!$C$12) -> 0.35970455 | E18: =E17+(Inputs!$C$23-Inputs!$C$16/Inputs!$C$12) -> 0.35270455 | F18: =F17+(Inputs!$C$23-Inputs!$C$16/Inputs!$C$12) -> 0.37160455 | G18: =G17+(Inputs!$C$23-Inputs!$C$16/Inputs!$C$12) -> 0.35350455
B19: Range (the margin slider's shaded zone) | C19: =MIN(C18:G18) -> 0.33530455 | D19: =MAX(C18:G18) -> 0.37160455

Sheet WACC
B2: Intercontinental Exchange (ICE): cost of capital
B3: Bottom-up beta: the median unlevered beta of the company's group, relevered for this company's debt.
B5: Peer | C5: Raw beta | D5: Debt ($mm) | E5: Equity ($mm) | F5: Tax rate | G5: Unlevered beta
B6: Intercontinental Exchange (ICE) | C6: 0.93718463 | D6: 20530 | E6: 87470 | F6: 0.25 | G6: =C6/(1+(1-F6)*D6/E6) -> 0.79690417 | H6: Raw betas: 60 monthly returns to Sep 2026 against the S&P 500 (S&P/TSX for TMX); Cboe uses Stock Analysis's 5-year beta. Debt and equity from Stock Analysis, Oct 13, 2026.
B7: CME Group (CME) | C7: 0.23986632 | D7: 3870 | E7: 99970 | F7: 0.25 | G7: =C7/(1+(1-F7)*D7/E7) -> 0.2330986
B8: Nasdaq (NDAQ) | C8: 0.99189493 | D8: 9320 | E8: 52250 | F8: 0.25 | G8: =C8/(1+(1-F8)*D8/E8) -> 0.87485669
B9: Cboe Global Markets (CBOE) | C9: 0.41 | D9: 1580 | E9: 30520 | F9: 0.25 | G9: =C9/(1+(1-F9)*D9/E9) -> 0.39467592
B10: TMX Group (X) | C10: 0.071228248 | D10: 2070 | E10: 15010 | F10: 0.265 | G10: =C10/(1+(1-F10)*D10/E10) -> 0.064672851
B11: Tradeweb (TW) | C11: 0.61179985 | D11: 150.34 | E11: 25740 | F11: 0.25 | G11: =C11/(1+(1-F11)*D11/E11) -> 0.60913153
B12: MarketAxess (MKTX) | C12: 0.79839643 | D12: 178.91 | E12: 5790 | F12: 0.25 | G12: =C12/(1+(1-F12)*D12/E12) -> 0.78031278
B14: Group median unlevered beta | C14: =MEDIAN(G6:G12) -> 0.60913153
B15: Debt ($mm) | C15: =Inputs!$C$27 -> 20530
B16: Market value of equity ($mm) | C16: =Inputs!$C$8 -> 87470
B17: Tax rate | C17: =Inputs!$C$20 -> 0.25
B18: Relevered beta | C18: =WACC!$C$14*(1+(1-WACC!$C$17)*WACC!$C$15/WACC!$C$16) -> 0.71635804 | H18: Hamada: unlevered beta x (1 + (1 - tax) x debt / equity).
B19: Risk-free rate | C19: =Inputs!$C$35 -> 0.0521
B20: Equity risk premium | C20: =Inputs!$C$38 -> 0.0423
B21: Cost of equity | C21: =WACC!$C$19+WACC!$C$18*WACC!$C$20 -> 0.082401945 | H21: CAPM: risk-free + beta x premium.
B23: Debt-to-EBITDA spread table
B24: Debt / EBITDA below | C24: Spread
B25: 1 | C25: 0.01 | H25: Synthetic spread over the risk-free rate by leverage, a simplified version of Damodaran's ratings table; the last row covers anything at 4x or above.
B26: 2 | C26: 0.0125
B27: 3 | C27: 0.016
B28: 4 | C28: 0.02
B29: 99 | C29: 0.0275
B31: Debt / EBITDA | C31: =Inputs!$C$27/Inputs!$C$24 -> 3.0596125
B32: Credit spread | C32: =INDEX(C25:C29,COUNTIF(B25:B29,"<="&WACC!$C$31)+1) -> 0.02 | H32: First row whose limit is above this company's leverage.
B33: Pre-tax cost of debt | C33: =WACC!$C$19+WACC!$C$32 -> 0.0721
B34: After-tax cost of debt | C34: =WACC!$C$33*(1-WACC!$C$17) -> 0.054075
B35: Weight of debt | C35: =WACC!$C$15/(WACC!$C$15+WACC!$C$16) -> 0.19009259 | H35: Market-value weights.
B36: Weight of equity | C36: =1-WACC!$C$35 -> 0.80990741
B37: WACC | C37: =WACC!$C$36*WACC!$C$21+WACC!$C$35*WACC!$C$34 -> 0.077017203

Sheet Solver
A1: Solver: bisection for the growth rate that makes the model equal the price (replaces Goal Seek)
B2: Revenue | C2: =Inputs!$C$12 -> 10560 | D2: Margin | E2: =Inputs!$C$23 -> 0.49526515 | F2: Debt | G2: =Inputs!$C$27 -> 20530 | H2: Cash | I2: =Inputs!$C$28 -> 1070 | J2: Shares | K2: =Inputs!$C$7 -> 561.39 | L2: Price | M2: =Inputs!$C$6 -> 155.80969 | N2: Years | O2: =Inputs!$C$46 -> 5 | P2: Fade | Q2: =Inputs!$C$47 -> 5
D3: Year | E3: 1 | F3: 2 | G3: 3 | H3: 4 | I3: 5 | J3: 6 | K3: 7 | L3: 8 | M3: 9 | N3: 10
A4: Each row tries the midpoint of the current range. If the value per share is above the price, the answer is lower, so the top of the range moves down; otherwise the bottom moves up.
A6: Base case: model WACC and terminal growth (40 steps) | E6: WACC | F6: =WACC!$C$37 -> 0.077017203 | G6: Terminal growth | I6: =Inputs!$C$37 -> 0.0283 | W6: Implied growth
A7: Step | B7: Low | C7: High | D7: Mid | E7: Rev Y1 | F7: Rev Y2 | G7: Rev Y3 | H7: Rev Y4 | I7: Rev Y5 | J7: Rev Y6 | K7: Rev Y7 | L7: Rev Y8 | M7: Rev Y9 | N7: Rev Y10 | O7: PV of FCF | P7: PV of TV | Q7: EV | R7: Equity | S7: Per share | T7: Value - price | W7: =$D$47 -> 0.022919701
A8: 1 | B8: -0.5 | C8: 1 | D8: =(B8+C8)/2 -> 0.25 | E8: =$C$2*(1+IF(E$3<=$O$2,$D8,$D8-($D8-$I$6)*MIN(E$3-$O$2,$Q$2)/$Q$2)) -> 13200 | F8: =E8*(1+IF(F$3<=$O$2,$D8,$D8-($D8-$I$6)*MIN(F$3-$O$2,$Q$2)/$Q$2)) -> 16500 | G8: =F8*(1+IF(G$3<=$O$2,$D8,$D8-($D8-$I$6)*MIN(G$3-$O$2,$Q$2)/$Q$2)) -> 20625 | H8: =G8*(1+IF(H$3<=$O$2,$D8,$D8-($D8-$I$6)*MIN(H$3-$O$2,$Q$2)/$Q$2)) -> 25781.25 | I8: =H8*(1+IF(I$3<=$O$2,$D8,$D8-($D8-$I$6)*MIN(I$3-$O$2,$Q$2)/$Q$2)) -> 32226.562 | J8: =I8*(1+IF(J$3<=$O$2,$D8,$D8-($D8-$I$6)*MIN(J$3-$O$2,$Q$2)/$Q$2)) -> 38854.277 | K8: =J8*(1+IF(K$3<=$O$2,$D8,$D8-($D8-$I$6)*MIN(K$3-$O$2,$Q$2)/$Q$2)) -> 45122.249 | L8: =K8*(1+IF(L$3<=$O$2,$D8,$D8-($D8-$I$6)*MIN(L$3-$O$2,$Q$2)/$Q$2)) -> 50400.65 | M8: =L8*(1+IF(M$3<=$O$2,$D8,$D8-($D8-$I$6)*MIN(M$3-$O$2,$Q$2)/$Q$2)) -> 54061.753 | N8: =M8*(1+IF(N$3<=$O$2,$D8,$D8-($D8-$I$6)*MIN(N$3-$O$2,$Q$2)/$Q$2)) -> 55591.701 | O8: =SUMPRODUCT(E8:N8,1/(1+$F$6)^$E$3:$N$3)*$E$2 -> 108048.66 | P8: =N8*$E$2*(1+$I$6)/($F$6-$I$6)/(1+$F$6)^$N$3 -> 276731.65 | Q8: =O8+P8 -> 384780.31 | R8: =Q8-$G$2+$I$2 -> 365320.31 | S8: =R8/$K$2 -> 650.74246 | T8: =S8-$M$2 -> 494.93277 | W8: =IF(OR(ABS(W7+0.5)<0.000001,ABS(W7-1)<0.000001),"Out of range","Solved") -> Solved
A9: 2 | B9: =IF(T8>0,B8,D8) -> -0.5 | C9: =IF(T8>0,D8,C8) -> 0.25 | D9: =(B9+C9)/2 -> -0.125 | E9: =$C$2*(1+IF(E$3<=$O$2,$D9,$D9-($D9-$I$6)*MIN(E$3-$O$2,$Q$2)/$Q$2)) -> 9240 | F9: =E9*(1+IF(F$3<=$O$2,$D9,$D9-($D9-$I$6)*MIN(F$3-$O$2,$Q$2)/$Q$2)) -> 8085 | G9: =F9*(1+IF(G$3<=$O$2,$D9,$D9-($D9-$I$6)*MIN(G$3-$O$2,$Q$2)/$Q$2)) -> 7074.375 | H9: =G9*(1+IF(H$3<=$O$2,$D9,$D9-($D9-$I$6)*MIN(H$3-$O$2,$Q$2)/$Q$2)) -> 6190.0781 | I9: =H9*(1+IF(I$3<=$O$2,$D9,$D9-($D9-$I$6)*MIN(I$3-$O$2,$Q$2)/$Q$2)) -> 5416.3184 | J9: =I9*(1+IF(J$3<=$O$2,$D9,$D9-($D9-$I$6)*MIN(J$3-$O$2,$Q$2)/$Q$2)) -> 4905.3429 | K9: =J9*(1+IF(K$3<=$O$2,$D9,$D9-($D9-$I$6)*MIN(K$3-$O$2,$Q$2)/$Q$2)) -> 4592.9707 | L9: =K9*(1+IF(L$3<=$O$2,$D9,$D9-($D9-$I$6)*MIN(L$3-$O$2,$Q$2)/$Q$2)) -> 4441.3108 | M9: =L9*(1+IF(M$3<=$O$2,$D9,$D9-($D9-$I$6)*MIN(M$3-$O$2,$Q$2)/$Q$2)) -> 4430.8293 | N9: =M9*(1+IF(N$3<=$O$2,$D9,$D9-($D9-$I$6)*MIN(N$3-$O$2,$Q$2)/$Q$2)) -> 4556.2217 | O9: =SUMPRODUCT(E9:N9,1/(1+$F$6)^$E$3:$N$3)*$E$2 -> 20959.844 | P9: =N9*$E$2*(1+$I$6)/($F$6-$I$6)/(1+$F$6)^$N$3 -> 22680.557 | Q9: =O9+P9 -> 43640.401 | R9: =Q9-$G$2+$I$2 -> 24180.401 | S9: =R9/$K$2 -> 43.072376 | T9: =S9-$M$2 -> -112.73731
A10: 3 | B10: =IF(T9>0,B9,D9) -> -0.125 | C10: =IF(T9>0,D9,C9) -> 0.25 | D10: =(B10+C10)/2 -> 0.0625 | E10: =$C$2*(1+IF(E$3<=$O$2,$D10,$D10-($D10-$I$6)*MIN(E$3-$O$2,$Q$2)/$Q$2)) -> 11220 | F10: =E10*(1+IF(F$3<=$O$2,$D10,$D10-($D10-$I$6)*MIN(F$3-$O$2,$Q$2)/$Q$2)) -> 11921.25 | G10: =F10*(1+IF(G$3<=$O$2,$D10,$D10-($D10-$I$6)*MIN(G$3-$O$2,$Q$2)/$Q$2)) -> 12666.328 | H10: =G10*(1+IF(H$3<=$O$2,$D10,$D10-($D10-$I$6)*MIN(H$3-$O$2,$Q$2)/$Q$2)) -> 13457.974 | I10: =H10*(1+IF(I$3<=$O$2,$D10,$D10-($D10-$I$6)*MIN(I$3-$O$2,$Q$2)/$Q$2)) -> 14299.097 | J10: =I10*(1+IF(J$3<=$O$2,$D10,$D10-($D10-$I$6)*MIN(J$3-$O$2,$Q$2)/$Q$2)) -> 15094.985 | K10: =J10*(1+IF(K$3<=$O$2,$D10,$D10-($D10-$I$6)*MIN(K$3-$O$2,$Q$2)/$Q$2)) -> 15831.922 | L10: =K10*(1+IF(L$3<=$O$2,$D10,$D10-($D10-$I$6)*MIN(L$3-$O$2,$Q$2)/$Q$2)) -> 16496.546 | M10: =L10*(1+IF(M$3<=$O$2,$D10,$D10-($D10-$I$6)*MIN(M$3-$O$2,$Q$2)/$Q$2)) -> 17076.235 | N10: =M10*(1+IF(N$3<=$O$2,$D10,$D10-($D10-$I$6)*MIN(N$3-$O$2,$Q$2)/$Q$2)) -> 17559.492 | O10: =SUMPRODUCT(E10:N10,1/(1+$F$6)^$E$3:$N$3)*$E$2 -> 47557.33 | P10: =N10*$E$2*(1+$I$6)/($F$6-$I$6)/(1+$F$6)^$N$3 -> 87409.938 | Q10: =O10+P10 -> 134967.27 | R10: =Q10-$G$2+$I$2 -> 115507.27 | S10: =R10/$K$2 -> 205.75227 | T10: =S10-$M$2 -> 49.942584
A11: 4 | B11: =IF(T10>0,B10,D10) -> -0.125 | C11: =IF(T10>0,D10,C10) -> 0.0625 | D11: =(B11+C11)/2 -> -0.03125 | E11: =$C$2*(1+IF(E$3<=$O$2,$D11,$D11-($D11-$I$6)*MIN(E$3-$O$2,$Q$2)/$Q$2)) -> 10230 | F11: =E11*(1+IF(F$3<=$O$2,$D11,$D11-($D11-$I$6)*MIN(F$3-$O$2,$Q$2)/$Q$2)) -> 9910.3125 | G11: =F11*(1+IF(G$3<=$O$2,$D11,$D11-($D11-$I$6)*MIN(G$3-$O$2,$Q$2)/$Q$2)) -> 9600.6152 | H11: =G11*(1+IF(H$3<=$O$2,$D11,$D11-($D11-$I$6)*MIN(H$3-$O$2,$Q$2)/$Q$2)) -> 9300.596 | I11: =H11*(1+IF(I$3<=$O$2,$D11,$D11-($D11-$I$6)*MIN(I$3-$O$2,$Q$2)/$Q$2)) -> 9009.9524 | J11: =I11*(1+IF(J$3<=$O$2,$D11,$D11-($D11-$I$6)*MIN(J$3-$O$2,$Q$2)/$Q$2)) -> 8835.6999 | K11: =J11*(1+IF(K$3<=$O$2,$D11,$D11-($D11-$I$6)*MIN(K$3-$O$2,$Q$2)/$Q$2)) -> 8770.0507 | L11: =K11*(1+IF(L$3<=$O$2,$D11,$D11-($D11-$I$6)*MIN(L$3-$O$2,$Q$2)/$Q$2)) -> 8809.3405 | M11: =L11*(1+IF(M$3<=$O$2,$D11,$D11-($D11-$I$6)*MIN(M$3-$O$2,$Q$2)/$Q$2)) -> 8953.7256 | N11: =M11*(1+IF(N$3<=$O$2,$D11,$D11-($D11-$I$6)*MIN(N$3-$O$2,$Q$2)/$Q$2)) -> 9207.116 | O11: =SUMPRODUCT(E11:N11,1/(1+$F$6)^$E$3:$N$3)*$E$2 -> 31487.518 | P11: =N11*$E$2*(1+$I$6)/($F$6-$I$6)/(1+$F$6)^$N$3 -> 45832.387 | Q11: =O11+P11 -> 77319.905 | R11: =Q11-$G$2+$I$2 -> 57859.905 | S11: =R11/$K$2 -> 103.06544 | T11: =S11-$M$2 -> -52.744251
A12: 5 | B12: =IF(T11>0,B11,D11) -> -0.03125 | C12: =IF(T11>0,D11,C11) -> 0.0625 | D12: =(B12+C12)/2 -> 0.015625 | E12: =$C$2*(1+IF(E$3<=$O$2,$D12,$D12-($D12-$I$6)*MIN(E$3-$O$2,$Q$2)/$Q$2)) -> 10725 | F12: =E12*(1+IF(F$3<=$O$2,$D12,$D12-($D12-$I$6)*MIN(F$3-$O$2,$Q$2)/$Q$2)) -> 10892.578 | G12: =F12*(1+IF(G$3<=$O$2,$D12,$D12-($D12-$I$6)*MIN(G$3-$O$2,$Q$2)/$Q$2)) -> 11062.775 | H12: =G12*(1+IF(H$3<=$O$2,$D12,$D12-($D12-$I$6)*MIN(H$3-$O$2,$Q$2)/$Q$2)) -> 11235.631 | I12: =H12*(1+IF(I$3<=$O$2,$D12,$D12-($D12-$I$6)*MIN(I$3-$O$2,$Q$2)/$Q$2)) -> 11411.187 | J12: =I12*(1+IF(J$3<=$O$2,$D12,$D12-($D12-$I$6)*MIN(J$3-$O$2,$Q$2)/$Q$2)) -> 11618.414 | K12: =J12*(1+IF(K$3<=$O$2,$D12,$D12-($D12-$I$6)*MIN(K$3-$O$2,$Q$2)/$Q$2)) -> 11858.857 | L12: =K12*(1+IF(L$3<=$O$2,$D12,$D12-($D12-$I$6)*MIN(L$3-$O$2,$Q$2)/$Q$2)) -> 12134.339 | M12: =L12*(1+IF(M$3<=$O$2,$D12,$D12-($D12-$I$6)*MIN(M$3-$O$2,$Q$2)/$Q$2)) -> 12446.98 | N12: =M12*(1+IF(N$3<=$O$2,$D12,$D12-($D12-$I$6)*MIN(N$3-$O$2,$Q$2)/$Q$2)) -> 12799.23 | O12: =SUMPRODUCT(E12:N12,1/(1+$F$6)^$E$3:$N$3)*$E$2 -> 38684.207 | P12: =N12*$E$2*(1+$I$6)/($F$6-$I$6)/(1+$F$6)^$N$3 -> 63713.68 | Q12: =O12+P12 -> 102397.89 | R12: =Q12-$G$2+$I$2 -> 82937.887 | S12: =R12/$K$2 -> 147.73667 | T12: =S12-$M$2 -> -8.0730203
A13: 6 | B13: =IF(T12>0,B12,D12) -> 0.015625 | C13: =IF(T12>0,D12,C12) -> 0.0625 | D13: =(B13+C13)/2 -> 0.0390625 | E13: =$C$2*(1+IF(E$3<=$O$2,$D13,$D13-($D13-$I$6)*MIN(E$3-$O$2,$Q$2)/$Q$2)) -> 10972.5 | F13: =E13*(1+IF(F$3<=$O$2,$D13,$D13-($D13-$I$6)*MIN(F$3-$O$2,$Q$2)/$Q$2)) -> 11401.113 | G13: =F13*(1+IF(G$3<=$O$2,$D13,$D13-($D13-$I$6)*MIN(G$3-$O$2,$Q$2)/$Q$2)) -> 11846.469 | H13: =G13*(1+IF(H$3<=$O$2,$D13,$D13-($D13-$I$6)*MIN(H$3-$O$2,$Q$2)/$Q$2)) -> 12309.222 | I13: =H13*(1+IF(I$3<=$O$2,$D13,$D13-($D13-$I$6)*MIN(I$3-$O$2,$Q$2)/$Q$2)) -> 12790.051 | J13: =I13*(1+IF(J$3<=$O$2,$D13,$D13-($D13-$I$6)*MIN(J$3-$O$2,$Q$2)/$Q$2)) -> 13262.132 | K13: =J13*(1+IF(K$3<=$O$2,$D13,$D13-($D13-$I$6)*MIN(K$3-$O$2,$Q$2)/$Q$2)) -> 13723.09 | L13: =K13*(1+IF(L$3<=$O$2,$D13,$D13-($D13-$I$6)*MIN(L$3-$O$2,$Q$2)/$Q$2)) -> 14170.532 | M13: =L13*(1+IF(M$3<=$O$2,$D13,$D13-($D13-$I$6)*MIN(M$3-$O$2,$Q$2)/$Q$2)) -> 14602.06 | N13: =M13*(1+IF(N$3<=$O$2,$D13,$D13-($D13-$I$6)*MIN(N$3-$O$2,$Q$2)/$Q$2)) -> 15015.298 | O13: =SUMPRODUCT(E13:N13,1/(1+$F$6)^$E$3:$N$3)*$E$2 -> 42890.144 | P13: =N13*$E$2*(1+$I$6)/($F$6-$I$6)/(1+$F$6)^$N$3 -> 74745.116 | Q13: =O13+P13 -> 117635.26 | R13: =Q13-$G$2+$I$2 -> 98175.26 | S13: =R13/$K$2 -> 174.87889 | T13: =S13-$M$2 -> 19.069203
A14: 7 | B14: =IF(T13>0,B13,D13) -> 0.015625 | C14: =IF(T13>0,D13,C13) -> 0.0390625 | D14: =(B14+C14)/2 -> 0.02734375 | E14: =$C$2*(1+IF(E$3<=$O$2,$D14,$D14-($D14-$I$6)*MIN(E$3-$O$2,$Q$2)/$Q$2)) -> 10848.75 | F14: =E14*(1+IF(F$3<=$O$2,$D14,$D14-($D14-$I$6)*MIN(F$3-$O$2,$Q$2)/$Q$2)) -> 11145.396 | G14: =F14*(1+IF(G$3<=$O$2,$D14,$D14-($D14-$I$6)*MIN(G$3-$O$2,$Q$2)/$Q$2)) -> 11450.152 | H14: =G14*(1+IF(H$3<=$O$2,$D14,$D14-($D14-$I$6)*MIN(H$3-$O$2,$Q$2)/$Q$2)) -> 11763.243 | I14: =H14*(1+IF(I$3<=$O$2,$D14,$D14-($D14-$I$6)*MIN(I$3-$O$2,$Q$2)/$Q$2)) -> 12084.894 | J14: =I14*(1+IF(J$3<=$O$2,$D14,$D14-($D14-$I$6)*MIN(J$3-$O$2,$Q$2)/$Q$2)) -> 12417.651 | K14: =J14*(1+IF(K$3<=$O$2,$D14,$D14-($D14-$I$6)*MIN(K$3-$O$2,$Q$2)/$Q$2)) -> 12761.946 | L14: =K14*(1+IF(L$3<=$O$2,$D14,$D14-($D14-$I$6)*MIN(L$3-$O$2,$Q$2)/$Q$2)) -> 13118.228 | M14: =L14*(1+IF(M$3<=$O$2,$D14,$D14-($D14-$I$6)*MIN(M$3-$O$2,$Q$2)/$Q$2)) -> 13486.965 | N14: =M14*(1+IF(N$3<=$O$2,$D14,$D14-($D14-$I$6)*MIN(N$3-$O$2,$Q$2)/$Q$2)) -> 13868.646 | O14: =SUMPRODUCT(E14:N14,1/(1+$F$6)^$E$3:$N$3)*$E$2 -> 40732.294 | P14: =N14*$E$2*(1+$I$6)/($F$6-$I$6)/(1+$F$6)^$N$3 -> 69037.161 | Q14: =O14+P14 -> 109769.45 | R14: =Q14-$G$2+$I$2 -> 90309.455 | S14: =R14/$K$2 -> 160.86759 | T14: =S14-$M$2 -> 5.0579008
A15: 8 | B15: =IF(T14>0,B14,D14) -> 0.015625 | C15: =IF(T14>0,D14,C14) -> 0.02734375 | D15: =(B15+C15)/2 -> 0.021484375 | E15: =$C$2*(1+IF(E$3<=$O$2,$D15,$D15-($D15-$I$6)*MIN(E$3-$O$2,$Q$2)/$Q$2)) -> 10786.875 | F15: =E15*(1+IF(F$3<=$O$2,$D15,$D15-($D15-$I$6)*MIN(F$3-$O$2,$Q$2)/$Q$2)) -> 11018.624 | G15: =F15*(1+IF(G$3<=$O$2,$D15,$D15-($D15-$I$6)*MIN(G$3-$O$2,$Q$2)/$Q$2)) -> 11255.353 | H15: =G15*(1+IF(H$3<=$O$2,$D15,$D15-($D15-$I$6)*MIN(H$3-$O$2,$Q$2)/$Q$2)) -> 11497.167 | I15: =H15*(1+IF(I$3<=$O$2,$D15,$D15-($D15-$I$6)*MIN(I$3-$O$2,$Q$2)/$Q$2)) -> 11744.176 | J15: =I15*(1+IF(J$3<=$O$2,$D15,$D15-($D15-$I$6)*MIN(J$3-$O$2,$Q$2)/$Q$2)) -> 12012.501 | K15: =J15*(1+IF(K$3<=$O$2,$D15,$D15-($D15-$I$6)*MIN(K$3-$O$2,$Q$2)/$Q$2)) -> 12303.331 | L15: =K15*(1+IF(L$3<=$O$2,$D15,$D15-($D15-$I$6)*MIN(L$3-$O$2,$Q$2)/$Q$2)) -> 12617.974 | M15: =L15*(1+IF(M$3<=$O$2,$D15,$D15-($D15-$I$6)*MIN(M$3-$O$2,$Q$2)/$Q$2)) -> 12957.863 | N15: =M15*(1+IF(N$3<=$O$2,$D15,$D15-($D15-$I$6)*MIN(N$3-$O$2,$Q$2)/$Q$2)) -> 13324.57 | O15: =SUMPRODUCT(E15:N15,1/(1+$F$6)^$E$3:$N$3)*$E$2 -> 39694.865 | P15: =N15*$E$2*(1+$I$6)/($F$6-$I$6)/(1+$F$6)^$N$3 -> 66328.789 | Q15: =O15+P15 -> 106023.65 | R15: =Q15-$G$2+$I$2 -> 86563.653 | S15: =R15/$K$2 -> 154.19522 | T15: =S15-$M$2 -> -1.6144689
A16: 9 | B16: =IF(T15>0,B15,D15) -> 0.021484375 | C16: =IF(T15>0,D15,C15) -> 0.02734375 | D16: =(B16+C16)/2 -> 0.024414062 | E16: =$C$2*(1+IF(E$3<=$O$2,$D16,$D16-($D16-$I$6)*MIN(E$3-$O$2,$Q$2)/$Q$2)) -> 10817.812 | F16: =E16*(1+IF(F$3<=$O$2,$D16,$D16-($D16-$I$6)*MIN(F$3-$O$2,$Q$2)/$Q$2)) -> 11081.919 | G16: =F16*(1+IF(G$3<=$O$2,$D16,$D16-($D16-$I$6)*MIN(G$3-$O$2,$Q$2)/$Q$2)) -> 11352.474 | H16: =G16*(1+IF(H$3<=$O$2,$D16,$D16-($D16-$I$6)*MIN(H$3-$O$2,$Q$2)/$Q$2)) -> 11629.634 | I16: =H16*(1+IF(I$3<=$O$2,$D16,$D16-($D16-$I$6)*MIN(I$3-$O$2,$Q$2)/$Q$2)) -> 11913.561 | J16: =I16*(1+IF(J$3<=$O$2,$D16,$D16-($D16-$I$6)*MIN(J$3-$O$2,$Q$2)/$Q$2)) -> 12213.678 | K16: =J16*(1+IF(K$3<=$O$2,$D16,$D16-($D16-$I$6)*MIN(K$3-$O$2,$Q$2)/$Q$2)) -> 12530.848 | L16: =K16*(1+IF(L$3<=$O$2,$D16,$D16-($D16-$I$6)*MIN(L$3-$O$2,$Q$2)/$Q$2)) -> 12865.994 | M16: =L16*(1+IF(M$3<=$O$2,$D16,$D16-($D16-$I$6)*MIN(M$3-$O$2,$Q$2)/$Q$2)) -> 13220.102 | N16: =M16*(1+IF(N$3<=$O$2,$D16,$D16-($D16-$I$6)*MIN(N$3-$O$2,$Q$2)/$Q$2)) -> 13594.231 | O16: =SUMPRODUCT(E16:N16,1/(1+$F$6)^$E$3:$N$3)*$E$2 -> 40210.192 | P16: =N16*$E$2*(1+$I$6)/($F$6-$I$6)/(1+$F$6)^$N$3 -> 67671.141 | Q16: =O16+P16 -> 107881.33 | R16: =Q16-$G$2+$I$2 -> 88421.333 | S16: =R16/$K$2 -> 157.50429 | T16: =S16-$M$2 -> 1.6946023
A17: 10 | B17: =IF(T16>0,B16,D16) -> 0.021484375 | C17: =IF(T16>0,D16,C16) -> 0.024414062 | D17: =(B17+C17)/2 -> 0.022949219 | E17: =$C$2*(1+IF(E$3<=$O$2,$D17,$D17-($D17-$I$6)*MIN(E$3-$O$2,$Q$2)/$Q$2)) -> 10802.344 | F17: =E17*(1+IF(F$3<=$O$2,$D17,$D17-($D17-$I$6)*MIN(F$3-$O$2,$Q$2)/$Q$2)) -> 11050.249 | G17: =F17*(1+IF(G$3<=$O$2,$D17,$D17-($D17-$I$6)*MIN(G$3-$O$2,$Q$2)/$Q$2)) -> 11303.844 | H17: =G17*(1+IF(H$3<=$O$2,$D17,$D17-($D17-$I$6)*MIN(H$3-$O$2,$Q$2)/$Q$2)) -> 11563.258 | I17: =H17*(1+IF(I$3<=$O$2,$D17,$D17-($D17-$I$6)*MIN(I$3-$O$2,$Q$2)/$Q$2)) -> 11828.626 | J17: =I17*(1+IF(J$3<=$O$2,$D17,$D17-($D17-$I$6)*MIN(J$3-$O$2,$Q$2)/$Q$2)) -> 12112.742 | K17: =J17*(1+IF(K$3<=$O$2,$D17,$D17-($D17-$I$6)*MIN(K$3-$O$2,$Q$2)/$Q$2)) -> 12416.645 | L17: =K17*(1+IF(L$3<=$O$2,$D17,$D17-($D17-$I$6)*MIN(L$3-$O$2,$Q$2)/$Q$2)) -> 12741.461 | M17: =L17*(1+IF(M$3<=$O$2,$D17,$D17-($D17-$I$6)*MIN(M$3-$O$2,$Q$2)/$Q$2)) -> 13088.409 | N17: =M17*(1+IF(N$3<=$O$2,$D17,$D17-($D17-$I$6)*MIN(N$3-$O$2,$Q$2)/$Q$2)) -> 13458.811 | O17: =SUMPRODUCT(E17:N17,1/(1+$F$6)^$E$3:$N$3)*$E$2 -> 39951.686 | P17: =N17*$E$2*(1+$I$6)/($F$6-$I$6)/(1+$F$6)^$N$3 -> 66997.029 | Q17: =O17+P17 -> 106948.72 | R17: =Q17-$G$2+$I$2 -> 87488.715 | S17: =R17/$K$2 -> 155.84302 | T17: =S17-$M$2 -> 0.033336951
A18: 11 | B18: =IF(T17>0,B17,D17) -> 0.021484375 | C18: =IF(T17>0,D17,C17) -> 0.022949219 | D18: =(B18+C18)/2 -> 0.022216797 | E18: =$C$2*(1+IF(E$3<=$O$2,$D18,$D18-($D18-$I$6)*MIN(E$3-$O$2,$Q$2)/$Q$2)) -> 10794.609 | F18: =E18*(1+IF(F$3<=$O$2,$D18,$D18-($D18-$I$6)*MIN(F$3-$O$2,$Q$2)/$Q$2)) -> 11034.431 | G18: =F18*(1+IF(G$3<=$O$2,$D18,$D18-($D18-$I$6)*MIN(G$3-$O$2,$Q$2)/$Q$2)) -> 11279.581 | H18: =G18*(1+IF(H$3<=$O$2,$D18,$D18-($D18-$I$6)*MIN(H$3-$O$2,$Q$2)/$Q$2)) -> 11530.177 | I18: =H18*(1+IF(I$3<=$O$2,$D18,$D18-($D18-$I$6)*MIN(I$3-$O$2,$Q$2)/$Q$2)) -> 11786.34 | J18: =I18*(1+IF(J$3<=$O$2,$D18,$D18-($D18-$I$6)*MIN(J$3-$O$2,$Q$2)/$Q$2)) -> 12062.535 | K18: =J18*(1+IF(K$3<=$O$2,$D18,$D18-($D18-$I$6)*MIN(K$3-$O$2,$Q$2)/$Q$2)) -> 12359.877 | L18: =K18*(1+IF(L$3<=$O$2,$D18,$D18-($D18-$I$6)*MIN(L$3-$O$2,$Q$2)/$Q$2)) -> 12679.587 | M18: =L18*(1+IF(M$3<=$O$2,$D18,$D18-($D18-$I$6)*MIN(M$3-$O$2,$Q$2)/$Q$2)) -> 13022.993 | N18: =M18*(1+IF(N$3<=$O$2,$D18,$D18-($D18-$I$6)*MIN(N$3-$O$2,$Q$2)/$Q$2)) -> 13391.543 | O18: =SUMPRODUCT(E18:N18,1/(1+$F$6)^$E$3:$N$3)*$E$2 -> 39823.066 | P18: =N18*$E$2*(1+$I$6)/($F$6-$I$6)/(1+$F$6)^$N$3 -> 66662.177 | Q18: =O18+P18 -> 106485.24 | R18: =Q18-$G$2+$I$2 -> 87025.243 | S18: =R18/$K$2 -> 155.01744 | T18: =S18-$M$2 -> -0.79224237
A19: 12 | B19: =IF(T18>0,B18,D18) -> 0.022216797 | C19: =IF(T18>0,D18,C18) -> 0.022949219 | D19: =(B19+C19)/2 -> 0.022583008 | E19: =$C$2*(1+IF(E$3<=$O$2,$D19,$D19-($D19-$I$6)*MIN(E$3-$O$2,$Q$2)/$Q$2)) -> 10798.477 | F19: =E19*(1+IF(F$3<=$O$2,$D19,$D19-($D19-$I$6)*MIN(F$3-$O$2,$Q$2)/$Q$2)) -> 11042.339 | G19: =F19*(1+IF(G$3<=$O$2,$D19,$D19-($D19-$I$6)*MIN(G$3-$O$2,$Q$2)/$Q$2)) -> 11291.708 | H19: =G19*(1+IF(H$3<=$O$2,$D19,$D19-($D19-$I$6)*MIN(H$3-$O$2,$Q$2)/$Q$2)) -> 11546.709 | I19: =H19*(1+IF(I$3<=$O$2,$D19,$D19-($D19-$I$6)*MIN(I$3-$O$2,$Q$2)/$Q$2)) -> 11807.468 | J19: =I19*(1+IF(J$3<=$O$2,$D19,$D19-($D19-$I$6)*MIN(J$3-$O$2,$Q$2)/$Q$2)) -> 12087.617 | K19: =J19*(1+IF(K$3<=$O$2,$D19,$D19-($D19-$I$6)*MIN(K$3-$O$2,$Q$2)/$Q$2)) -> 12388.233 | L19: =K19*(1+IF(L$3<=$O$2,$D19,$D19-($D19-$I$6)*MIN(L$3-$O$2,$Q$2)/$Q$2)) -> 12710.491 | M19: =L19*(1+IF(M$3<=$O$2,$D19,$D19-($D19-$I$6)*MIN(M$3-$O$2,$Q$2)/$Q$2)) -> 13055.665 | N19: =M19*(1+IF(N$3<=$O$2,$D19,$D19-($D19-$I$6)*MIN(N$3-$O$2,$Q$2)/$Q$2)) -> 13425.14 | O19: =SUMPRODUCT(E19:N19,1/(1+$F$6)^$E$3:$N$3)*$E$2 -> 39887.324 | P19: =N19*$E$2*(1+$I$6)/($F$6-$I$6)/(1+$F$6)^$N$3 -> 66829.42 | Q19: =O19+P19 -> 106716.74 | R19: =Q19-$G$2+$I$2 -> 87256.743 | S19: =R19/$K$2 -> 155.42981 | T19: =S19-$M$2 -> -0.37987256
A20: 13 | B20: =IF(T19>0,B19,D19) -> 0.022583008 | C20: =IF(T19>0,D19,C19) -> 0.022949219 | D20: =(B20+C20)/2 -> 0.022766113 | E20: =$C$2*(1+IF(E$3<=$O$2,$D20,$D20-($D20-$I$6)*MIN(E$3-$O$2,$Q$2)/$Q$2)) -> 10800.41 | F20: =E20*(1+IF(F$3<=$O$2,$D20,$D20-($D20-$I$6)*MIN(F$3-$O$2,$Q$2)/$Q$2)) -> 11046.294 | G20: =F20*(1+IF(G$3<=$O$2,$D20,$D20-($D20-$I$6)*MIN(G$3-$O$2,$Q$2)/$Q$2)) -> 11297.775 | H20: =G20*(1+IF(H$3<=$O$2,$D20,$D20-($D20-$I$6)*MIN(H$3-$O$2,$Q$2)/$Q$2)) -> 11554.981 | I20: =H20*(1+IF(I$3<=$O$2,$D20,$D20-($D20-$I$6)*MIN(I$3-$O$2,$Q$2)/$Q$2)) -> 11818.043 | J20: =I20*(1+IF(J$3<=$O$2,$D20,$D20-($D20-$I$6)*MIN(J$3-$O$2,$Q$2)/$Q$2)) -> 12100.174 | K20: =J20*(1+IF(K$3<=$O$2,$D20,$D20-($D20-$I$6)*MIN(K$3-$O$2,$Q$2)/$Q$2)) -> 12402.432 | L20: =K20*(1+IF(L$3<=$O$2,$D20,$D20-($D20-$I$6)*MIN(L$3-$O$2,$Q$2)/$Q$2)) -> 12725.968 | M20: =L20*(1+IF(M$3<=$O$2,$D20,$D20-($D20-$I$6)*MIN(M$3-$O$2,$Q$2)/$Q$2)) -> 13072.028 | N20: =M20*(1+IF(N$3<=$O$2,$D20,$D20-($D20-$I$6)*MIN(N$3-$O$2,$Q$2)/$Q$2)) -> 13441.966 | O20: =SUMPRODUCT(E20:N20,1/(1+$F$6)^$E$3:$N$3)*$E$2 -> 39919.492 | P20: =N20*$E$2*(1+$I$6)/($F$6-$I$6)/(1+$F$6)^$N$3 -> 66913.178 | Q20: =O20+P20 -> 106832.67 | R20: =Q20-$G$2+$I$2 -> 87372.67 | S20: =R20/$K$2 -> 155.63631 | T20: =S20-$M$2 -> -0.17337286
... A47: 40 | B47: =IF(T46>0,B46,D46) -> 0.022919701 | C47: =IF(T46>0,D46,C46) -> 0.022919701 | D47: =(B47+C47)/2 -> 0.022919701 | E47: =$C$2*(1+IF(E$3<=$O$2,$D47,$D47-($D47-$I$6)*MIN(E$3-$O$2,$Q$2)/$Q$2)) -> 10802.032 | F47: =E47*(1+IF(F$3<=$O$2,$D47,$D47-($D47-$I$6)*MIN(F$3-$O$2,$Q$2)/$Q$2)) -> 11049.611 | G47: =F47*(1+IF(G$3<=$O$2,$D47,$D47-($D47-$I$6)*MIN(G$3-$O$2,$Q$2)/$Q$2)) -> 11302.865 | H47: =G47*(1+IF(H$3<=$O$2,$D47,$D47-($D47-$I$6)*MIN(H$3-$O$2,$Q$2)/$Q$2)) -> 11561.923 | I47: =H47*(1+IF(I$3<=$O$2,$D47,$D47-($D47-$I$6)*MIN(I$3-$O$2,$Q$2)/$Q$2)) -> 11826.919 | J47: =I47*(1+IF(J$3<=$O$2,$D47,$D47-($D47-$I$6)*MIN(J$3-$O$2,$Q$2)/$Q$2)) -> 12110.715 | K47: =J47*(1+IF(K$3<=$O$2,$D47,$D47-($D47-$I$6)*MIN(K$3-$O$2,$Q$2)/$Q$2)) -> 12414.353 | L47: =K47*(1+IF(L$3<=$O$2,$D47,$D47-($D47-$I$6)*MIN(L$3-$O$2,$Q$2)/$Q$2)) -> 12738.962 | M47: =L47*(1+IF(M$3<=$O$2,$D47,$D47-($D47-$I$6)*MIN(M$3-$O$2,$Q$2)/$Q$2)) -> 13085.767 | N47: =M47*(1+IF(N$3<=$O$2,$D47,$D47-($D47-$I$6)*MIN(N$3-$O$2,$Q$2)/$Q$2)) -> 13456.094 | O47: =SUMPRODUCT(E47:N47,1/(1+$F$6)^$E$3:$N$3)*$E$2 -> 39946.495 | P47: =N47*$E$2*(1+$I$6)/($F$6-$I$6)/(1+$F$6)^$N$3 -> 66983.505 | Q47: =O47+P47 -> 106930 | R47: =Q47-$G$2+$I$2 -> 87470 | S47: =R47/$K$2 -> 155.80969 | T47: =S47-$M$2 -> 1.4248087e-09
A49: Grid block 2: row 1, column 1 of table A (24 steps) | E49: WACC | F49: =Sensitivity!$B$10 -> 0.067017203 | G49: Terminal growth | I49: =Sensitivity!$C$9 -> 0.0183
A50: Step | B50: Low | C50: High | D50: Mid | E50: Rev Y1 | F50: Rev Y2 | G50: Rev Y3 | H50: Rev Y4 | I50: Rev Y5 | J50: Rev Y6 | K50: Rev Y7 | L50: Rev Y8 | M50: Rev Y9 | N50: Rev Y10 | O50: PV of FCF | P50: PV of TV | Q50: EV | R50: Equity | S50: Per share | T50: Value - price
A51: 1 | B51: -0.5 | C51: 1 | D51: =(B51+C51)/2 -> 0.25 | E51: =$C$2*(1+IF(E$3<=$O$2,$D51,$D51-($D51-$I$49)*MIN(E$3-$O$2,$Q$2)/$Q$2)) -> 13200 | F51: =E51*(1+IF(F$3<=$O$2,$D51,$D51-($D51-$I$49)*MIN(F$3-$O$2,$Q$2)/$Q$2)) -> 16500 | G51: =F51*(1+IF(G$3<=$O$2,$D51,$D51-($D51-$I$49)*MIN(G$3-$O$2,$Q$2)/$Q$2)) -> 20625 | H51: =G51*(1+IF(H$3<=$O$2,$D51,$D51-($D51-$I$49)*MIN(H$3-$O$2,$Q$2)/$Q$2)) -> 25781.25 | I51: =H51*(1+IF(I$3<=$O$2,$D51,$D51-($D51-$I$49)*MIN(I$3-$O$2,$Q$2)/$Q$2)) -> 32226.562 | J51: =I51*(1+IF(J$3<=$O$2,$D51,$D51-($D51-$I$49)*MIN(J$3-$O$2,$Q$2)/$Q$2)) -> 38789.824 | K51: =J51*(1+IF(K$3<=$O$2,$D51,$D51-($D51-$I$49)*MIN(K$3-$O$2,$Q$2)/$Q$2)) -> 44892.239 | L51: =K51*(1+IF(L$3<=$O$2,$D51,$D51-($D51-$I$49)*MIN(L$3-$O$2,$Q$2)/$Q$2)) -> 49874.38 | M51: =L51*(1+IF(M$3<=$O$2,$D51,$D51-($D51-$I$49)*MIN(M$3-$O$2,$Q$2)/$Q$2)) -> 53098.26 | N51: =M51*(1+IF(N$3<=$O$2,$D51,$D51-($D51-$I$49)*MIN(N$3-$O$2,$Q$2)/$Q$2)) -> 54069.958 | O51: =SUMPRODUCT(E51:N51,1/(1+$F$49)^$E$3:$N$3)*$E$2 -> 113607.26 | P51: =N51*$E$2*(1+$I$49)/($F$49-$I$49)/(1+$F$49)^$N$3 -> 292599.1 | Q51: =O51+P51 -> 406206.36 | R51: =Q51-$G$2+$I$2 -> 386746.36 | S51: =R51/$K$2 -> 688.90853 | T51: =S51-$M$2 -> 533.09885
A52: 2 | B52: =IF(T51>0,B51,D51) -> -0.5 | C52: =IF(T51>0,D51,C51) -> 0.25 | D52: =(B52+C52)/2 -> -0.125 | E52: =$C$2*(1+IF(E$3<=$O$2,$D52,$D52-($D52-$I$49)*MIN(E$3-$O$2,$Q$2)/$Q$2)) -> 9240 | F52: =E52*(1+IF(F$3<=$O$2,$D52,$D52-($D52-$I$49)*MIN(F$3-$O$2,$Q$2)/$Q$2)) -> 8085 | G52: =F52*(1+IF(G$3<=$O$2,$D52,$D52-($D52-$I$49)*MIN(G$3-$O$2,$Q$2)/$Q$2)) -> 7074.375 | H52: =G52*(1+IF(H$3<=$O$2,$D52,$D52-($D52-$I$49)*MIN(H$3-$O$2,$Q$2)/$Q$2)) -> 6190.0781 | I52: =H52*(1+IF(I$3<=$O$2,$D52,$D52-($D52-$I$49)*MIN(I$3-$O$2,$Q$2)/$Q$2)) -> 5416.3184 | J52: =I52*(1+IF(J$3<=$O$2,$D52,$D52-($D52-$I$49)*MIN(J$3-$O$2,$Q$2)/$Q$2)) -> 4894.5102 | K52: =J52*(1+IF(K$3<=$O$2,$D52,$D52-($D52-$I$49)*MIN(K$3-$O$2,$Q$2)/$Q$2)) -> 4563.2498 | L52: =K52*(1+IF(L$3<=$O$2,$D52,$D52-($D52-$I$49)*MIN(L$3-$O$2,$Q$2)/$Q$2)) -> 4385.1918 | M52: =L52*(1+IF(M$3<=$O$2,$D52,$D52-($D52-$I$49)*MIN(M$3-$O$2,$Q$2)/$Q$2)) -> 4339.7612 | N52: =M52*(1+IF(N$3<=$O$2,$D52,$D52-($D52-$I$49)*MIN(N$3-$O$2,$Q$2)/$Q$2)) -> 4419.1788 | O52: =SUMPRODUCT(E52:N52,1/(1+$F$49)^$E$3:$N$3)*$E$2 -> 21707.788 | P52: =N52*$E$2*(1+$I$49)/($F$49-$I$49)/(1+$F$49)^$N$3 -> 23914.347 | Q52: =O52+P52 -> 45622.136 | R52: =Q52-$G$2+$I$2 -> 26162.136 | S52: =R52/$K$2 -> 46.602426 | T52: =S52-$M$2 -> -109.20726
A53: 3 | B53: =IF(T52>0,B52,D52) -> -0.125 | C53: =IF(T52>0,D52,C52) -> 0.25 | D53: =(B53+C53)/2 -> 0.0625 | E53: =$C$2*(1+IF(E$3<=$O$2,$D53,$D53-($D53-$I$49)*MIN(E$3-$O$2,$Q$2)/$Q$2)) -> 11220 | F53: =E53*(1+IF(F$3<=$O$2,$D53,$D53-($D53-$I$49)*MIN(F$3-$O$2,$Q$2)/$Q$2)) -> 11921.25 | G53: =F53*(1+IF(G$3<=$O$2,$D53,$D53-($D53-$I$49)*MIN(G$3-$O$2,$Q$2)/$Q$2)) -> 12666.328 | H53: =G53*(1+IF(H$3<=$O$2,$D53,$D53-($D53-$I$49)*MIN(H$3-$O$2,$Q$2)/$Q$2)) -> 13457.974 | I53: =H53*(1+IF(I$3<=$O$2,$D53,$D53-($D53-$I$49)*MIN(I$3-$O$2,$Q$2)/$Q$2)) -> 14299.097 | J53: =I53*(1+IF(J$3<=$O$2,$D53,$D53-($D53-$I$49)*MIN(J$3-$O$2,$Q$2)/$Q$2)) -> 15066.387 | K53: =J53*(1+IF(K$3<=$O$2,$D53,$D53-($D53-$I$49)*MIN(K$3-$O$2,$Q$2)/$Q$2)) -> 15741.662 | L53: =K53*(1+IF(L$3<=$O$2,$D53,$D53-($D53-$I$49)*MIN(L$3-$O$2,$Q$2)/$Q$2)) -> 16308.047 | M53: =L53*(1+IF(M$3<=$O$2,$D53,$D53-($D53-$I$49)*MIN(M$3-$O$2,$Q$2)/$Q$2)) -> 16750.647 | N53: =M53*(1+IF(N$3<=$O$2,$D53,$D53-($D53-$I$49)*MIN(N$3-$O$2,$Q$2)/$Q$2)) -> 17057.184 | O53: =SUMPRODUCT(E53:N53,1/(1+$F$49)^$E$3:$N$3)*$E$2 -> 49677.075 | P53: =N53*$E$2*(1+$I$49)/($F$49-$I$49)/(1+$F$49)^$N$3 -> 92304.803 | Q53: =O53+P53 -> 141981.88 | R53: =Q53-$G$2+$I$2 -> 122521.88 | S53: =R53/$K$2 -> 218.24735 | T53: =S53-$M$2 -> 62.437659
A54: 4 | B54: =IF(T53>0,B53,D53) -> -0.125 | C54: =IF(T53>0,D53,C53) -> 0.0625 | D54: =(B54+C54)/2 -> -0.03125 | E54: =$C$2*(1+IF(E$3<=$O$2,$D54,$D54-($D54-$I$49)*MIN(E$3-$O$2,$Q$2)/$Q$2)) -> 10230 | F54: =E54*(1+IF(F$3<=$O$2,$D54,$D54-($D54-$I$49)*MIN(F$3-$O$2,$Q$2)/$Q$2)) -> 9910.3125 | G54: =F54*(1+IF(G$3<=$O$2,$D54,$D54-($D54-$I$49)*MIN(G$3-$O$2,$Q$2)/$Q$2)) -> 9600.6152 | H54: =G54*(1+IF(H$3<=$O$2,$D54,$D54-($D54-$I$49)*MIN(H$3-$O$2,$Q$2)/$Q$2)) -> 9300.596 | I54: =H54*(1+IF(I$3<=$O$2,$D54,$D54-($D54-$I$49)*MIN(I$3-$O$2,$Q$2)/$Q$2)) -> 9009.9524 | J54: =I54*(1+IF(J$3<=$O$2,$D54,$D54-($D54-$I$49)*MIN(J$3-$O$2,$Q$2)/$Q$2)) -> 8817.68 | K54: =J54*(1+IF(K$3<=$O$2,$D54,$D54-($D54-$I$49)*MIN(K$3-$O$2,$Q$2)/$Q$2)) -> 8716.8939 | L54: =K54*(1+IF(L$3<=$O$2,$D54,$D54-($D54-$I$49)*MIN(L$3-$O$2,$Q$2)/$Q$2)) -> 8703.6442 | M54: =L54*(1+IF(M$3<=$O$2,$D54,$D54-($D54-$I$49)*MIN(M$3-$O$2,$Q$2)/$Q$2)) -> 8776.6678 | N54: =M54*(1+IF(N$3<=$O$2,$D54,$D54-($D54-$I$49)*MIN(N$3-$O$2,$Q$2)/$Q$2)) -> 8937.2808 | O54: =SUMPRODUCT(E54:N54,1/(1+$F$49)^$E$3:$N$3)*$E$2 -> 32757.744 | P54: =N54*$E$2*(1+$I$49)/($F$49-$I$49)/(1+$F$49)^$N$3 -> 48364.017 | Q54: =O54+P54 -> 81121.761 | R54: =Q54-$G$2+$I$2 -> 61661.761 | S54: =R54/$K$2 -> 109.83765 | T54: =S54-$M$2 -> -45.972032
A55: 5 | B55: =IF(T54>0,B54,D54) -> -0.03125 | C55: =IF(T54>0,D54,C54) -> 0.0625 | D55: =(B55+C55)/2 -> 0.015625 | E55: =$C$2*(1+IF(E$3<=$O$2,$D55,$D55-($D55-$I$49)*MIN(E$3-$O$2,$Q$2)/$Q$2)) -> 10725 | F55: =E55*(1+IF(F$3<=$O$2,$D55,$D55-($D55-$I$49)*MIN(F$3-$O$2,$Q$2)/$Q$2)) -> 10892.578 | G55: =F55*(1+IF(G$3<=$O$2,$D55,$D55-($D55-$I$49)*MIN(G$3-$O$2,$Q$2)/$Q$2)) -> 11062.775 | H55: =G55*(1+IF(H$3<=$O$2,$D55,$D55-($D55-$I$49)*MIN(H$3-$O$2,$Q$2)/$Q$2)) -> 11235.631 | I55: =H55*(1+IF(I$3<=$O$2,$D55,$D55-($D55-$I$49)*MIN(I$3-$O$2,$Q$2)/$Q$2)) -> 11411.187 | J55: =I55*(1+IF(J$3<=$O$2,$D55,$D55-($D55-$I$49)*MIN(J$3-$O$2,$Q$2)/$Q$2)) -> 11595.592 | K55: =J55*(1+IF(K$3<=$O$2,$D55,$D55-($D55-$I$49)*MIN(K$3-$O$2,$Q$2)/$Q$2)) -> 11789.18 | L55: =K55*(1+IF(L$3<=$O$2,$D55,$D55-($D55-$I$49)*MIN(L$3-$O$2,$Q$2)/$Q$2)) -> 11992.308 | M55: =L55*(1+IF(M$3<=$O$2,$D55,$D55-($D55-$I$49)*MIN(M$3-$O$2,$Q$2)/$Q$2)) -> 12205.351 | N55: =M55*(1+IF(N$3<=$O$2,$D55,$D55-($D55-$I$49)*MIN(N$3-$O$2,$Q$2)/$Q$2)) -> 12428.709 | O55: =SUMPRODUCT(E55:N55,1/(1+$F$49)^$E$3:$N$3)*$E$2 -> 40329.007 | P55: =N55*$E$2*(1+$I$49)/($F$49-$I$49)/(1+$F$49)^$N$3 -> 67257.851 | Q55: =O55+P55 -> 107586.86 | R55: =Q55-$G$2+$I$2 -> 88126.858 | S55: =R55/$K$2 -> 156.97974 | T55: =S55-$M$2 -> 1.1700572
A56: 6 | B56: =IF(T55>0,B55,D55) -> -0.03125 | C56: =IF(T55>0,D55,C55) -> 0.015625 | D56: =(B56+C56)/2 -> -0.0078125 | E56: =$C$2*(1+IF(E$3<=$O$2,$D56,$D56-($D56-$I$49)*MIN(E$3-$O$2,$Q$2)/$Q$2)) -> 10477.5 | F56: =E56*(1+IF(F$3<=$O$2,$D56,$D56-($D56-$I$49)*MIN(F$3-$O$2,$Q$2)/$Q$2)) -> 10395.645 | G56: =F56*(1+IF(G$3<=$O$2,$D56,$D56-($D56-$I$49)*MIN(G$3-$O$2,$Q$2)/$Q$2)) -> 10314.429 | H56: =G56*(1+IF(H$3<=$O$2,$D56,$D56-($D56-$I$49)*MIN(H$3-$O$2,$Q$2)/$Q$2)) -> 10233.847 | I56: =H56*(1+IF(I$3<=$O$2,$D56,$D56-($D56-$I$49)*MIN(I$3-$O$2,$Q$2)/$Q$2)) -> 10153.895 | J56: =I56*(1+IF(J$3<=$O$2,$D56,$D56-($D56-$I$49)*MIN(J$3-$O$2,$Q$2)/$Q$2)) -> 10127.597 | K56: =J56*(1+IF(K$3<=$O$2,$D56,$D56-($D56-$I$49)*MIN(K$3-$O$2,$Q$2)/$Q$2)) -> 10154.257 | L56: =K56*(1+IF(L$3<=$O$2,$D56,$D56-($D56-$I$49)*MIN(L$3-$O$2,$Q$2)/$Q$2)) -> 10234.019 | M56: =L56*(1+IF(M$3<=$O$2,$D56,$D56-($D56-$I$49)*MIN(M$3-$O$2,$Q$2)/$Q$2)) -> 10367.855 | N56: =M56*(1+IF(N$3<=$O$2,$D56,$D56-($D56-$I$49)*MIN(N$3-$O$2,$Q$2)/$Q$2)) -> 10557.586 | O56: =SUMPRODUCT(E56:N56,1/(1+$F$49)^$E$3:$N$3)*$E$2 -> 36342.756 | P56: =N56*$E$2*(1+$I$49)/($F$49-$I$49)/(1+$F$49)^$N$3 -> 57132.286 | Q56: =O56+P56 -> 93475.041 | R56: =Q56-$G$2+$I$2 -> 74015.041 | S56: =R56/$K$2 -> 131.84246 | T56: =S56-$M$2 -> -23.967222
A57: 7 | B57: =IF(T56>0,B56,D56) -> -0.0078125 | C57: =IF(T56>0,D56,C56) -> 0.015625 | D57: =(B57+C57)/2 -> 0.00390625 | E57: =$C$2*(1+IF(E$3<=$O$2,$D57,$D57-($D57-$I$49)*MIN(E$3-$O$2,$Q$2)/$Q$2)) -> 10601.25 | F57: =E57*(1+IF(F$3<=$O$2,$D57,$D57-($D57-$I$49)*MIN(F$3-$O$2,$Q$2)/$Q$2)) -> 10642.661 | G57: =F57*(1+IF(G$3<=$O$2,$D57,$D57-($D57-$I$49)*MIN(G$3-$O$2,$Q$2)/$Q$2)) -> 10684.234 | H57: =G57*(1+IF(H$3<=$O$2,$D57,$D57-($D57-$I$49)*MIN(H$3-$O$2,$Q$2)/$Q$2)) -> 10725.969 | I57: =H57*(1+IF(I$3<=$O$2,$D57,$D57-($D57-$I$49)*MIN(I$3-$O$2,$Q$2)/$Q$2)) -> 10767.868 | J57: =I57*(1+IF(J$3<=$O$2,$D57,$D57-($D57-$I$49)*MIN(J$3-$O$2,$Q$2)/$Q$2)) -> 10840.928 | K57: =J57*(1+IF(K$3<=$O$2,$D57,$D57-($D57-$I$49)*MIN(K$3-$O$2,$Q$2)/$Q$2)) -> 10945.692 | L57: =K57*(1+IF(L$3<=$O$2,$D57,$D57-($D57-$I$49)*MIN(L$3-$O$2,$Q$2)/$Q$2)) -> 11082.978 | M57: =L57*(1+IF(M$3<=$O$2,$D57,$D57-($D57-$I$49)*MIN(M$3-$O$2,$Q$2)/$Q$2)) -> 11253.891 | N57: =M57*(1+IF(N$3<=$O$2,$D57,$D57-($D57-$I$49)*MIN(N$3-$O$2,$Q$2)/$Q$2)) -> 11459.838 | O57: =SUMPRODUCT(E57:N57,1/(1+$F$49)^$E$3:$N$3)*$E$2 -> 38283.186 | P57: =N57*$E$2*(1+$I$49)/($F$49-$I$49)/(1+$F$49)^$N$3 -> 62014.81 | Q57: =O57+P57 -> 100298 | R57: =Q57-$G$2+$I$2 -> 80837.996 | S57: =R57/$K$2 -> 143.99615 | T57: =S57-$M$2 -> -11.813541
A58: 8 | B58: =IF(T57>0,B57,D57) -> 0.00390625 | C58: =IF(T57>0,D57,C57) -> 0.015625 | D58: =(B58+C58)/2 -> 0.009765625 | E58: =$C$2*(1+IF(E$3<=$O$2,$D58,$D58-($D58-$I$49)*MIN(E$3-$O$2,$Q$2)/$Q$2)) -> 10663.125 | F58: =E58*(1+IF(F$3<=$O$2,$D58,$D58-($D58-$I$49)*MIN(F$3-$O$2,$Q$2)/$Q$2)) -> 10767.257 | G58: =F58*(1+IF(G$3<=$O$2,$D58,$D58-($D58-$I$49)*MIN(G$3-$O$2,$Q$2)/$Q$2)) -> 10872.406 | H58: =G58*(1+IF(H$3<=$O$2,$D58,$D58-($D58-$I$49)*MIN(H$3-$O$2,$Q$2)/$Q$2)) -> 10978.582 | I58: =H58*(1+IF(I$3<=$O$2,$D58,$D58-($D58-$I$49)*MIN(I$3-$O$2,$Q$2)/$Q$2)) -> 11085.795 | J58: =I58*(1+IF(J$3<=$O$2,$D58,$D58-($D58-$I$49)*MIN(J$3-$O$2,$Q$2)/$Q$2)) -> 11212.976 | K58: =J58*(1+IF(K$3<=$O$2,$D58,$D58-($D58-$I$49)*MIN(K$3-$O$2,$Q$2)/$Q$2)) -> 11360.756 | L58: =K58*(1+IF(L$3<=$O$2,$D58,$D58-($D58-$I$49)*MIN(L$3-$O$2,$Q$2)/$Q$2)) -> 11529.875 | M58: =L58*(1+IF(M$3<=$O$2,$D58,$D58-($D58-$I$49)*MIN(M$3-$O$2,$Q$2)/$Q$2)) -> 11721.192 | N58: =M58*(1+IF(N$3<=$O$2,$D58,$D58-($D58-$I$49)*MIN(N$3-$O$2,$Q$2)/$Q$2)) -> 11935.69 | O58: =SUMPRODUCT(E58:N58,1/(1+$F$49)^$E$3:$N$3)*$E$2 -> 39292.593 | P58: =N58*$E$2*(1+$I$49)/($F$49-$I$49)/(1+$F$49)^$N$3 -> 64589.882 | Q58: =O58+P58 -> 103882.47 | R58: =Q58-$G$2+$I$2 -> 84422.474 | S58: =R58/$K$2 -> 150.38115 | T58: =S58-$M$2 -> -5.4285357
A59: 9 | B59: =IF(T58>0,B58,D58) -> 0.009765625 | C59: =IF(T58>0,D58,C58) -> 0.015625 | D59: =(B59+C59)/2 -> 0.012695312 | E59: =$C$2*(1+IF(E$3<=$O$2,$D59,$D59-($D59-$I$49)*MIN(E$3-$O$2,$Q$2)/$Q$2)) -> 10694.062 | F59: =E59*(1+IF(F$3<=$O$2,$D59,$D59-($D59-$I$49)*MIN(F$3-$O$2,$Q$2)/$Q$2)) -> 10829.827 | G59: =F59*(1+IF(G$3<=$O$2,$D59,$D59-($D59-$I$49)*MIN(G$3-$O$2,$Q$2)/$Q$2)) -> 10967.315 | H59: =G59*(1+IF(H$3<=$O$2,$D59,$D59-($D59-$I$49)*MIN(H$3-$O$2,$Q$2)/$Q$2)) -> 11106.548 | I59: =H59*(1+IF(I$3<=$O$2,$D59,$D59-($D59-$I$49)*MIN(I$3-$O$2,$Q$2)/$Q$2)) -> 11247.55 | J59: =I59*(1+IF(J$3<=$O$2,$D59,$D59-($D59-$I$49)*MIN(J$3-$O$2,$Q$2)/$Q$2)) -> 11402.949 | K59: =J59*(1+IF(K$3<=$O$2,$D59,$D59-($D59-$I$49)*MIN(K$3-$O$2,$Q$2)/$Q$2)) -> 11573.277 | L59: =K59*(1+IF(L$3<=$O$2,$D59,$D59-($D59-$I$49)*MIN(L$3-$O$2,$Q$2)/$Q$2)) -> 11759.122 | M59: =L59*(1+IF(M$3<=$O$2,$D59,$D59-($D59-$I$49)*MIN(M$3-$O$2,$Q$2)/$Q$2)) -> 11961.132 | N59: =M59*(1+IF(N$3<=$O$2,$D59,$D59-($D59-$I$49)*MIN(N$3-$O$2,$Q$2)/$Q$2)) -> 12180.021 | O59: =SUMPRODUCT(E59:N59,1/(1+$F$49)^$E$3:$N$3)*$E$2 -> 39807.382 | P59: =N59*$E$2*(1+$I$49)/($F$49-$I$49)/(1+$F$49)^$N$3 -> 65912.077 | Q59: =O59+P59 -> 105719.46 | R59: =Q59-$G$2+$I$2 -> 86259.459 | S59: =R59/$K$2 -> 153.65336 | T59: =S59-$M$2 -> -2.1563278
A60: 10 | B60: =IF(T59>0,B59,D59) -> 0.012695312 | C60: =IF(T59>0,D59,C59) -> 0.015625 | D60: =(B60+C60)/2 -> 0.014160156 | E60: =$C$2*(1+IF(E$3<=$O$2,$D60,$D60-($D60-$I$49)*MIN(E$3-$O$2,$Q$2)/$Q$2)) -> 10709.531 | F60: =E60*(1+IF(F$3<=$O$2,$D60,$D60-($D60-$I$49)*MIN(F$3-$O$2,$Q$2)/$Q$2)) -> 10861.18 | G60: =F60*(1+IF(G$3<=$O$2,$D60,$D60-($D60-$I$49)*MIN(G$3-$O$2,$Q$2)/$Q$2)) -> 11014.976 | H60: =G60*(1+IF(H$3<=$O$2,$D60,$D60-($D60-$I$49)*MIN(H$3-$O$2,$Q$2)/$Q$2)) -> 11170.95 | I60: =H60*(1+IF(I$3<=$O$2,$D60,$D60-($D60-$I$49)*MIN(I$3-$O$2,$Q$2)/$Q$2)) -> 11329.132 | J60: =I60*(1+IF(J$3<=$O$2,$D60,$D60-($D60-$I$49)*MIN(J$3-$O$2,$Q$2)/$Q$2)) -> 11498.935 | K60: =J60*(1+IF(K$3<=$O$2,$D60,$D60-($D60-$I$49)*MIN(K$3-$O$2,$Q$2)/$Q$2)) -> 11680.803 | L60: =K60*(1+IF(L$3<=$O$2,$D60,$D60-($D60-$I$49)*MIN(L$3-$O$2,$Q$2)/$Q$2)) -> 11875.219 | M60: =L60*(1+IF(M$3<=$O$2,$D60,$D60-($D60-$I$49)*MIN(M$3-$O$2,$Q$2)/$Q$2)) -> 12082.703 | N60: =M60*(1+IF(N$3<=$O$2,$D60,$D60-($D60-$I$49)*MIN(N$3-$O$2,$Q$2)/$Q$2)) -> 12303.816 | O60: =SUMPRODUCT(E60:N60,1/(1+$F$49)^$E$3:$N$3)*$E$2 -> 40067.335 | P60: =N60*$E$2*(1+$I$49)/($F$49-$I$49)/(1+$F$49)^$N$3 -> 66581.995 | Q60: =O60+P60 -> 106649.33 | R60: =Q60-$G$2+$I$2 -> 87189.329 | S60: =R60/$K$2 -> 155.30973 | T60: =S60-$M$2 -> -0.49995673
A61: 11 | B61: =IF(T60>0,B60,D60) -> 0.014160156 | C61: =IF(T60>0,D60,C60) -> 0.015625 | D61: =(B61+C61)/2 -> 0.014892578 | E61: =$C$2*(1+IF(E$3<=$O$2,$D61,$D61-($D61-$I$49)*MIN(E$3-$O$2,$Q$2)/$Q$2)) -> 10717.266 | F61: =E61*(1+IF(F$3<=$O$2,$D61,$D61-($D61-$I$49)*MIN(F$3-$O$2,$Q$2)/$Q$2)) -> 10876.873 | G61: =F61*(1+IF(G$3<=$O$2,$D61,$D61-($D61-$I$49)*MIN(G$3-$O$2,$Q$2)/$Q$2)) -> 11038.858 | H61: =G61*(1+IF(H$3<=$O$2,$D61,$D61-($D61-$I$49)*MIN(H$3-$O$2,$Q$2)/$Q$2)) -> 11203.255 | I61: =H61*(1+IF(I$3<=$O$2,$D61,$D61-($D61-$I$49)*MIN(I$3-$O$2,$Q$2)/$Q$2)) -> 11370.1 | J61: =I61*(1+IF(J$3<=$O$2,$D61,$D61-($D61-$I$49)*MIN(J$3-$O$2,$Q$2)/$Q$2)) -> 11547.179 | K61: =J61*(1+IF(K$3<=$O$2,$D61,$D61-($D61-$I$49)*MIN(K$3-$O$2,$Q$2)/$Q$2)) -> 11734.885 | L61: =K61*(1+IF(L$3<=$O$2,$D61,$D61-($D61-$I$49)*MIN(L$3-$O$2,$Q$2)/$Q$2)) -> 11933.639 | M61: =L61*(1+IF(M$3<=$O$2,$D61,$D61-($D61-$I$49)*MIN(M$3-$O$2,$Q$2)/$Q$2)) -> 12143.892 | N61: =M61*(1+IF(N$3<=$O$2,$D61,$D61-($D61-$I$49)*MIN(N$3-$O$2,$Q$2)/$Q$2)) -> 12366.125 | O61: =SUMPRODUCT(E61:N61,1/(1+$F$49)^$E$3:$N$3)*$E$2 -> 40197.955 | P61: =N61*$E$2*(1+$I$49)/($F$49-$I$49)/(1+$F$49)^$N$3 -> 66919.178 | Q61: =O61+P61 -> 107117.13 | R61: =Q61-$G$2+$I$2 -> 87657.133 | S61: =R61/$K$2 -> 156.14303 | T61: =S61-$M$2 -> 0.33333868
A62: 12 | B62: =IF(T61>0,B61,D61) -> 0.014160156 | C62: =IF(T61>0,D61,C61) -> 0.014892578 | D62: =(B62+C62)/2 -> 0.014526367 | E62: =$C$2*(1+IF(E$3<=$O$2,$D62,$D62-($D62-$I$49)*MIN(E$3-$O$2,$Q$2)/$Q$2)) -> 10713.398 | F62: =E62*(1+IF(F$3<=$O$2,$D62,$D62-($D62-$I$49)*MIN(F$3-$O$2,$Q$2)/$Q$2)) -> 10869.025 | G62: =F62*(1+IF(G$3<=$O$2,$D62,$D62-($D62-$I$49)*MIN(G$3-$O$2,$Q$2)/$Q$2)) -> 11026.913 | H62: =G62*(1+IF(H$3<=$O$2,$D62,$D62-($D62-$I$49)*MIN(H$3-$O$2,$Q$2)/$Q$2)) -> 11187.094 | I62: =H62*(1+IF(I$3<=$O$2,$D62,$D62-($D62-$I$49)*MIN(I$3-$O$2,$Q$2)/$Q$2)) -> 11349.601 | J62: =I62*(1+IF(J$3<=$O$2,$D62,$D62-($D62-$I$49)*MIN(J$3-$O$2,$Q$2)/$Q$2)) -> 11523.036 | K62: =J62*(1+IF(K$3<=$O$2,$D62,$D62-($D62-$I$49)*MIN(K$3-$O$2,$Q$2)/$Q$2)) -> 11707.817 | L62: =K62*(1+IF(L$3<=$O$2,$D62,$D62-($D62-$I$49)*MIN(L$3-$O$2,$Q$2)/$Q$2)) -> 11904.398 | M62: =L62*(1+IF(M$3<=$O$2,$D62,$D62-($D62-$I$49)*MIN(M$3-$O$2,$Q$2)/$Q$2)) -> 12113.264 | N62: =M62*(1+IF(N$3<=$O$2,$D62,$D62-($D62-$I$49)*MIN(N$3-$O$2,$Q$2)/$Q$2)) -> 12334.936 | O62: =SUMPRODUCT(E62:N62,1/(1+$F$49)^$E$3:$N$3)*$E$2 -> 40132.591 | P62: =N62*$E$2*(1+$I$49)/($F$49-$I$49)/(1+$F$49)^$N$3 -> 66750.4 | Q62: =O62+P62 -> 106882.99 | R62: =Q62-$G$2+$I$2 -> 87422.991 | S62: =R62/$K$2 -> 155.72595 | T62: =S62-$M$2 -> -0.083736139
A63: 13 | B63: =IF(T62>0,B62,D62) -> 0.014526367 | C63: =IF(T62>0,D62,C62) -> 0.014892578 | D63: =(B63+C63)/2 -> 0.014709473 | E63: =$C$2*(1+IF(E$3<=$O$2,$D63,$D63-($D63-$I$49)*MIN(E$3-$O$2,$Q$2)/$Q$2)) -> 10715.332 | F63: =E63*(1+IF(F$3<=$O$2,$D63,$D63-($D63-$I$49)*MIN(F$3-$O$2,$Q$2)/$Q$2)) -> 10872.949 | G63: =F63*(1+IF(G$3<=$O$2,$D63,$D63-($D63-$I$49)*MIN(G$3-$O$2,$Q$2)/$Q$2)) -> 11032.884 | H63: =G63*(1+IF(H$3<=$O$2,$D63,$D63-($D63-$I$49)*MIN(H$3-$O$2,$Q$2)/$Q$2)) -> 11195.172 | I63: =H63*(1+IF(I$3<=$O$2,$D63,$D63-($D63-$I$49)*MIN(I$3-$O$2,$Q$2)/$Q$2)) -> 11359.847 | J63: =I63*(1+IF(J$3<=$O$2,$D63,$D63-($D63-$I$49)*MIN(J$3-$O$2,$Q$2)/$Q$2)) -> 11535.102 | K63: =J63*(1+IF(K$3<=$O$2,$D63,$D63-($D63-$I$49)*MIN(K$3-$O$2,$Q$2)/$Q$2)) -> 11721.344 | L63: =K63*(1+IF(L$3<=$O$2,$D63,$D63-($D63-$I$49)*MIN(L$3-$O$2,$Q$2)/$Q$2)) -> 11919.011 | M63: =L63*(1+IF(M$3<=$O$2,$D63,$D63-($D63-$I$49)*MIN(M$3-$O$2,$Q$2)/$Q$2)) -> 12128.569 | N63: =M63*(1+IF(N$3<=$O$2,$D63,$D63-($D63-$I$49)*MIN(N$3-$O$2,$Q$2)/$Q$2)) -> 12350.522 | O63: =SUMPRODUCT(E63:N63,1/(1+$F$49)^$E$3:$N$3)*$E$2 -> 40165.26 | P63: =N63*$E$2*(1+$I$49)/($F$49-$I$49)/(1+$F$49)^$N$3 -> 66834.742 | Q63: =O63+P63 -> 107000 | R63: =Q63-$G$2+$I$2 -> 87540.002 | S63: =R63/$K$2 -> 155.93438 | T63: =S63-$M$2 -> 0.1246944
... A74: 24 | B74: =IF(T73>0,B73,D73) -> 0.01459986 | C74: =IF(T73>0,D73,C73) -> 0.014600039 | D74: =(B74+C74)/2 -> 0.014599949 | E74: =$C$2*(1+IF(E$3<=$O$2,$D74,$D74-($D74-$I$49)*MIN(E$3-$O$2,$Q$2)/$Q$2)) -> 10714.175 | F74: =E74*(1+IF(F$3<=$O$2,$D74,$D74-($D74-$I$49)*MIN(F$3-$O$2,$Q$2)/$Q$2)) -> 10870.602 | G74: =F74*(1+IF(G$3<=$O$2,$D74,$D74-($D74-$I$49)*MIN(G$3-$O$2,$Q$2)/$Q$2)) -> 11029.312 | H74: =G74*(1+IF(H$3<=$O$2,$D74,$D74-($D74-$I$49)*MIN(H$3-$O$2,$Q$2)/$Q$2)) -> 11190.34 | I74: =H74*(1+IF(I$3<=$O$2,$D74,$D74-($D74-$I$49)*MIN(I$3-$O$2,$Q$2)/$Q$2)) -> 11353.718 | J74: =I74*(1+IF(J$3<=$O$2,$D74,$D74-($D74-$I$49)*MIN(J$3-$O$2,$Q$2)/$Q$2)) -> 11527.883 | K74: =J74*(1+IF(K$3<=$O$2,$D74,$D74-($D74-$I$49)*MIN(K$3-$O$2,$Q$2)/$Q$2)) -> 11713.251 | L74: =K74*(1+IF(L$3<=$O$2,$D74,$D74-($D74-$I$49)*MIN(L$3-$O$2,$Q$2)/$Q$2)) -> 11910.268 | M74: =L74*(1+IF(M$3<=$O$2,$D74,$D74-($D74-$I$49)*MIN(M$3-$O$2,$Q$2)/$Q$2)) -> 12119.412 | N74: =M74*(1+IF(N$3<=$O$2,$D74,$D74-($D74-$I$49)*MIN(N$3-$O$2,$Q$2)/$Q$2)) -> 12341.198 | O74: =SUMPRODUCT(E74:N74,1/(1+$F$49)^$E$3:$N$3)*$E$2 -> 40145.716 | P74: =N74*$E$2*(1+$I$49)/($F$49-$I$49)/(1+$F$49)^$N$3 -> 66784.282 | Q74: =O74+P74 -> 106930 | R74: =Q74-$G$2+$I$2 -> 87469.998 | S74: =R74/$K$2 -> 155.80968 | T74: =S74-$M$2 -> -2.8654616e-06
A76: Grid block 3: row 1, column 2 of table A (24 steps) | E76: WACC | F76: =Sensitivity!$B$10 -> 0.067017203 | G76: Terminal growth | I76: =Sensitivity!$D$9 -> 0.0233
A77: Step | B77: Low | C77: High | D77: Mid | E77: Rev Y1 | F77: Rev Y2 | G77: Rev Y3 | H77: Rev Y4 | I77: Rev Y5 | J77: Rev Y6 | K77: Rev Y7 | L77: Rev Y8 | M77: Rev Y9 | N77: Rev Y10 | O77: PV of FCF | P77: PV of TV | Q77: EV | R77: Equity | S77: Per share | T77: Value - price
A78: 1 | B78: -0.5 | C78: 1 | D78: =(B78+C78)/2 -> 0.25 | E78: =$C$2*(1+IF(E$3<=$O$2,$D78,$D78-($D78-$I$76)*MIN(E$3-$O$2,$Q$2)/$Q$2)) -> 13200 | F78: =E78*(1+IF(F$3<=$O$2,$D78,$D78-($D78-$I$76)*MIN(F$3-$O$2,$Q$2)/$Q$2)) -> 16500 | G78: =F78*(1+IF(G$3<=$O$2,$D78,$D78-($D78-$I$76)*MIN(G$3-$O$2,$Q$2)/$Q$2)) -> 20625 | H78: =G78*(1+IF(H$3<=$O$2,$D78,$D78-($D78-$I$76)*MIN(H$3-$O$2,$Q$2)/$Q$2)) -> 25781.25 | I78: =H78*(1+IF(I$3<=$O$2,$D78,$D78-($D78-$I$76)*MIN(I$3-$O$2,$Q$2)/$Q$2)) -> 32226.562 | J78: =I78*(1+IF(J$3<=$O$2,$D78,$D78-($D78-$I$76)*MIN(J$3-$O$2,$Q$2)/$Q$2)) -> 38822.051 | K78: =J78*(1+IF(K$3<=$O$2,$D78,$D78-($D78-$I$76)*MIN(K$3-$O$2,$Q$2)/$Q$2)) -> 45007.18 | L78: =K78*(1+IF(L$3<=$O$2,$D78,$D78-($D78-$I$76)*MIN(L$3-$O$2,$Q$2)/$Q$2)) -> 50137.098 | M78: =L78*(1+IF(M$3<=$O$2,$D78,$D78-($D78-$I$76)*MIN(M$3-$O$2,$Q$2)/$Q$2)) -> 53578.509 | N78: =M78*(1+IF(N$3<=$O$2,$D78,$D78-($D78-$I$76)*MIN(N$3-$O$2,$Q$2)/$Q$2)) -> 54826.888 | O78: =SUMPRODUCT(E78:N78,1/(1+$F$76)^$E$3:$N$3)*$E$2 -> 114060.29 | P78: =N78*$E$2*(1+$I$76)/($F$76-$I$76)/(1+$F$76)^$N$3 -> 332252.12 | Q78: =O78+P78 -> 446312.41 | R78: =Q78-$G$2+$I$2 -> 426852.41 | S78: =R78/$K$2 -> 760.34916 | T78: =S78-$M$2 -> 604.53947
A79: 2 | B79: =IF(T78>0,B78,D78) -> -0.5 | C79: =IF(T78>0,D78,C78) -> 0.25 | D79: =(B79+C79)/2 -> -0.125 | E79: =$C$2*(1+IF(E$3<=$O$2,$D79,$D79-($D79-$I$76)*MIN(E$3-$O$2,$Q$2)/$Q$2)) -> 9240 | F79: =E79*(1+IF(F$3<=$O$2,$D79,$D79-($D79-$I$76)*MIN(F$3-$O$2,$Q$2)/$Q$2)) -> 8085 | G79: =F79*(1+IF(G$3<=$O$2,$D79,$D79-($D79-$I$76)*MIN(G$3-$O$2,$Q$2)/$Q$2)) -> 7074.375 | H79: =G79*(1+IF(H$3<=$O$2,$D79,$D79-($D79-$I$76)*MIN(H$3-$O$2,$Q$2)/$Q$2)) -> 6190.0781 | I79: =H79*(1+IF(I$3<=$O$2,$D79,$D79-($D79-$I$76)*MIN(I$3-$O$2,$Q$2)/$Q$2)) -> 5416.3184 | J79: =I79*(1+IF(J$3<=$O$2,$D79,$D79-($D79-$I$76)*MIN(J$3-$O$2,$Q$2)/$Q$2)) -> 4899.9266 | K79: =J79*(1+IF(K$3<=$O$2,$D79,$D79-($D79-$I$76)*MIN(K$3-$O$2,$Q$2)/$Q$2)) -> 4578.0994 | L79: =K79*(1+IF(L$3<=$O$2,$D79,$D79-($D79-$I$76)*MIN(L$3-$O$2,$Q$2)/$Q$2)) -> 4413.1963 | M79: =L79*(1+IF(M$3<=$O$2,$D79,$D79-($D79-$I$76)*MIN(M$3-$O$2,$Q$2)/$Q$2)) -> 4385.1283 | N79: =M79*(1+IF(N$3<=$O$2,$D79,$D79-($D79-$I$76)*MIN(N$3-$O$2,$Q$2)/$Q$2)) -> 4487.3018 | O79: =SUMPRODUCT(E79:N79,1/(1+$F$76)^$E$3:$N$3)*$E$2 -> 21752.7 | P79: =N79*$E$2*(1+$I$76)/($F$76-$I$76)/(1+$F$76)^$N$3 -> 27193.146 | Q79: =O79+P79 -> 48945.846 | R79: =Q79-$G$2+$I$2 -> 29485.846 | S79: =R79/$K$2 -> 52.522926 | T79: =S79-$M$2 -> -103.28676
...

Sheet DCF
B2: Intercontinental Exchange (ICE): discounted cash flow
B3: Panel A runs the model at the solved growth rate, so it should land on the price. Panel B runs it at your view.
B5: A. At the solved (implied) growth rate
B6: Year | C6: 1 | D6: 2 | E6: 3 | F6: 4 | G6: 5 | H6: 6 | I6: 7 | J6: 8 | K6: 9 | L6: 10
B7: Revenue growth | C7: =IF(C$6<=Inputs!$C$46,Solver!$W$7,Solver!$W$7-(Solver!$W$7-Inputs!$C$37)*MIN(C$6-Inputs!$C$46,Inputs!$C$47)/Inputs!$C$47) -> 0.022919701 | D7: =IF(D$6<=Inputs!$C$46,Solver!$W$7,Solver!$W$7-(Solver!$W$7-Inputs!$C$37)*MIN(D$6-Inputs!$C$46,Inputs!$C$47)/Inputs!$C$47) -> 0.022919701 | E7: =IF(E$6<=Inputs!$C$46,Solver!$W$7,Solver!$W$7-(Solver!$W$7-Inputs!$C$37)*MIN(E$6-Inputs!$C$46,Inputs!$C$47)/Inputs!$C$47) -> 0.022919701 | F7: =IF(F$6<=Inputs!$C$46,Solver!$W$7,Solver!$W$7-(Solver!$W$7-Inputs!$C$37)*MIN(F$6-Inputs!$C$46,Inputs!$C$47)/Inputs!$C$47) -> 0.022919701 | G7: =IF(G$6<=Inputs!$C$46,Solver!$W$7,Solver!$W$7-(Solver!$W$7-Inputs!$C$37)*MIN(G$6-Inputs!$C$46,Inputs!$C$47)/Inputs!$C$47) -> 0.022919701 | H7: =IF(H$6<=Inputs!$C$46,Solver!$W$7,Solver!$W$7-(Solver!$W$7-Inputs!$C$37)*MIN(H$6-Inputs!$C$46,Inputs!$C$47)/Inputs!$C$47) -> 0.023995761 | I7: =IF(I$6<=Inputs!$C$46,Solver!$W$7,Solver!$W$7-(Solver!$W$7-Inputs!$C$37)*MIN(I$6-Inputs!$C$46,Inputs!$C$47)/Inputs!$C$47) -> 0.025071821 | J7: =IF(J$6<=Inputs!$C$46,Solver!$W$7,Solver!$W$7-(Solver!$W$7-Inputs!$C$37)*MIN(J$6-Inputs!$C$46,Inputs!$C$47)/Inputs!$C$47) -> 0.02614788 | ... L7: =IF(L$6<=Inputs!$C$46,Solver!$W$7,Solver!$W$7-(Solver!$W$7-Inputs!$C$37)*MIN(L$6-Inputs!$C$46,Inputs!$C$47)/Inputs!$C$47) -> 0.0283
B8: Revenue ($mm) | C8: =Inputs!$C$12*(1+C7) -> 10802.032 | D8: =C8*(1+D7) -> 11049.611 | E8: =D8*(1+E7) -> 11302.865 | F8: =E8*(1+F7) -> 11561.923 | G8: =F8*(1+G7) -> 11826.919 | H8: =G8*(1+H7) -> 12110.715 | I8: =H8*(1+I7) -> 12414.353 | J8: =I8*(1+J7) -> 12738.962 | K8: =J8*(1+K7) -> 13085.767 | L8: =K8*(1+L7) -> 13456.094
B9: Unlevered free cash flow ($mm) | C9: =C8*Inputs!$C$23 -> 5349.87 | D9: =D8*Inputs!$C$23 -> 5472.4875 | E9: =E8*Inputs!$C$23 -> 5597.9152 | F9: =F8*Inputs!$C$23 -> 5726.2178 | G9: =G8*Inputs!$C$23 -> 5857.461 | H9: =H8*Inputs!$C$23 -> 5998.0152 | I9: =I8*Inputs!$C$23 -> 6148.3964 | J9: =J8*Inputs!$C$23 -> 6309.1639 | ... L9: =L8*Inputs!$C$23 -> 6664.3344
B10: Discount factor | C10: =1/(1+WACC!$C$37)^C$6 -> 0.92849028 | D10: =1/(1+WACC!$C$37)^D$6 -> 0.86209419 | E10: =1/(1+WACC!$C$37)^E$6 -> 0.80044608 | F10: =1/(1+WACC!$C$37)^F$6 -> 0.7432064 | G10: =1/(1+WACC!$C$37)^G$6 -> 0.69005991 | H10: =1/(1+WACC!$C$37)^H$6 -> 0.64071392 | I10: =1/(1+WACC!$C$37)^I$6 -> 0.59489664 | J10: =1/(1+WACC!$C$37)^J$6 -> 0.55235575 | ... L10: =1/(1+WACC!$C$37)^L$6 -> 0.47618268
B11: Present value ($mm) | C11: =C9*C10 -> 4967.3023 | D11: =D9*D10 -> 4717.7997 | E11: =E9*E10 -> 4480.8293 | F11: =F9*F10 -> 4255.7617 | G11: =G9*G10 -> 4041.999 | H11: =H9*H10 -> 3843.0118 | I11: =I9*I10 -> 3657.6604 | J11: =J9*J10 -> 3484.903 | ... L11: =L9*L10 -> 3173.4406
B13: Sum of present values, years 1 to 10 | C13: =SUM(C11:L11) -> 39946.495
B14: Terminal value at year 10 | C14: =L9*(1+Inputs!$C$37)/(WACC!$C$37-Inputs!$C$37) -> 140667.66
B15: Present value of terminal value | C15: =C14*L10 -> 66983.505
B16: Enterprise value | C16: =C13+C15 -> 106930
B17: Less: debt | C17: =-Inputs!$C$27 -> -20530
B18: Plus: cash | C18: =Inputs!$C$28 -> 1070
B19: Equity value | C19: =SUM(C16:C18) -> 87470
B20: Shares (mm) | C20: =Inputs!$C$7 -> 561.39
B21: Value per share ($) | C21: =C19/C20 -> 155.80969
B22: Price at the lock ($) | C22: =Inputs!$C$6 -> 155.80969
B23: Value / price - 1 | C23: =C21/C22-1 -> 9.144685e-12
B24: Terminal value share of enterprise value | C24: =C15/C16 -> 0.62642388
B25: B. At your view of growth (Inputs tab, yellow cell)
B26: Year | C26: 1 | D26: 2 | E26: 3 | F26: 4 | G26: 5 | H26: 6 | I26: 7 | J26: 8 | K26: 9 | L26: 10
B27: Revenue growth | C27: =IF(C$26<=Inputs!$C$46,Inputs!$C$45,Inputs!$C$45-(Inputs!$C$45-Inputs!$C$37)*MIN(C$26-Inputs!$C$46,Inputs!$C$47)/Inputs!$C$47) -> 0.0812 | D27: =IF(D$26<=Inputs!$C$46,Inputs!$C$45,Inputs!$C$45-(Inputs!$C$45-Inputs!$C$37)*MIN(D$26-Inputs!$C$46,Inputs!$C$47)/Inputs!$C$47) -> 0.0812 | E27: =IF(E$26<=Inputs!$C$46,Inputs!$C$45,Inputs!$C$45-(Inputs!$C$45-Inputs!$C$37)*MIN(E$26-Inputs!$C$46,Inputs!$C$47)/Inputs!$C$47) -> 0.0812 | F27: =IF(F$26<=Inputs!$C$46,Inputs!$C$45,Inputs!$C$45-(Inputs!$C$45-Inputs!$C$37)*MIN(F$26-Inputs!$C$46,Inputs!$C$47)/Inputs!$C$47) -> 0.0812 | G27: =IF(G$26<=Inputs!$C$46,Inputs!$C$45,Inputs!$C$45-(Inputs!$C$45-Inputs!$C$37)*MIN(G$26-Inputs!$C$46,Inputs!$C$47)/Inputs!$C$47) -> 0.0812 | H27: =IF(H$26<=Inputs!$C$46,Inputs!$C$45,Inputs!$C$45-(Inputs!$C$45-Inputs!$C$37)*MIN(H$26-Inputs!$C$46,Inputs!$C$47)/Inputs!$C$47) -> 0.07062 | I27: =IF(I$26<=Inputs!$C$46,Inputs!$C$45,Inputs!$C$45-(Inputs!$C$45-Inputs!$C$37)*MIN(I$26-Inputs!$C$46,Inputs!$C$47)/Inputs!$C$47) -> 0.06004 | J27: =IF(J$26<=Inputs!$C$46,Inputs!$C$45,Inputs!$C$45-(Inputs!$C$45-Inputs!$C$37)*MIN(J$26-Inputs!$C$46,Inputs!$C$47)/Inputs!$C$47) -> 0.04946 | ... L27: =IF(L$26<=Inputs!$C$46,Inputs!$C$45,Inputs!$C$45-(Inputs!$C$45-Inputs!$C$37)*MIN(L$26-Inputs!$C$46,Inputs!$C$47)/Inputs!$C$47) -> 0.0283
B28: Revenue ($mm) | C28: =Inputs!$C$12*(1+C27) -> 11417.472 | D28: =C28*(1+D27) -> 12344.571 | E28: =D28*(1+E27) -> 13346.95 | F28: =E28*(1+F27) -> 14430.722 | G28: =F28*(1+G27) -> 15602.497 | H28: =G28*(1+H27) -> 16704.345 | I28: =H28*(1+I27) -> 17707.274 | J28: =I28*(1+J27) -> 18583.076 | K28: =J28*(1+K27) -> 19305.586 | L28: =K28*(1+L27) -> 19851.934
B29: Unlevered free cash flow ($mm) | C29: =C28*Inputs!$C$23 -> 5654.676 | D29: =D28*Inputs!$C$23 -> 6113.8357 | E29: =E28*Inputs!$C$23 -> 6610.2791 | F29: =F28*Inputs!$C$23 -> 7147.0338 | G29: =G28*Inputs!$C$23 -> 7727.373 | H29: =H28*Inputs!$C$23 -> 8273.08 | I29: =I28*Inputs!$C$23 -> 8769.7958 | J29: =J28*Inputs!$C$23 -> 9203.5499 | ... L29: =L28*Inputs!$C$23 -> 9831.971
B30: Discount factor | C30: =1/(1+WACC!$C$37)^C$26 -> 0.92849028 | D30: =1/(1+WACC!$C$37)^D$26 -> 0.86209419 | E30: =1/(1+WACC!$C$37)^E$26 -> 0.80044608 | F30: =1/(1+WACC!$C$37)^F$26 -> 0.7432064 | G30: =1/(1+WACC!$C$37)^G$26 -> 0.69005991 | H30: =1/(1+WACC!$C$37)^H$26 -> 0.64071392 | I30: =1/(1+WACC!$C$37)^I$26 -> 0.59489664 | J30: =1/(1+WACC!$C$37)^J$26 -> 0.55235575 | ... L30: =1/(1+WACC!$C$37)^L$26 -> 0.47618268
B31: Present value ($mm) | C31: =C29*C30 -> 5250.3117 | D31: =D29*D30 -> 5270.7022 | E31: =E29*E30 -> 5291.172 | F31: =F29*F30 -> 5311.7213 | G31: =G29*G30 -> 5332.3503 | H31: =H29*H30 -> 5300.6775 | I31: =I29*I30 -> 5217.1221 | J31: =J29*J30 -> 5083.6337 | ... L31: =L29*L30 -> 4681.8144
B33: Sum of present values, years 1 to 10 | C33: =SUM(C31:L31) -> 51643.127
B34: Terminal value at year 10 | C34: =L29*(1+Inputs!$C$37)/(WACC!$C$37-Inputs!$C$37) -> 207528.66
B35: Present value of terminal value | C35: =C34*L30 -> 98821.555
B36: Enterprise value | C36: =C33+C35 -> 150464.68
B37: Less: debt | C37: =-Inputs!$C$27 -> -20530
B38: Plus: cash | C38: =Inputs!$C$28 -> 1070
B39: Equity value | C39: =SUM(C36:C38) -> 131004.68
B40: Shares (mm) | C40: =Inputs!$C$7 -> 561.39
B41: Value per share ($) | C41: =C39/C40 -> 233.35771
B42: Price at the lock ($) | C42: =Inputs!$C$6 -> 155.80969
B43: Value / price - 1 | C43: =C41/C42-1 -> 0.49770987
B44: Terminal value share of enterprise value | C44: =C35/C36 -> 0.65677575

Sheet Sensitivity
B2: Intercontinental Exchange (ICE): sensitivity
B3: Table A re-solves implied growth for each pair of inputs (Solver tab, blocks 2 to 26). Table B values the stock at a growth view.
B5: WACC step | C5: 0.005 | D5: Terminal-growth step | F5: 0.005
B6: Growth-view step | C6: 0.02
B8: A. Implied 5-year growth: WACC (rows) by terminal growth (columns)
C9: =Inputs!$C$37+(0-2)*$F$5 -> 0.0183 | D9: =Inputs!$C$37+(1-2)*$F$5 -> 0.0233 | E9: =Inputs!$C$37+(2-2)*$F$5 -> 0.0283 | F9: =Inputs!$C$37+(3-2)*$F$5 -> 0.0333 | G9: =Inputs!$C$37+(4-2)*$F$5 -> 0.0383
B10: =WACC!$C$37+(0-2)*$C$5 -> 0.067017203 | C10: =Solver!$D$74 -> 0.014599949 | D10: =Solver!$D$101 -> 0.00094553828 | E10: =Solver!$D$128 -> -0.014309257 | F10: =Solver!$D$155 -> -0.031584471 | G10: =Solver!$D$182 -> -0.051494867 | I10: Centre cell = the base case. Each step changes one input by the step size above.
B11: =WACC!$C$37+(1-2)*$C$5 -> 0.072017203 | C11: =Solver!$D$209 -> 0.031172425 | D11: =Solver!$D$236 -> 0.018761128 | E11: =Solver!$D$263 -> 0.0050446689 | F11: =Solver!$D$290 -> -0.010278791 | G11: =Solver!$D$317 -> -0.027631432
B12: =WACC!$C$37+(2-2)*$C$5 -> 0.077017203 | C12: =Solver!$D$344 -> 0.046768576 | D12: =Solver!$D$371 -> 0.035387248 | E12: =Solver!$D$398 -> 0.022919625 | F12: =Solver!$D$425 -> 0.0091412961 | G12: =Solver!$D$452 -> -0.0062510073
B13: =WACC!$C$37+(3-2)*$C$5 -> 0.082017203 | C13: =Solver!$D$479 -> 0.061546296 | D13: =Solver!$D$506 -> 0.051032573 | E13: =Solver!$D$533 -> 0.039599568 | F13: =Solver!$D$560 -> 0.027075619 | G13: =Solver!$D$587 -> 0.013235241
B14: =WACC!$C$37+(4-2)*$C$5 -> 0.087017203 | C14: =Solver!$D$614 -> 0.07562843 | D14: =Solver!$D$641 -> 0.065855533 | E14: =Solver!$D$668 -> 0.055293888 | F14: =Solver!$D$695 -> 0.043809205 | G14: =Solver!$D$722 -> 0.031228751
B17: B. Value per share: WACC (rows) by your growth view (columns)
C18: =Inputs!$C$45+(0-2)*$C$6 -> 0.0412 | D18: =Inputs!$C$45+(1-2)*$C$6 -> 0.0612 | E18: =Inputs!$C$45+(2-2)*$C$6 -> 0.0812 | F18: =Inputs!$C$45+(3-2)*$C$6 -> 0.1012 | G18: =Inputs!$C$45+(4-2)*$C$6 -> 0.1212
